Workbook

Sheet Leads
A1: N° du lead | B1: Date et heure de réception | C1: Date et heure du 1er contact | D1: Délai de 1er contact (min) | E1: Prénom | F1: Nom | G1: Courriel | H1: Téléphone | I1: Entreprise | J1: Type de client | K1: Type d'événement | L1: Date de l'événement | M1: Ville | N1: Nombre d'invités | O1: Budget déclaré | P1: Route (formulaire) | Q1: Pointage (0-100) | R1: Étape du pipeline | S1: Raison de perte / disqualification | T1: Forfait proposé | U1: Montant proposé ($) | V1: Montant gagné ($) | W1: Date et heure du dépôt | X1: utm_source | Y1: utm_medium | Z1: utm_campaign | AA1: utm_content | AB1: utm_term | AC1: gclid (Google) | AD1: msclkid (Microsoft) | AE1: fbclid (Meta) | AF1: oppref (ChatGPT) | AG1: event_id (déduplication) | AH1: Consentement marketing | AI1: Consentement mesure | AJ1: Date du consentement | AK1: Désabonné | AL1: Conseiller | AM1: Notes | AN1: Rôle dans la décision | AO1: Échéance de décision | AP1: Source / campagne (forcer) | AQ1: Campagne (calculée) | AR1: Segment | AS1: Route selon les règles | AT1: Route retenue | AU1: Lead qualifié (A ou B) 1/0 | AV1: Gagné (dépôt payé ou plus) 1/0 | AW1: Priorité de rappel | AX1: Valeur de conversion provisoire ($) | AY1: Valeur ($) : gagnée ou pondérée | AZ1: Ligne EXEMPLE 1/0 | BA1: Rang import Google
A2: lead_id | B2: date_heure_reception | C2: date_heure_1er_contact | D2: delai_min | E2: prenom | F2: nom | G2: courriel | H2: telephone | I2: entreprise | J2: type_client | K2: type_evenement | L2: date_evenement | M2: ville | N2: nb_invites | O2: budget_declare | P2: route | Q2: lead_score | R2: etape | S2: raison_perte | T2: forfait_propose | U2: montant_propose | V2: montant_gagne | W2: date_depot | X2: utm_source | Y2: utm_medium | Z2: utm_campaign | AA2: utm_content | AB2: utm_term | AC2: gclid | AD2: msclkid | AE2: fbclid | AF2: oppref | AG2: event_id | AH2: consent_marketing | AI2: consent_mesure | AJ2: date_consentement | AK2: desabonne | AL2: conseiller | AM2: notes | AN2: role_decision | AO2: echeance_decision | AP2: campagne_manuelle | AQ2: campagne | AR2: segment | AS2: route_calculee | AT2: route_effective | AU2: qualifie | AV2: gagne | AW2: priorite_rappel | AX2: valeur_conv_provisoire | AY2: valeur | AZ2: est_exemple | BA2: rang_import
A3: EXEMPLE-001 | B3: 46296.425 | C3: 46296.428 | D3: =IF(OR(B3="",C3=""),"",ROUND((C3-B3)*1440,0)) | E3: Exemple | F3: Corpo-Party | G3: exemple1@exemple.com | H3: +15145550101 | I3: Entreprise Exemple inc. | J3: entreprise | K3: corpo_party | L3: 46367 | M3: Laval | N3: 75_149 | O3: 2500_4999 | P3: A | Q3: =IF(A3="","",IFERROR(VLOOKUP(O3,Listes!$R$3:$T$8,2,FALSE),0)+IFERROR(VLOOKUP(J3,Listes!$J$3:$L$6,2,FALSE),0)+IFERROR(VLOOKUP(N3,Listes!$N$3:$P$6,2,FALSE),0)+IF(OR(L3="",B3=""),0,IF(L3-INT(B3)<10,8,IF(L3-INT(B3)<=90,10,5)))+IFERROR(VLOOKUP(AN3,Listes!$V$3:$W$5,2,FALSE),0)+IFERROR(VLOOKUP(AO3,Listes!$Y$3:$Z$5,2,FALSE),0)) | R3: Dépôt payé (gagné) | T3: Gala Signature (2 495 $) | U3: 2495 | V3: 2495 | W3: 46298.604 | X3: google | Y3: cpc | Z3: gads_corpo_fetes | AA3: rsa_prixfixe_v1 | AB3: party de bureau | AC3: EXEMPLE-GCLID-001 | AG3: ex-0001 | AH3: oui | AI3: oui | AJ3: 46296.425 | AK3: non | AL3: Alexandre | AM3: EXEMPLE : supprimer cette ligne avant l'usage réel. | AN3: Je décide | AO3: Cette semaine | AQ3: =IF(A3="","",IF(AP3<>"",AP3,IF(LEFT(Z3,11)="gads_marque","Google Search – Marque",IF(LEFT(Z3,12)="gads_mariage","Google Search – Mariage et privé",IF(LEFT(Z3,10)="gads_corpo","Google Search – Corporatif",IF(LEFT(Z3,5)="meta_","Meta – Leads",IF(LEFT(Z3,5)="msft_","Microsoft Ads",IF(LEFT(Z3,8)="chatgpt_","ChatGPT Ads – Test",IF(X3="gbp","Fiche Google (organique)","Autre / non payé"))))))))) | AR3: =IF(K3="","",IFERROR(VLOOKUP(K3,Listes!$F$3:$H$8,3,FALSE),"")) | AS3: =IF(O3="","",IF(AND(M3="Autre (plus de 40 km)",OR(O3="lt600",O3="600_999",O3="1000_2499")),"D",IF(OR(O3="lt600",AND(O3="600_999",K3<>"mariage",K3<>"prive")),"C",IF(OR(O3="2500_4999",O3="5000p",J3="entreprise",J3="organisme",J3="agence"),"A",IF(OR(O3="1000_2499",O3="600_999"),"B",IF(O3="inconnu",IF(OR(N3="75_149",N3="150p"),"A","B"),"")))))) | AT3: =IF(A3="","",IF(P3<>"",P3,AS3)) | AU3: =IF(A3="","",IF(OR(AT3="A",AT3="B"),1,0)) | AV3: =IF(A3="","",IF(OR(R3="Dépôt payé (gagné)",R3="Événement livré",R3="Avis obtenu"),1,0)) | AW3: =IF(A3="","",IF(Q3>70,"Immédiat – propriétaire",IF(Q3>=40,"15 min – personne de garde","Selon la route"))) | AX3: =IF(A3="","",IF(AT3="A",400,IF(AT3="B",150,0))) | AY3: =IF(A3="","",IF(AV3=1,N(V3),IF(N(U3)>0,ROUND(N(U3)*IFERROR(VLOOKUP(R3,Listes!$AE$3:$AG$12,2,FALSE),0),0),0))) | AZ3: =IF(LEFT(A3,7)="EXEMPLE",1,0) | BA3: =IF(AND(AV3=1,AZ3=0,AC3<>"",W3<>"",N(V3)>0),COUNTIFS($AV$3:AV3,1,$AZ$3:AZ3,0,$AC$3:AC3,"<>",$W$3:W3,"<>",$V$3:V3,">0"),"")
A4: EXEMPLE-002 | B4: 46297.819 | C4: 46297.835 | D4: =IF(OR(B4="",C4=""),"",ROUND((C4-B4)*1440,0)) | E4: Exemple | F4: Mariage | G4: exemple2@exemple.com | H4: +14505550102 | J4: particulier | K4: mariage | L4: 46585 | M4: Mirabel | N4: 75_149 | O4: 1000_2499 | P4: B | Q4: =IF(A4="","",IFERROR(VLOOKUP(O4,Listes!$R$3:$T$8,2,FALSE),0)+IFERROR(VLOOKUP(J4,Listes!$J$3:$L$6,2,FALSE),0)+IFERROR(VLOOKUP(N4,Listes!$N$3:$P$6,2,FALSE),0)+IF(OR(L4="",B4=""),0,IF(L4-INT(B4)<10,8,IF(L4-INT(B4)<=90,10,5)))+IFERROR(VLOOKUP(AN4,Listes!$V$3:$W$5,2,FALSE),0)+IFERROR(VLOOKUP(AO4,Listes!$Y$3:$Z$5,2,FALSE),0)) | R4: Proposition envoyée | T4: Soirée Signature (1 449 $) | U4: 1449 | X4: google | Y4: cpc | Z4: gads_mariage_deco | AA4: rsa_dates_v1 | AB4: decor mariage | AC4: EXEMPLE-GCLID-002 | AG4: ex-0002 | AH4: non | AI4: oui | AJ4: 46297.819 | AK4: non | AL4: Alexandre | AM4: EXEMPLE : délai de 22 min sur une route B, la ligne est signalée en rouge. | AN4: Je décide | AO4: D'ici 30 jours | AQ4: =IF(A4="","",IF(AP4<>"",AP4,IF(LEFT(Z4,11)="gads_marque","Google Search – Marque",IF(LEFT(Z4,12)="gads_mariage","Google Search – Mariage et privé",IF(LEFT(Z4,10)="gads_corpo","Google Search – Corporatif",IF(LEFT(Z4,5)="meta_","Meta – Leads",IF(LEFT(Z4,5)="msft_","Microsoft Ads",IF(LEFT(Z4,8)="chatgpt_","ChatGPT Ads – Test",IF(X4="gbp","Fiche Google (organique)","Autre / non payé"))))))))) | AR4: =IF(K4="","",IFERROR(VLOOKUP(K4,Listes!$F$3:$H$8,3,FALSE),"")) | AS4: =IF(O4="","",IF(AND(M4="Autre (plus de 40 km)",OR(O4="lt600",O4="600_999",O4="1000_2499")),"D",IF(OR(O4="lt600",AND(O4="600_999",K4<>"mariage",K4<>"prive")),"C",IF(OR(O4="2500_4999",O4="5000p",J4="entreprise",J4="organisme",J4="agence"),"A",IF(OR(O4="1000_2499",O4="600_999"),"B",IF(O4="inconnu",IF(OR(N4="75_149",N4="150p"),"A","B"),"")))))) | AT4: =IF(A4="","",IF(P4<>"",P4,AS4)) | AU4: =IF(A4="","",IF(OR(AT4="A",AT4="B"),1,0)) | AV4: =IF(A4="","",IF(OR(R4="Dépôt payé (gagné)",R4="Événement livré",R4="Avis obtenu"),1,0)) | AW4: =IF(A4="","",IF(Q4>70,"Immédiat – propriétaire",IF(Q4>=40,"15 min – personne de garde","Selon la route"))) | AX4: =IF(A4="","",IF(AT4="A",400,IF(AT4="B",150,0))) | AY4: =IF(A4="","",IF(AV4=1,N(V4),IF(N(U4)>0,ROUND(N(U4)*IFERROR(VLOOKUP(R4,Listes!$AE$3:$AG$12,2,FALSE),0),0),0))) | AZ4: =IF(LEFT(A4,7)="EXEMPLE",1,0) | BA4: =IF(AND(AV4=1,AZ4=0,AC4<>"",W4<>"",N(V4)>0),COUNTIFS($AV$3:AV4,1,$AZ$3:AZ4,0,$AC$3:AC4,"<>",$W$3:W4,"<>",$V$3:V4,">0"),"")
A5: EXEMPLE-003 | B5: 46298.462 | D5: =IF(OR(B5="",C5=""),"",ROUND((C5-B5)*1440,0)) | E5: Exemple | F5: Privé | G5: exemple3@exemple.com | H5: +15145550103 | J5: particulier | K5: prive | L5: 46333 | M5: Boisbriand | N5: lt30 | O5: lt600 | P5: C | Q5: =IF(A5="","",IFERROR(VLOOKUP(O5,Listes!$R$3:$T$8,2,FALSE),0)+IFERROR(VLOOKUP(J5,Listes!$J$3:$L$6,2,FALSE),0)+IFERROR(VLOOKUP(N5,Listes!$N$3:$P$6,2,FALSE),0)+IF(OR(L5="",B5=""),0,IF(L5-INT(B5)<10,8,IF(L5-INT(B5)<=90,10,5)))+IFERROR(VLOOKUP(AN5,Listes!$V$3:$W$5,2,FALSE),0)+IFERROR(VLOOKUP(AO5,Listes!$Y$3:$Z$5,2,FALSE),0)) | R5: Disqualifié | S5: Disqualifié – budget < seuil | X5: meta | Y5: paid_social | Z5: meta_mariage_deco | AA5: reel_avantapres_v2 | AE5: EXEMPLE-FBCLID-003 | AG5: ex-0003 | AH5: non | AI5: non | AK5: non | AL5: Alexandre | AM5: EXEMPLE : route C, redirigé vers la boutique. | AN5: Je décide | AO5: Cette semaine | AQ5: =IF(A5="","",IF(AP5<>"",AP5,IF(LEFT(Z5,11)="gads_marque","Google Search – Marque",IF(LEFT(Z5,12)="gads_mariage","Google Search – Mariage et privé",IF(LEFT(Z5,10)="gads_corpo","Google Search – Corporatif",IF(LEFT(Z5,5)="meta_","Meta – Leads",IF(LEFT(Z5,5)="msft_","Microsoft Ads",IF(LEFT(Z5,8)="chatgpt_","ChatGPT Ads – Test",IF(X5="gbp","Fiche Google (organique)","Autre / non payé"))))))))) | AR5: =IF(K5="","",IFERROR(VLOOKUP(K5,Listes!$F$3:$H$8,3,FALSE),"")) | AS5: =IF(O5="","",IF(AND(M5="Autre (plus de 40 km)",OR(O5="lt600",O5="600_999",O5="1000_2499")),"D",IF(OR(O5="lt600",AND(O5="600_999",K5<>"mariage",K5<>"prive")),"C",IF(OR(O5="2500_4999",O5="5000p",J5="entreprise",J5="organisme",J5="agence"),"A",IF(OR(O5="1000_2499",O5="600_999"),"B",IF(O5="inconnu",IF(OR(N5="75_149",N5="150p"),"A","B"),"")))))) | AT5: =IF(A5="","",IF(P5<>"",P5,AS5)) | AU5: =IF(A5="","",IF(OR(AT5="A",AT5="B"),1,0)) | AV5: =IF(A5="","",IF(OR(R5="Dépôt payé (gagné)",R5="Événement livré",R5="Avis obtenu"),1,0)) | AW5: =IF(A5="","",IF(Q5>70,"Immédiat – propriétaire",IF(Q5>=40,"15 min – personne de garde","Selon la route"))) | AX5: =IF(A5="","",IF(AT5="A",400,IF(AT5="B",150,0))) | AY5: =IF(A5="","",IF(AV5=1,N(V5),IF(N(U5)>0,ROUND(N(U5)*IFERROR(VLOOKUP(R5,Listes!$AE$3:$AG$12,2,FALSE),0),0),0))) | AZ5: =IF(LEFT(A5,7)="EXEMPLE",1,0) | BA5: =IF(AND(AV5=1,AZ5=0,AC5<>"",W5<>"",N(V5)>0),COUNTIFS($AV$3:AV5,1,$AZ$3:AZ5,0,$AC$3:AC5,"<>",$W$3:W5,"<>",$V$3:V5,">0"),"")
A6: EXEMPLE-004 | B6: 46300.396 | C6: 46300.398 | D6: =IF(OR(B6="",C6=""),"",ROUND((C6-B6)*1440,0)) | E6: Exemple | F6: Gala | G6: exemple4@exemple.com | H6: +14505550104 | I6: Ville Exemple | J6: organisme | K6: corpo_gala | L6: 46438 | M6: Terrebonne | N6: 150p | O6: 5000p | P6: A | Q6: =IF(A6="","",IFERROR(VLOOKUP(O6,Listes!$R$3:$T$8,2,FALSE),0)+IFERROR(VLOOKUP(J6,Listes!$J$3:$L$6,2,FALSE),0)+IFERROR(VLOOKUP(N6,Listes!$N$3:$P$6,2,FALSE),0)+IF(OR(L6="",B6=""),0,IF(L6-INT(B6)<10,8,IF(L6-INT(B6)<=90,10,5)))+IFERROR(VLOOKUP(AN6,Listes!$V$3:$W$5,2,FALSE),0)+IFERROR(VLOOKUP(AO6,Listes!$Y$3:$Z$5,2,FALSE),0)) | R6: Négociation | T6: Sur mesure | U6: 3200 | X6: chatgpt | Y6: cpc | Z6: chatgpt_corpo_fetes | AA6: card_dates_dec_v1 | AF6: EXEMPLE-OPPREF-004 | AG6: ex-0004 | AH6: oui | AI6: non | AJ6: 46300.396 | AK6: non | AL6: Alexandre | AM6: EXEMPLE : comité, relance la veille de la réunion. | AN6: Je compare des options pour un comité | AO6: D'ici 30 jours | AQ6: =IF(A6="","",IF(AP6<>"",AP6,IF(LEFT(Z6,11)="gads_marque","Google Search – Marque",IF(LEFT(Z6,12)="gads_mariage","Google Search – Mariage et privé",IF(LEFT(Z6,10)="gads_corpo","Google Search – Corporatif",IF(LEFT(Z6,5)="meta_","Meta – Leads",IF(LEFT(Z6,5)="msft_","Microsoft Ads",IF(LEFT(Z6,8)="chatgpt_","ChatGPT Ads – Test",IF(X6="gbp","Fiche Google (organique)","Autre / non payé"))))))))) | AR6: =IF(K6="","",IFERROR(VLOOKUP(K6,Listes!$F$3:$H$8,3,FALSE),"")) | AS6: =IF(O6="","",IF(AND(M6="Autre (plus de 40 km)",OR(O6="lt600",O6="600_999",O6="1000_2499")),"D",IF(OR(O6="lt600",AND(O6="600_999",K6<>"mariage",K6<>"prive")),"C",IF(OR(O6="2500_4999",O6="5000p",J6="entreprise",J6="organisme",J6="agence"),"A",IF(OR(O6="1000_2499",O6="600_999"),"B",IF(O6="inconnu",IF(OR(N6="75_149",N6="150p"),"A","B"),"")))))) | AT6: =IF(A6="","",IF(P6<>"",P6,AS6)) | AU6: =IF(A6="","",IF(OR(AT6="A",AT6="B"),1,0)) | AV6: =IF(A6="","",IF(OR(R6="Dépôt payé (gagné)",R6="Événement livré",R6="Avis obtenu"),1,0)) | AW6: =IF(A6="","",IF(Q6>70,"Immédiat – propriétaire",IF(Q6>=40,"15 min – personne de garde","Selon la route"))) | AX6: =IF(A6="","",IF(AT6="A",400,IF(AT6="B",150,0))) | AY6: =IF(A6="","",IF(AV6=1,N(V6),IF(N(U6)>0,ROUND(N(U6)*IFERROR(VLOOKUP(R6,Listes!$AE$3:$AG$12,2,FALSE),0),0),0))) | AZ6: =IF(LEFT(A6,7)="EXEMPLE",1,0) | BA6: =IF(AND(AV6=1,AZ6=0,AC6<>"",W6<>"",N(V6)>0),COUNTIFS($AV$3:AV6,1,$AZ$3:AZ6,0,$AC$3:AC6,"<>",$W$3:W6,"<>",$V$3:V6,">0"),"")
A7: EXEMPLE-005 | B7: 46301.576 | C7: 46301.582 | D7: =IF(OR(B7="",C7=""),"",ROUND((C7-B7)*1440,0)) | E7: Exemple | F7: 5à7 | G7: exemple5@exemple.com | H7: +15145550105 | I7: PME Exemple | J7: entreprise | K7: corpo_5a7 | L7: 46352 | M7: Montréal – centre-ville | N7: 30_74 | O7: 1000_2499 | P7: A | Q7: =IF(A7="","",IFERROR(VLOOKUP(O7,Listes!$R$3:$T$8,2,FALSE),0)+IFERROR(VLOOKUP(J7,Listes!$J$3:$L$6,2,FALSE),0)+IFERROR(VLOOKUP(N7,Listes!$N$3:$P$6,2,FALSE),0)+IF(OR(L7="",B7=""),0,IF(L7-INT(B7)<10,8,IF(L7-INT(B7)<=90,10,5)))+IFERROR(VLOOKUP(AN7,Listes!$V$3:$W$5,2,FALSE),0)+IFERROR(VLOOKUP(AO7,Listes!$Y$3:$Z$5,2,FALSE),0)) | R7: Perdu | S7: Perdu – concurrent | T7: 5 à 7 (1 195 $) | U7: 1195 | X7: bing | Y7: cpc | Z7: msft_corpo | AA7: rsa_prixfixe_v1 | AB7: 5 a 7 entreprise | AD7: EXEMPLE-MSCLKID-005 | AG7: ex-0005 | AH7: non | AI7: non | AK7: non | AL7: Alexandre | AM7: EXEMPLE : concurrent = [nom] ; noter lequel. | AN7: Je recommande, quelqu'un d'autre approuve | AO7: Cette semaine | AQ7: =IF(A7="","",IF(AP7<>"",AP7,IF(LEFT(Z7,11)="gads_marque","Google Search – Marque",IF(LEFT(Z7,12)="gads_mariage","Google Search – Mariage et privé",IF(LEFT(Z7,10)="gads_corpo","Google Search – Corporatif",IF(LEFT(Z7,5)="meta_","Meta – Leads",IF(LEFT(Z7,5)="msft_","Microsoft Ads",IF(LEFT(Z7,8)="chatgpt_","ChatGPT Ads – Test",IF(X7="gbp","Fiche Google (organique)","Autre / non payé"))))))))) | AR7: =IF(K7="","",IFERROR(VLOOKUP(K7,Listes!$F$3:$H$8,3,FALSE),"")) | AS7: =IF(O7="","",IF(AND(M7="Autre (plus de 40 km)",OR(O7="lt600",O7="600_999",O7="1000_2499")),"D",IF(OR(O7="lt600",AND(O7="600_999",K7<>"mariage",K7<>"prive")),"C",IF(OR(O7="2500_4999",O7="5000p",J7="entreprise",J7="organisme",J7="agence"),"A",IF(OR(O7="1000_2499",O7="600_999"),"B",IF(O7="inconnu",IF(OR(N7="75_149",N7="150p"),"A","B"),"")))))) | AT7: =IF(A7="","",IF(P7<>"",P7,AS7)) | AU7: =IF(A7="","",IF(OR(AT7="A",AT7="B"),1,0)) | AV7: =IF(A7="","",IF(OR(R7="Dépôt payé (gagné)",R7="Événement livré",R7="Avis obtenu"),1,0)) | AW7: =IF(A7="","",IF(Q7>70,"Immédiat – propriétaire",IF(Q7>=40,"15 min – personne de garde","Selon la route"))) | AX7: =IF(A7="","",IF(AT7="A",400,IF(AT7="B",150,0))) | AY7: =IF(A7="","",IF(AV7=1,N(V7),IF(N(U7)>0,ROUND(N(U7)*IFERROR(VLOOKUP(R7,Listes!$AE$3:$AG$12,2,FALSE),0),0),0))) | AZ7: =IF(LEFT(A7,7)="EXEMPLE",1,0) | BA7: =IF(AND(AV7=1,AZ7=0,AC7<>"",W7<>"",N(V7)>0),COUNTIFS($AV$3:AV7,1,$AZ$3:AZ7,0,$AC$3:AC7,"<>",$W$3:W7,"<>",$V$3:V7,">0"),"")
D8: =IF(OR(B8="",C8=""),"",ROUND((C8-B8)*1440,0)) | Q8: =IF(A8="","",IFERROR(VLOOKUP(O8,Listes!$R$3:$T$8,2,FALSE),0)+IFERROR(VLOOKUP(J8,Listes!$J$3:$L$6,2,FALSE),0)+IFERROR(VLOOKUP(N8,Listes!$N$3:$P$6,2,FALSE),0)+IF(OR(L8="",B8=""),0,IF(L8-INT(B8)<10,8,IF(L8-INT(B8)<=90,10,5)))+IFERROR(VLOOKUP(AN8,Listes!$V$3:$W$5,2,FALSE),0)+IFERROR(VLOOKUP(AO8,Listes!$Y$3:$Z$5,2,FALSE),0)) | AQ8: =IF(A8="","",IF(AP8<>"",AP8,IF(LEFT(Z8,11)="gads_marque","Google Search – Marque",IF(LEFT(Z8,12)="gads_mariage","Google Search – Mariage et privé",IF(LEFT(Z8,10)="gads_corpo","Google Search – Corporatif",IF(LEFT(Z8,5)="meta_","Meta – Leads",IF(LEFT(Z8,5)="msft_","Microsoft Ads",IF(LEFT(Z8,8)="chatgpt_","ChatGPT Ads – Test",IF(X8="gbp","Fiche Google (organique)","Autre / non payé"))))))))) | AR8: =IF(K8="","",IFERROR(VLOOKUP(K8,Listes!$F$3:$H$8,3,FALSE),"")) | AS8: =IF(O8="","",IF(AND(M8="Autre (plus de 40 km)",OR(O8="lt600",O8="600_999",O8="1000_2499")),"D",IF(OR(O8="lt600",AND(O8="600_999",K8<>"mariage",K8<>"prive")),"C",IF(OR(O8="2500_4999",O8="5000p",J8="entreprise",J8="organisme",J8="agence"),"A",IF(OR(O8="1000_2499",O8="600_999"),"B",IF(O8="inconnu",IF(OR(N8="75_149",N8="150p"),"A","B"),"")))))) | AT8: =IF(A8="","",IF(P8<>"",P8,AS8)) | AU8: =IF(A8="","",IF(OR(AT8="A",AT8="B"),1,0)) | AV8: =IF(A8="","",IF(OR(R8="Dépôt payé (gagné)",R8="Événement livré",R8="Avis obtenu"),1,0)) | AW8: =IF(A8="","",IF(Q8>70,"Immédiat – propriétaire",IF(Q8>=40,"15 min – personne de garde","Selon la route"))) | AX8: =IF(A8="","",IF(AT8="A",400,IF(AT8="B",150,0))) | AY8: =IF(A8="","",IF(AV8=1,N(V8),IF(N(U8)>0,ROUND(N(U8)*IFERROR(VLOOKUP(R8,Listes!$AE$3:$AG$12,2,FALSE),0),0),0))) | AZ8: =IF(LEFT(A8,7)="EXEMPLE",1,0) | BA8: =IF(AND(AV8=1,AZ8=0,AC8<>"",W8<>"",N(V8)>0),COUNTIFS($AV$3:AV8,1,$AZ$3:AZ8,0,$AC$3:AC8,"<>",$W$3:W8,"<>",$V$3:V8,">0"),"")
D9: =IF(OR(B9="",C9=""),"",ROUND((C9-B9)*1440,0)) | Q9: =IF(A9="","",IFERROR(VLOOKUP(O9,Listes!$R$3:$T$8,2,FALSE),0)+IFERROR(VLOOKUP(J9,Listes!$J$3:$L$6,2,FALSE),0)+IFERROR(VLOOKUP(N9,Listes!$N$3:$P$6,2,FALSE),0)+IF(OR(L9="",B9=""),0,IF(L9-INT(B9)<10,8,IF(L9-INT(B9)<=90,10,5)))+IFERROR(VLOOKUP(AN9,Listes!$V$3:$W$5,2,FALSE),0)+IFERROR(VLOOKUP(AO9,Listes!$Y$3:$Z$5,2,FALSE),0)) | AQ9: =IF(A9="","",IF(AP9<>"",AP9,IF(LEFT(Z9,11)="gads_marque","Google Search – Marque",IF(LEFT(Z9,12)="gads_mariage","Google Search – Mariage et privé",IF(LEFT(Z9,10)="gads_corpo","Google Search – Corporatif",IF(LEFT(Z9,5)="meta_","Meta – Leads",IF(LEFT(Z9,5)="msft_","Microsoft Ads",IF(LEFT(Z9,8)="chatgpt_","ChatGPT Ads – Test",IF(X9="gbp","Fiche Google (organique)","Autre / non payé"))))))))) | AR9: =IF(K9="","",IFERROR(VLOOKUP(K9,Listes!$F$3:$H$8,3,FALSE),"")) | AS9: =IF(O9="","",IF(AND(M9="Autre (plus de 40 km)",OR(O9="lt600",O9="600_999",O9="1000_2499")),"D",IF(OR(O9="lt600",AND(O9="600_999",K9<>"mariage",K9<>"prive")),"C",IF(OR(O9="2500_4999",O9="5000p",J9="entreprise",J9="organisme",J9="agence"),"A",IF(OR(O9="1000_2499",O9="600_999"),"B",IF(O9="inconnu",IF(OR(N9="75_149",N9="150p"),"A","B"),"")))))) | AT9: =IF(A9="","",IF(P9<>"",P9,AS9)) | AU9: =IF(A9="","",IF(OR(AT9="A",AT9="B"),1,0)) | AV9: =IF(A9="","",IF(OR(R9="Dépôt payé (gagné)",R9="Événement livré",R9="Avis obtenu"),1,0)) | AW9: =IF(A9="","",IF(Q9>70,"Immédiat – propriétaire",IF(Q9>=40,"15 min – personne de garde","Selon la route"))) | AX9: =IF(A9="","",IF(AT9="A",400,IF(AT9="B",150,0))) | AY9: =IF(A9="","",IF(AV9=1,N(V9),IF(N(U9)>0,ROUND(N(U9)*IFERROR(VLOOKUP(R9,Listes!$AE$3:$AG$12,2,FALSE),0),0),0))) | AZ9: =IF(LEFT(A9,7)="EXEMPLE",1,0) | BA9: =IF(AND(AV9=1,AZ9=0,AC9<>"",W9<>"",N(V9)>0),COUNTIFS($AV$3:AV9,1,$AZ$3:AZ9,0,$AC$3:AC9,"<>",$W$3:W9,"<>",$V$3:V9,">0"),"")
D10: =IF(OR(B10="",C10=""),"",ROUND((C10-B10)*1440,0)) | Q10: =IF(A10="","",IFERROR(VLOOKUP(O10,Listes!$R$3:$T$8,2,FALSE),0)+IFERROR(VLOOKUP(J10,Listes!$J$3:$L$6,2,FALSE),0)+IFERROR(VLOOKUP(N10,Listes!$N$3:$P$6,2,FALSE),0)+IF(OR(L10="",B10=""),0,IF(L10-INT(B10)<10,8,IF(L10-INT(B10)<=90,10,5)))+IFERROR(VLOOKUP(AN10,Listes!$V$3:$W$5,2,FALSE),0)+IFERROR(VLOOKUP(AO10,Listes!$Y$3:$Z$5,2,FALSE),0)) | AQ10: =IF(A10="","",IF(AP10<>"",AP10,IF(LEFT(Z10,11)="gads_marque","Google Search – Marque",IF(LEFT(Z10,12)="gads_mariage","Google Search – Mariage et privé",IF(LEFT(Z10,10)="gads_corpo","Google Search – Corporatif",IF(LEFT(Z10,5)="meta_","Meta – Leads",IF(LEFT(Z10,5)="msft_","Microsoft Ads",IF(LEFT(Z10,8)="chatgpt_","ChatGPT Ads – Test",IF(X10="gbp","Fiche Google (organique)","Autre / non payé"))))))))) | AR10: =IF(K10="","",IFERROR(VLOOKUP(K10,Listes!$F$3:$H$8,3,FALSE),"")) | AS10: =IF(O10="","",IF(AND(M10="Autre (plus de 40 km)",OR(O10="lt600",O10="600_999",O10="1000_2499")),"D",IF(OR(O10="lt600",AND(O10="600_999",K10<>"mariage",K10<>"prive")),"C",IF(OR(O10="2500_4999",O10="5000p",J10="entreprise",J10="organisme",J10="agence"),"A",IF(OR(O10="1000_2499",O10="600_999"),"B",IF(O10="inconnu",IF(OR(N10="75_149",N10="150p"),"A","B"),"")))))) | AT10: =IF(A10="","",IF(P10<>"",P10,AS10)) | AU10: =IF(A10="","",IF(OR(AT10="A",AT10="B"),1,0)) | AV10: =IF(A10="","",IF(OR(R10="Dépôt payé (gagné)",R10="Événement livré",R10="Avis obtenu"),1,0)) | AW10: =IF(A10="","",IF(Q10>70,"Immédiat – propriétaire",IF(Q10>=40,"15 min – personne de garde","Selon la route"))) | AX10: =IF(A10="","",IF(AT10="A",400,IF(AT10="B",150,0))) | AY10: =IF(A10="","",IF(AV10=1,N(V10),IF(N(U10)>0,ROUND(N(U10)*IFERROR(VLOOKUP(R10,Listes!$AE$3:$AG$12,2,FALSE),0),0),0))) | AZ10: =IF(LEFT(A10,7)="EXEMPLE",1,0) | BA10: =IF(AND(AV10=1,AZ10=0,AC10<>"",W10<>"",N(V10)>0),COUNTIFS($AV$3:AV10,1,$AZ$3:AZ10,0,$AC$3:AC10,"<>",$W$3:W10,"<>",$V$3:V10,">0"),"")
D11: =IF(OR(B11="",C11=""),"",ROUND((C11-B11)*1440,0)) | Q11: =IF(A11="","",IFERROR(VLOOKUP(O11,Listes!$R$3:$T$8,2,FALSE),0)+IFERROR(VLOOKUP(J11,Listes!$J$3:$L$6,2,FALSE),0)+IFERROR(VLOOKUP(N11,Listes!$N$3:$P$6,2,FALSE),0)+IF(OR(L11="",B11=""),0,IF(L11-INT(B11)<10,8,IF(L11-INT(B11)<=90,10,5)))+IFERROR(VLOOKUP(AN11,Listes!$V$3:$W$5,2,FALSE),0)+IFERROR(VLOOKUP(AO11,Listes!$Y$3:$Z$5,2,FALSE),0)) | AQ11: =IF(A11="","",IF(AP11<>"",AP11,IF(LEFT(Z11,11)="gads_marque","Google Search – Marque",IF(LEFT(Z11,12)="gads_mariage","Google Search – Mariage et privé",IF(LEFT(Z11,10)="gads_corpo","Google Search – Corporatif",IF(LEFT(Z11,5)="meta_","Meta – Leads",IF(LEFT(Z11,5)="msft_","Microsoft Ads",IF(LEFT(Z11,8)="chatgpt_","ChatGPT Ads – Test",IF(X11="gbp","Fiche Google (organique)","Autre / non payé"))))))))) | AR11: =IF(K11="","",IFERROR(VLOOKUP(K11,Listes!$F$3:$H$8,3,FALSE),"")) | AS11: =IF(O11="","",IF(AND(M11="Autre (plus de 40 km)",OR(O11="lt600",O11="600_999",O11="1000_2499")),"D",IF(OR(O11="lt600",AND(O11="600_999",K11<>"mariage",K11<>"prive")),"C",IF(OR(O11="2500_4999",O11="5000p",J11="entreprise",J11="organisme",J11="agence"),"A",IF(OR(O11="1000_2499",O11="600_999"),"B",IF(O11="inconnu",IF(OR(N11="75_149",N11="150p"),"A","B"),"")))))) | AT11: =IF(A11="","",IF(P11<>"",P11,AS11)) | AU11: =IF(A11="","",IF(OR(AT11="A",AT11="B"),1,0)) | AV11: =IF(A11="","",IF(OR(R11="Dépôt payé (gagné)",R11="Événement livré",R11="Avis obtenu"),1,0)) | AW11: =IF(A11="","",IF(Q11>70,"Immédiat – propriétaire",IF(Q11>=40,"15 min – personne de garde","Selon la route"))) | AX11: =IF(A11="","",IF(AT11="A",400,IF(AT11="B",150,0))) | AY11: =IF(A11="","",IF(AV11=1,N(V11),IF(N(U11)>0,ROUND(N(U11)*IFERROR(VLOOKUP(R11,Listes!$AE$3:$AG$12,2,FALSE),0),0),0))) | AZ11: =IF(LEFT(A11,7)="EXEMPLE",1,0) | BA11: =IF(AND(AV11=1,AZ11=0,AC11<>"",W11<>"",N(V11)>0),COUNTIFS($AV$3:AV11,1,$AZ$3:AZ11,0,$AC$3:AC11,"<>",$W$3:W11,"<>",$V$3:V11,">0"),"")
D12: =IF(OR(B12="",C12=""),"",ROUND((C12-B12)*1440,0)) | Q12: =IF(A12="","",IFERROR(VLOOKUP(O12,Listes!$R$3:$T$8,2,FALSE),0)+IFERROR(VLOOKUP(J12,Listes!$J$3:$L$6,2,FALSE),0)+IFERROR(VLOOKUP(N12,Listes!$N$3:$P$6,2,FALSE),0)+IF(OR(L12="",B12=""),0,IF(L12-INT(B12)<10,8,IF(L12-INT(B12)<=90,10,5)))+IFERROR(VLOOKUP(AN12,Listes!$V$3:$W$5,2,FALSE),0)+IFERROR(VLOOKUP(AO12,Listes!$Y$3:$Z$5,2,FALSE),0)) | AQ12: =IF(A12="","",IF(AP12<>"",AP12,IF(LEFT(Z12,11)="gads_marque","Google Search – Marque",IF(LEFT(Z12,12)="gads_mariage","Google Search – Mariage et privé",IF(LEFT(Z12,10)="gads_corpo","Google Search – Corporatif",IF(LEFT(Z12,5)="meta_","Meta – Leads",IF(LEFT(Z12,5)="msft_","Microsoft Ads",IF(LEFT(Z12,8)="chatgpt_","ChatGPT Ads – Test",IF(X12="gbp","Fiche Google (organique)","Autre / non payé"))))))))) | AR12: =IF(K12="","",IFERROR(VLOOKUP(K12,Listes!$F$3:$H$8,3,FALSE),"")) | AS12: =IF(O12="","",IF(AND(M12="Autre (plus de 40 km)",OR(O12="lt600",O12="600_999",O12="1000_2499")),"D",IF(OR(O12="lt600",AND(O12="600_999",K12<>"mariage",K12<>"prive")),"C",IF(OR(O12="2500_4999",O12="5000p",J12="entreprise",J12="organisme",J12="agence"),"A",IF(OR(O12="1000_2499",O12="600_999"),"B",IF(O12="inconnu",IF(OR(N12="75_149",N12="150p"),"A","B"),"")))))) | AT12: =IF(A12="","",IF(P12<>"",P12,AS12)) | AU12: =IF(A12="","",IF(OR(AT12="A",AT12="B"),1,0)) | AV12: =IF(A12="","",IF(OR(R12="Dépôt payé (gagné)",R12="Événement livré",R12="Avis obtenu"),1,0)) | AW12: =IF(A12="","",IF(Q12>70,"Immédiat – propriétaire",IF(Q12>=40,"15 min – personne de garde","Selon la route"))) | AX12: =IF(A12="","",IF(AT12="A",400,IF(AT12="B",150,0))) | AY12: =IF(A12="","",IF(AV12=1,N(V12),IF(N(U12)>0,ROUND(N(U12)*IFERROR(VLOOKUP(R12,Listes!$AE$3:$AG$12,2,FALSE),0),0),0))) | AZ12: =IF(LEFT(A12,7)="EXEMPLE",1,0) | BA12: =IF(AND(AV12=1,AZ12=0,AC12<>"",W12<>"",N(V12)>0),COUNTIFS($AV$3:AV12,1,$AZ$3:AZ12,0,$AC$3:AC12,"<>",$W$3:W12,"<>",$V$3:V12,">0"),"")
D13: =IF(OR(B13="",C13=""),"",ROUND((C13-B13)*1440,0)) | Q13: =IF(A13="","",IFERROR(VLOOKUP(O13,Listes!$R$3:$T$8,2,FALSE),0)+IFERROR(VLOOKUP(J13,Listes!$J$3:$L$6,2,FALSE),0)+IFERROR(VLOOKUP(N13,Listes!$N$3:$P$6,2,FALSE),0)+IF(OR(L13="",B13=""),0,IF(L13-INT(B13)<10,8,IF(L13-INT(B13)<=90,10,5)))+IFERROR(VLOOKUP(AN13,Listes!$V$3:$W$5,2,FALSE),0)+IFERROR(VLOOKUP(AO13,Listes!$Y$3:$Z$5,2,FALSE),0)) | AQ13: =IF(A13="","",IF(AP13<>"",AP13,IF(LEFT(Z13,11)="gads_marque","Google Search – Marque",IF(LEFT(Z13,12)="gads_mariage","Google Search – Mariage et privé",IF(LEFT(Z13,10)="gads_corpo","Google Search – Corporatif",IF(LEFT(Z13,5)="meta_","Meta – Leads",IF(LEFT(Z13,5)="msft_","Microsoft Ads",IF(LEFT(Z13,8)="chatgpt_","ChatGPT Ads – Test",IF(X13="gbp","Fiche Google (organique)","Autre / non payé"))))))))) | AR13: =IF(K13="","",IFERROR(VLOOKUP(K13,Listes!$F$3:$H$8,3,FALSE),"")) | AS13: =IF(O13="","",IF(AND(M13="Autre (plus de 40 km)",OR(O13="lt600",O13="600_999",O13="1000_2499")),"D",IF(OR(O13="lt600",AND(O13="600_999",K13<>"mariage",K13<>"prive")),"C",IF(OR(O13="2500_4999",O13="5000p",J13="entreprise",J13="organisme",J13="agence"),"A",IF(OR(O13="1000_2499",O13="600_999"),"B",IF(O13="inconnu",IF(OR(N13="75_149",N13="150p"),"A","B"),"")))))) | AT13: =IF(A13="","",IF(P13<>"",P13,AS13)) | AU13: =IF(A13="","",IF(OR(AT13="A",AT13="B"),1,0)) | AV13: =IF(A13="","",IF(OR(R13="Dépôt payé (gagné)",R13="Événement livré",R13="Avis obtenu"),1,0)) | AW13: =IF(A13="","",IF(Q13>70,"Immédiat – propriétaire",IF(Q13>=40,"15 min – personne de garde","Selon la route"))) | AX13: =IF(A13="","",IF(AT13="A",400,IF(AT13="B",150,0))) | AY13: =IF(A13="","",IF(AV13=1,N(V13),IF(N(U13)>0,ROUND(N(U13)*IFERROR(VLOOKUP(R13,Listes!$AE$3:$AG$12,2,FALSE),0),0),0))) | AZ13: =IF(LEFT(A13,7)="EXEMPLE",1,0) | BA13: =IF(AND(AV13=1,AZ13=0,AC13<>"",W13<>"",N(V13)>0),COUNTIFS($AV$3:AV13,1,$AZ$3:AZ13,0,$AC$3:AC13,"<>",$W$3:W13,"<>",$V$3:V13,">0"),"")
D14: =IF(OR(B14="",C14=""),"",ROUND((C14-B14)*1440,0)) | Q14: =IF(A14="","",IFERROR(VLOOKUP(O14,Listes!$R$3:$T$8,2,FALSE),0)+IFERROR(VLOOKUP(J14,Listes!$J$3:$L$6,2,FALSE),0)+IFERROR(VLOOKUP(N14,Listes!$N$3:$P$6,2,FALSE),0)+IF(OR(L14="",B14=""),0,IF(L14-INT(B14)<10,8,IF(L14-INT(B14)<=90,10,5)))+IFERROR(VLOOKUP(AN14,Listes!$V$3:$W$5,2,FALSE),0)+IFERROR(VLOOKUP(AO14,Listes!$Y$3:$Z$5,2,FALSE),0)) | AQ14: =IF(A14="","",IF(AP14<>"",AP14,IF(LEFT(Z14,11)="gads_marque","Google Search – Marque",IF(LEFT(Z14,12)="gads_mariage","Google Search – Mariage et privé",IF(LEFT(Z14,10)="gads_corpo","Google Search – Corporatif",IF(LEFT(Z14,5)="meta_","Meta – Leads",IF(LEFT(Z14,5)="msft_","Microsoft Ads",IF(LEFT(Z14,8)="chatgpt_","ChatGPT Ads – Test",IF(X14="gbp","Fiche Google (organique)","Autre / non payé"))))))))) | AR14: =IF(K14="","",IFERROR(VLOOKUP(K14,Listes!$F$3:$H$8,3,FALSE),"")) | AS14: =IF(O14="","",IF(AND(M14="Autre (plus de 40 km)",OR(O14="lt600",O14="600_999",O14="1000_2499")),"D",IF(OR(O14="lt600",AND(O14="600_999",K14<>"mariage",K14<>"prive")),"C",IF(OR(O14="2500_4999",O14="5000p",J14="entreprise",J14="organisme",J14="agence"),"A",IF(OR(O14="1000_2499",O14="600_999"),"B",IF(O14="inconnu",IF(OR(N14="75_149",N14="150p"),"A","B"),"")))))) | AT14: =IF(A14="","",IF(P14<>"",P14,AS14)) | AU14: =IF(A14="","",IF(OR(AT14="A",AT14="B"),1,0)) | AV14: =IF(A14="","",IF(OR(R14="Dépôt payé (gagné)",R14="Événement livré",R14="Avis obtenu"),1,0)) | AW14: =IF(A14="","",IF(Q14>70,"Immédiat – propriétaire",IF(Q14>=40,"15 min – personne de garde","Selon la route"))) | AX14: =IF(A14="","",IF(AT14="A",400,IF(AT14="B",150,0))) | AY14: =IF(A14="","",IF(AV14=1,N(V14),IF(N(U14)>0,ROUND(N(U14)*IFERROR(VLOOKUP(R14,Listes!$AE$3:$AG$12,2,FALSE),0),0),0))) | AZ14: =IF(LEFT(A14,7)="EXEMPLE",1,0) | BA14: =IF(AND(AV14=1,AZ14=0,AC14<>"",W14<>"",N(V14)>0),COUNTIFS($AV$3:AV14,1,$AZ$3:AZ14,0,$AC$3:AC14,"<>",$W$3:W14,"<>",$V$3:V14,">0"),"")
D15: =IF(OR(B15="",C15=""),"",ROUND((C15-B15)*1440,0)) | Q15: =IF(A15="","",IFERROR(VLOOKUP(O15,Listes!$R$3:$T$8,2,FALSE),0)+IFERROR(VLOOKUP(J15,Listes!$J$3:$L$6,2,FALSE),0)+IFERROR(VLOOKUP(N15,Listes!$N$3:$P$6,2,FALSE),0)+IF(OR(L15="",B15=""),0,IF(L15-INT(B15)<10,8,IF(L15-INT(B15)<=90,10,5)))+IFERROR(VLOOKUP(AN15,Listes!$V$3:$W$5,2,FALSE),0)+IFERROR(VLOOKUP(AO15,Listes!$Y$3:$Z$5,2,FALSE),0)) | AQ15: =IF(A15="","",IF(AP15<>"",AP15,IF(LEFT(Z15,11)="gads_marque","Google Search – Marque",IF(LEFT(Z15,12)="gads_mariage","Google Search – Mariage et privé",IF(LEFT(Z15,10)="gads_corpo","Google Search – Corporatif",IF(LEFT(Z15,5)="meta_","Meta – Leads",IF(LEFT(Z15,5)="msft_","Microsoft Ads",IF(LEFT(Z15,8)="chatgpt_","ChatGPT Ads – Test",IF(X15="gbp","Fiche Google (organique)","Autre / non payé"))))))))) | AR15: =IF(K15="","",IFERROR(VLOOKUP(K15,Listes!$F$3:$H$8,3,FALSE),"")) | AS15: =IF(O15="","",IF(AND(M15="Autre (plus de 40 km)",OR(O15="lt600",O15="600_999",O15="1000_2499")),"D",IF(OR(O15="lt600",AND(O15="600_999",K15<>"mariage",K15<>"prive")),"C",IF(OR(O15="2500_4999",O15="5000p",J15="entreprise",J15="organisme",J15="agence"),"A",IF(OR(O15="1000_2499",O15="600_999"),"B",IF(O15="inconnu",IF(OR(N15="75_149",N15="150p"),"A","B"),"")))))) | AT15: =IF(A15="","",IF(P15<>"",P15,AS15)) | AU15: =IF(A15="","",IF(OR(AT15="A",AT15="B"),1,0)) | AV15: =IF(A15="","",IF(OR(R15="Dépôt payé (gagné)",R15="Événement livré",R15="Avis obtenu"),1,0)) | AW15: =IF(A15="","",IF(Q15>70,"Immédiat – propriétaire",IF(Q15>=40,"15 min – personne de garde","Selon la route"))) | AX15: =IF(A15="","",IF(AT15="A",400,IF(AT15="B",150,0))) | AY15: =IF(A15="","",IF(AV15=1,N(V15),IF(N(U15)>0,ROUND(N(U15)*IFERROR(VLOOKUP(R15,Listes!$AE$3:$AG$12,2,FALSE),0),0),0))) | AZ15: =IF(LEFT(A15,7)="EXEMPLE",1,0) | BA15: =IF(AND(AV15=1,AZ15=0,AC15<>"",W15<>"",N(V15)>0),COUNTIFS($AV$3:AV15,1,$AZ$3:AZ15,0,$AC$3:AC15,"<>",$W$3:W15,"<>",$V$3:V15,">0"),"")
D16: =IF(OR(B16="",C16=""),"",ROUND((C16-B16)*1440,0)) | Q16: =IF(A16="","",IFERROR(VLOOKUP(O16,Listes!$R$3:$T$8,2,FALSE),0)+IFERROR(VLOOKUP(J16,Listes!$J$3:$L$6,2,FALSE),0)+IFERROR(VLOOKUP(N16,Listes!$N$3:$P$6,2,FALSE),0)+IF(OR(L16="",B16=""),0,IF(L16-INT(B16)<10,8,IF(L16-INT(B16)<=90,10,5)))+IFERROR(VLOOKUP(AN16,Listes!$V$3:$W$5,2,FALSE),0)+IFERROR(VLOOKUP(AO16,Listes!$Y$3:$Z$5,2,FALSE),0)) | AQ16: =IF(A16="","",IF(AP16<>"",AP16,IF(LEFT(Z16,11)="gads_marque","Google Search – Marque",IF(LEFT(Z16,12)="gads_mariage","Google Search – Mariage et privé",IF(LEFT(Z16,10)="gads_corpo","Google Search – Corporatif",IF(LEFT(Z16,5)="meta_","Meta – Leads",IF(LEFT(Z16,5)="msft_","Microsoft Ads",IF(LEFT(Z16,8)="chatgpt_","ChatGPT Ads – Test",IF(X16="gbp","Fiche Google (organique)","Autre / non payé"))))))))) | AR16: =IF(K16="","",IFERROR(VLOOKUP(K16,Listes!$F$3:$H$8,3,FALSE),"")) | AS16: =IF(O16="","",IF(AND(M16="Autre (plus de 40 km)",OR(O16="lt600",O16="600_999",O16="1000_2499")),"D",IF(OR(O16="lt600",AND(O16="600_999",K16<>"mariage",K16<>"prive")),"C",IF(OR(O16="2500_4999",O16="5000p",J16="entreprise",J16="organisme",J16="agence"),"A",IF(OR(O16="1000_2499",O16="600_999"),"B",IF(O16="inconnu",IF(OR(N16="75_149",N16="150p"),"A","B"),"")))))) | AT16: =IF(A16="","",IF(P16<>"",P16,AS16)) | AU16: =IF(A16="","",IF(OR(AT16="A",AT16="B"),1,0)) | AV16: =IF(A16="","",IF(OR(R16="Dépôt payé (gagné)",R16="Événement livré",R16="Avis obtenu"),1,0)) | AW16: =IF(A16="","",IF(Q16>70,"Immédiat – propriétaire",IF(Q16>=40,"15 min – personne de garde","Selon la route"))) | AX16: =IF(A16="","",IF(AT16="A",400,IF(AT16="B",150,0))) | AY16: =IF(A16="","",IF(AV16=1,N(V16),IF(N(U16)>0,ROUND(N(U16)*IFERROR(VLOOKUP(R16,Listes!$AE$3:$AG$12,2,FALSE),0),0),0))) | AZ16: =IF(LEFT(A16,7)="EXEMPLE",1,0) | BA16: =IF(AND(AV16=1,AZ16=0,AC16<>"",W16<>"",N(V16)>0),COUNTIFS($AV$3:AV16,1,$AZ$3:AZ16,0,$AC$3:AC16,"<>",$W$3:W16,"<>",$V$3:V16,">0"),"")
D17: =IF(OR(B17="",C17=""),"",ROUND((C17-B17)*1440,0)) | Q17: =IF(A17="","",IFERROR(VLOOKUP(O17,Listes!$R$3:$T$8,2,FALSE),0)+IFERROR(VLOOKUP(J17,Listes!$J$3:$L$6,2,FALSE),0)+IFERROR(VLOOKUP(N17,Listes!$N$3:$P$6,2,FALSE),0)+IF(OR(L17="",B17=""),0,IF(L17-INT(B17)<10,8,IF(L17-INT(B17)<=90,10,5)))+IFERROR(VLOOKUP(AN17,Listes!$V$3:$W$5,2,FALSE),0)+IFERROR(VLOOKUP(AO17,Listes!$Y$3:$Z$5,2,FALSE),0)) | AQ17: =IF(A17="","",IF(AP17<>"",AP17,IF(LEFT(Z17,11)="gads_marque","Google Search – Marque",IF(LEFT(Z17,12)="gads_mariage","Google Search – Mariage et privé",IF(LEFT(Z17,10)="gads_corpo","Google Search – Corporatif",IF(LEFT(Z17,5)="meta_","Meta – Leads",IF(LEFT(Z17,5)="msft_","Microsoft Ads",IF(LEFT(Z17,8)="chatgpt_","ChatGPT Ads – Test",IF(X17="gbp","Fiche Google (organique)","Autre / non payé"))))))))) | AR17: =IF(K17="","",IFERROR(VLOOKUP(K17,Listes!$F$3:$H$8,3,FALSE),"")) | AS17: =IF(O17="","",IF(AND(M17="Autre (plus de 40 km)",OR(O17="lt600",O17="600_999",O17="1000_2499")),"D",IF(OR(O17="lt600",AND(O17="600_999",K17<>"mariage",K17<>"prive")),"C",IF(OR(O17="2500_4999",O17="5000p",J17="entreprise",J17="organisme",J17="agence"),"A",IF(OR(O17="1000_2499",O17="600_999"),"B",IF(O17="inconnu",IF(OR(N17="75_149",N17="150p"),"A","B"),"")))))) | AT17: =IF(A17="","",IF(P17<>"",P17,AS17)) | AU17: =IF(A17="","",IF(OR(AT17="A",AT17="B"),1,0)) | AV17: =IF(A17="","",IF(OR(R17="Dépôt payé (gagné)",R17="Événement livré",R17="Avis obtenu"),1,0)) | AW17: =IF(A17="","",IF(Q17>70,"Immédiat – propriétaire",IF(Q17>=40,"15 min – personne de garde","Selon la route"))) | AX17: =IF(A17="","",IF(AT17="A",400,IF(AT17="B",150,0))) | AY17: =IF(A17="","",IF(AV17=1,N(V17),IF(N(U17)>0,ROUND(N(U17)*IFERROR(VLOOKUP(R17,Listes!$AE$3:$AG$12,2,FALSE),0),0),0))) | AZ17: =IF(LEFT(A17,7)="EXEMPLE",1,0) | BA17: =IF(AND(AV17=1,AZ17=0,AC17<>"",W17<>"",N(V17)>0),COUNTIFS($AV$3:AV17,1,$AZ$3:AZ17,0,$AC$3:AC17,"<>",$W$3:W17,"<>",$V$3:V17,">0"),"")
D18: =IF(OR(B18="",C18=""),"",ROUND((C18-B18)*1440,0)) | Q18: =IF(A18="","",IFERROR(VLOOKUP(O18,Listes!$R$3:$T$8,2,FALSE),0)+IFERROR(VLOOKUP(J18,Listes!$J$3:$L$6,2,FALSE),0)+IFERROR(VLOOKUP(N18,Listes!$N$3:$P$6,2,FALSE),0)+IF(OR(L18="",B18=""),0,IF(L18-INT(B18)<10,8,IF(L18-INT(B18)<=90,10,5)))+IFERROR(VLOOKUP(AN18,Listes!$V$3:$W$5,2,FALSE),0)+IFERROR(VLOOKUP(AO18,Listes!$Y$3:$Z$5,2,FALSE),0)) | AQ18: =IF(A18="","",IF(AP18<>"",AP18,IF(LEFT(Z18,11)="gads_marque","Google Search – Marque",IF(LEFT(Z18,12)="gads_mariage","Google Search – Mariage et privé",IF(LEFT(Z18,10)="gads_corpo","Google Search – Corporatif",IF(LEFT(Z18,5)="meta_","Meta – Leads",IF(LEFT(Z18,5)="msft_","Microsoft Ads",IF(LEFT(Z18,8)="chatgpt_","ChatGPT Ads – Test",IF(X18="gbp","Fiche Google (organique)","Autre / non payé"))))))))) | AR18: =IF(K18="","",IFERROR(VLOOKUP(K18,Listes!$F$3:$H$8,3,FALSE),"")) | AS18: =IF(O18="","",IF(AND(M18="Autre (plus de 40 km)",OR(O18="lt600",O18="600_999",O18="1000_2499")),"D",IF(OR(O18="lt600",AND(O18="600_999",K18<>"mariage",K18<>"prive")),"C",IF(OR(O18="2500_4999",O18="5000p",J18="entreprise",J18="organisme",J18="agence"),"A",IF(OR(O18="1000_2499",O18="600_999"),"B",IF(O18="inconnu",IF(OR(N18="75_149",N18="150p"),"A","B"),"")))))) | AT18: =IF(A18="","",IF(P18<>"",P18,AS18)) | AU18: =IF(A18="","",IF(OR(AT18="A",AT18="B"),1,0)) | AV18: =IF(A18="","",IF(OR(R18="Dépôt payé (gagné)",R18="Événement livré",R18="Avis obtenu"),1,0)) | AW18: =IF(A18="","",IF(Q18>70,"Immédiat – propriétaire",IF(Q18>=40,"15 min – personne de garde","Selon la route"))) | AX18: =IF(A18="","",IF(AT18="A",400,IF(AT18="B",150,0))) | AY18: =IF(A18="","",IF(AV18=1,N(V18),IF(N(U18)>0,ROUND(N(U18)*IFERROR(VLOOKUP(R18,Listes!$AE$3:$AG$12,2,FALSE),0),0),0))) | AZ18: =IF(LEFT(A18,7)="EXEMPLE",1,0) | BA18: =IF(AND(AV18=1,AZ18=0,AC18<>"",W18<>"",N(V18)>0),COUNTIFS($AV$3:AV18,1,$AZ$3:AZ18,0,$AC$3:AC18,"<>",$W$3:W18,"<>",$V$3:V18,">0"),"")
D19: =IF(OR(B19="",C19=""),"",ROUND((C19-B19)*1440,0)) | Q19: =IF(A19="","",IFERROR(VLOOKUP(O19,Listes!$R$3:$T$8,2,FALSE),0)+IFERROR(VLOOKUP(J19,Listes!$J$3:$L$6,2,FALSE),0)+IFERROR(VLOOKUP(N19,Listes!$N$3:$P$6,2,FALSE),0)+IF(OR(L19="",B19=""),0,IF(L19-INT(B19)<10,8,IF(L19-INT(B19)<=90,10,5)))+IFERROR(VLOOKUP(AN19,Listes!$V$3:$W$5,2,FALSE),0)+IFERROR(VLOOKUP(AO19,Listes!$Y$3:$Z$5,2,FALSE),0)) | AQ19: =IF(A19="","",IF(AP19<>"",AP19,IF(LEFT(Z19,11)="gads_marque","Google Search – Marque",IF(LEFT(Z19,12)="gads_mariage","Google Search – Mariage et privé",IF(LEFT(Z19,10)="gads_corpo","Google Search – Corporatif",IF(LEFT(Z19,5)="meta_","Meta – Leads",IF(LEFT(Z19,5)="msft_","Microsoft Ads",IF(LEFT(Z19,8)="chatgpt_","ChatGPT Ads – Test",IF(X19="gbp","Fiche Google (organique)","Autre / non payé"))))))))) | AR19: =IF(K19="","",IFERROR(VLOOKUP(K19,Listes!$F$3:$H$8,3,FALSE),"")) | AS19: =IF(O19="","",IF(AND(M19="Autre (plus de 40 km)",OR(O19="lt600",O19="600_999",O19="1000_2499")),"D",IF(OR(O19="lt600",AND(O19="600_999",K19<>"mariage",K19<>"prive")),"C",IF(OR(O19="2500_4999",O19="5000p",J19="entreprise",J19="organisme",J19="agence"),"A",IF(OR(O19="1000_2499",O19="600_999"),"B",IF(O19="inconnu",IF(OR(N19="75_149",N19="150p"),"A","B"),"")))))) | AT19: =IF(A19="","",IF(P19<>"",P19,AS19)) | AU19: =IF(A19="","",IF(OR(AT19="A",AT19="B"),1,0)) | AV19: =IF(A19="","",IF(OR(R19="Dépôt payé (gagné)",R19="Événement livré",R19="Avis obtenu"),1,0)) | AW19: =IF(A19="","",IF(Q19>70,"Immédiat – propriétaire",IF(Q19>=40,"15 min – personne de garde","Selon la route"))) | AX19: =IF(A19="","",IF(AT19="A",400,IF(AT19="B",150,0))) | AY19: =IF(A19="","",IF(AV19=1,N(V19),IF(N(U19)>0,ROUND(N(U19)*IFERROR(VLOOKUP(R19,Listes!$AE$3:$AG$12,2,FALSE),0),0),0))) | AZ19: =IF(LEFT(A19,7)="EXEMPLE",1,0) | BA19: =IF(AND(AV19=1,AZ19=0,AC19<>"",W19<>"",N(V19)>0),COUNTIFS($AV$3:AV19,1,$AZ$3:AZ19,0,$AC$3:AC19,"<>",$W$3:W19,"<>",$V$3:V19,">0"),"")
... D1002: =IF(OR(B1002="",C1002=""),"",ROUND((C1002-B1002)*1440,0)) | Q1002: =IF(A1002="","",IFERROR(VLOOKUP(O1002,Listes!$R$3:$T$8,2,FALSE),0)+IFERROR(VLOOKUP(J1002,Listes!$J$3:$L$6,2,FALSE),0)+IFERROR(VLOOKUP(N1002,Listes!$N$3:$P$6,2,FALSE),0)+IF(OR(L1002="",B1002=""),0,IF(L1002-INT(B1002)<10,8,IF(L1002-INT(B1002)<=90,10,5)))+IFERROR(VLOOKUP(AN1002,Listes!$V$3:$W$5,2,FALSE),0)+IFERROR(VLOOKUP(AO1002,Listes!$Y$3:$Z$5,2,FALSE),0)) | AQ1002: =IF(A1002="","",IF(AP1002<>"",AP1002,IF(LEFT(Z1002,11)="gads_marque","Google Search – Marque",IF(LEFT(Z1002,12)="gads_mariage","Google Search – Mariage et privé",IF(LEFT(Z1002,10)="gads_corpo","Google Search – Corporatif",IF(LEFT(Z1002,5)="meta_","Meta – Leads",IF(LEFT(Z1002,5)="msft_","Microsoft Ads",IF(LEFT(Z1002,8)="chatgpt_","ChatGPT Ads – Test",IF(X1002="gbp","Fiche Google (organique)","Autre / non payé"))))))))) | AR1002: =IF(K1002="","",IFERROR(VLOOKUP(K1002,Listes!$F$3:$H$8,3,FALSE),"")) | AS1002: =IF(O1002="","",IF(AND(M1002="Autre (plus de 40 km)",OR(O1002="lt600",O1002="600_999",O1002="1000_2499")),"D",IF(OR(O1002="lt600",AND(O1002="600_999",K1002<>"mariage",K1002<>"prive")),"C",IF(OR(O1002="2500_4999",O1002="5000p",J1002="entreprise",J1002="organisme",J1002="agence"),"A",IF(OR(O1002="1000_2499",O1002="600_999"),"B",IF(O1002="inconnu",IF(OR(N1002="75_149",N1002="150p"),"A","B"),"")))))) | AT1002: =IF(A1002="","",IF(P1002<>"",P1002,AS1002)) | AU1002: =IF(A1002="","",IF(OR(AT1002="A",AT1002="B"),1,0)) | AV1002: =IF(A1002="","",IF(OR(R1002="Dépôt payé (gagné)",R1002="Événement livré",R1002="Avis obtenu"),1,0)) | AW1002: =IF(A1002="","",IF(Q1002>70,"Immédiat – propriétaire",IF(Q1002>=40,"15 min – personne de garde","Selon la route"))) | AX1002: =IF(A1002="","",IF(AT1002="A",400,IF(AT1002="B",150,0))) | AY1002: =IF(A1002="","",IF(AV1002=1,N(V1002),IF(N(U1002)>0,ROUND(N(U1002)*IFERROR(VLOOKUP(R1002,Listes!$AE$3:$AG$12,2,FALSE),0),0),0))) | AZ1002: =IF(LEFT(A1002,7)="EXEMPLE",1,0) | BA1002: =IF(AND(AV1002=1,AZ1002=0,AC1002<>"",W1002<>"",N(V1002)>0),COUNTIFS($AV$3:AV1002,1,$AZ$3:AZ1002,0,$AC$3:AC1002,"<>",$W$3:W1002,"<>",$V$3:V1002,">0"),"")

Sheet Dépenses
A1: Dépenses publicitaires quotidiennes par campagne ($ CA, avant taxes)
A2: Saisir chaque matin la dépense de la veille (rapport de chaque plateforme). Cellules jaunes = saisie.
B3: Budget cible ($/jour) | C3: 100 | D3: 80 | E3: 60 | F3: 30 | G3: 20 | H3: 10 | I3: =SUM(C3:H3) | J3: ← total visé : 300 $/jour. Ajuster lors de la bascule saisonnière (COMPTE-RENDU.md).
B4: Dépensé (cumul) | C4: =SUM(C8:C464) | D4: =SUM(D8:D464) | E4: =SUM(E8:E464) | F4: =SUM(F8:F464) | G4: =SUM(G8:G464) | H4: =SUM(H8:H464) | I4: =SUM(C4:H4)
B5: Budget des jours saisis | C5: =C3*COUNT(C8:C464) | D5: =D3*COUNT(D8:D464) | E5: =E3*COUNT(E8:E464) | F5: =F3*COUNT(F8:F464) | G5: =G3*COUNT(G8:G464) | H5: =H3*COUNT(H8:H464) | I5: =SUM(C5:H5)
B6: Écart cumulé ($) | C6: =C4-C5 | D6: =D4-D5 | E6: =E4-E5 | F6: =F4-F5 | G6: =G4-G5 | H6: =H4-H5 | I6: =I4-I5
A7: Date | B7: Jour | C7: Google Search – Corporatif | D7: Meta – Leads | E7: Google Search – Mariage et privé | F7: ChatGPT Ads – Test | G7: Microsoft Ads | H7: Google Search – Marque | I7: Total réel | J7: Budget cible du jour | K7: Écart ($) | L7: Écart (%) | M7: Notes
A8: 46296 | B8: =CHOOSE(WEEKDAY(A8,2),"lundi","mardi","mercredi","jeudi","vendredi","samedi","dimanche") | I8: =IF(COUNT(C8:H8)=0,"",SUM(C8:H8)) | J8: =$I$3 | K8: =IF(I8="","",I8-J8) | L8: =IF(OR(I8="",N(J8)=0),"",K8/J8)
A9: 46297 | B9: =CHOOSE(WEEKDAY(A9,2),"lundi","mardi","mercredi","jeudi","vendredi","samedi","dimanche") | I9: =IF(COUNT(C9:H9)=0,"",SUM(C9:H9)) | J9: =$I$3 | K9: =IF(I9="","",I9-J9) | L9: =IF(OR(I9="",N(J9)=0),"",K9/J9)
A10: 46298 | B10: =CHOOSE(WEEKDAY(A10,2),"lundi","mardi","mercredi","jeudi","vendredi","samedi","dimanche") | I10: =IF(COUNT(C10:H10)=0,"",SUM(C10:H10)) | J10: =$I$3 | K10: =IF(I10="","",I10-J10) | L10: =IF(OR(I10="",N(J10)=0),"",K10/J10)
A11: 46299 | B11: =CHOOSE(WEEKDAY(A11,2),"lundi","mardi","mercredi","jeudi","vendredi","samedi","dimanche") | I11: =IF(COUNT(C11:H11)=0,"",SUM(C11:H11)) | J11: =$I$3 | K11: =IF(I11="","",I11-J11) | L11: =IF(OR(I11="",N(J11)=0),"",K11/J11)
A12: 46300 | B12: =CHOOSE(WEEKDAY(A12,2),"lundi","mardi","mercredi","jeudi","vendredi","samedi","dimanche") | I12: =IF(COUNT(C12:H12)=0,"",SUM(C12:H12)) | J12: =$I$3 | K12: =IF(I12="","",I12-J12) | L12: =IF(OR(I12="",N(J12)=0),"",K12/J12)
A13: 46301 | B13: =CHOOSE(WEEKDAY(A13,2),"lundi","mardi","mercredi","jeudi","vendredi","samedi","dimanche") | I13: =IF(COUNT(C13:H13)=0,"",SUM(C13:H13)) | J13: =$I$3 | K13: =IF(I13="","",I13-J13) | L13: =IF(OR(I13="",N(J13)=0),"",K13/J13)
A14: 46302 | B14: =CHOOSE(WEEKDAY(A14,2),"lundi","mardi","mercredi","jeudi","vendredi","samedi","dimanche") | I14: =IF(COUNT(C14:H14)=0,"",SUM(C14:H14)) | J14: =$I$3 | K14: =IF(I14="","",I14-J14) | L14: =IF(OR(I14="",N(J14)=0),"",K14/J14)
A15: 46303 | B15: =CHOOSE(WEEKDAY(A15,2),"lundi","mardi","mercredi","jeudi","vendredi","samedi","dimanche") | I15: =IF(COUNT(C15:H15)=0,"",SUM(C15:H15)) | J15: =$I$3 | K15: =IF(I15="","",I15-J15) | L15: =IF(OR(I15="",N(J15)=0),"",K15/J15)
A16: 46304 | B16: =CHOOSE(WEEKDAY(A16,2),"lundi","mardi","mercredi","jeudi","vendredi","samedi","dimanche") | I16: =IF(COUNT(C16:H16)=0,"",SUM(C16:H16)) | J16: =$I$3 | K16: =IF(I16="","",I16-J16) | L16: =IF(OR(I16="",N(J16)=0),"",K16/J16)
A17: 46305 | B17: =CHOOSE(WEEKDAY(A17,2),"lundi","mardi","mercredi","jeudi","vendredi","samedi","dimanche") | I17: =IF(COUNT(C17:H17)=0,"",SUM(C17:H17)) | J17: =$I$3 | K17: =IF(I17="","",I17-J17) | L17: =IF(OR(I17="",N(J17)=0),"",K17/J17)
A18: 46306 | B18: =CHOOSE(WEEKDAY(A18,2),"lundi","mardi","mercredi","jeudi","vendredi","samedi","dimanche") | I18: =IF(COUNT(C18:H18)=0,"",SUM(C18:H18)) | J18: =$I$3 | K18: =IF(I18="","",I18-J18) | L18: =IF(OR(I18="",N(J18)=0),"",K18/J18)
A19: 46307 | B19: =CHOOSE(WEEKDAY(A19,2),"lundi","mardi","mercredi","jeudi","vendredi","samedi","dimanche") | I19: =IF(COUNT(C19:H19)=0,"",SUM(C19:H19)) | J19: =$I$3 | K19: =IF(I19="","",I19-J19) | L19: =IF(OR(I19="",N(J19)=0),"",K19/J19)
... A464: 46752 | B464: =CHOOSE(WEEKDAY(A464,2),"lundi","mardi","mercredi","jeudi","vendredi","samedi","dimanche") | I464: =IF(COUNT(C464:H464)=0,"",SUM(C464:H464)) | J464: =$I$3 | K464: =IF(I464="","",I464-J464) | L464: =IF(OR(I464="",N(J464)=0),"",K464/J464)

Sheet Tableau de bord
B1: Tableau de bord des indicateurs — Évenox (revue chaque lundi, 9 h)
B2: Leads comptés par date de réception (cohorte) ; contrats, revenu et ROAS = leads de la même cohorte qui ont atteint « Dépôt payé (gagné) » ou plus. Lead qualifié (LQ) = route A ou B.
F3: Cibles et seuils (tracking-setup.md §10, COMPTE-RENDU.md §4)
B4: Semaine débutant le (lundi) | C4: =TODAY()-WEEKDAY(TODAY(),2)+1 | D4: Formule par défaut = lundi de la semaine en cours ; inscrire une date pour une autre semaine. | F4: Coût par lead qualifié (max) | I4: 150
B5: Mois analysé (1er jour du mois) | C5: =DATE(YEAR(TODAY()),MONTH(TODAY()),1) | D5: Formule par défaut = mois en cours ; inscrire le 1er d'un mois (ex. 2026-11-01). | F5: % de leads qualifiés (min) | I5: 0.4
B6: Inclure les lignes EXEMPLE? | C6: Non | F6: Taux de signature des LQ (min) | I6: 0.25
B7: (critère interne, ne pas modifier) | C7: =IF(C6="Oui",1,0) | F7: Panier moyen (min) | I7: 1500
F8: ROAS (min) | I8: 2.5
F9: Règle « Réduire 30 % » : coût par LQ > | I9: =2*$I$4
F10: Dépense minimale avant décision (par campagne) | I10: 300
F11: Règle « Augmenter +20 % » : coût par LQ < | I11: 100
F12: ChatGPT au jour 30 : LQ minimum | I12: 2
F13: ChatGPT : dépense de référence (≈ 30 jours × 30 $) | I13: 900
F14: Délai de réponse médian visé (min), routes A et B | I14: 5
B16: Décision hebdo (tracking-setup.md §10) : « Réduire 30 % » si coût par LQ > 2 × la cible 2 semaines de suite et ≥ 300 $ dépensés ; « Augmenter +20 % » si coût par LQ < 100 $ et signature ≥ 25 %.
B17: Semaine : du lundi indiqué en C4 au dimanche suivant
B18: Campagne | C18: Dépenses | D18: Budget cible (jours saisis) | E18: Écart vs budget | F18: Leads (tous) | G18: Leads qualifiés (LQ) | H18: % qualifiés | I18: Coût par lead | J18: Coût par LQ | K18: Contrats (dépôts) | L18: Taux de signature | M18: Revenu (montant gagné) | N18: Panier moyen | O18: ROAS | P18: Pipeline pondéré | Q18: Décision | R18: Sem. préc. : dépenses | S18: Sem. préc. : LQ
B19: Google Search – Corporatif | C19: =SUMIFS('Dépenses'!$C$8:$C$464,'Dépenses'!$A$8:$A$464,">="&$C$4,'Dépenses'!$A$8:$A$464,"<"&($C$4+7)) | D19: ='Dépenses'!$C$3*COUNTIFS('Dépenses'!$A$8:$A$464,">="&$C$4,'Dépenses'!$A$8:$A$464,"<"&($C$4+7),'Dépenses'!$C$8:$C$464,"<>") | E19: =C19-D19 | F19: =COUNTIFS(Leads!$AQ$3:$AQ$1002,$B19,Leads!$B$3:$B$1002,">="&$C$4,Leads!$B$3:$B$1002,"<"&($C$4+7),Leads!$AZ$3:$AZ$1002,"<="&$C$7) | G19: =COUNTIFS(Leads!$AQ$3:$AQ$1002,$B19,Leads!$B$3:$B$1002,">="&$C$4,Leads!$B$3:$B$1002,"<"&($C$4+7),Leads!$AZ$3:$AZ$1002,"<="&$C$7,Leads!$AU$3:$AU$1002,1) | H19: =IF(F19=0,"—",G19/F19) | I19: =IF(OR(F19=0,C19=0),"—",C19/F19) | J19: =IF(OR(G19=0,C19=0),"—",C19/G19) | K19: =COUNTIFS(Leads!$AQ$3:$AQ$1002,$B19,Leads!$B$3:$B$1002,">="&$C$4,Leads!$B$3:$B$1002,"<"&($C$4+7),Leads!$AZ$3:$AZ$1002,"<="&$C$7,Leads!$AV$3:$AV$1002,1) | L19: =IF(G19=0,"—",K19/G19) | M19: =SUMIFS(Leads!$V$3:$V$1002,Leads!$AQ$3:$AQ$1002,$B19,Leads!$B$3:$B$1002,">="&$C$4,Leads!$B$3:$B$1002,"<"&($C$4+7),Leads!$AZ$3:$AZ$1002,"<="&$C$7,Leads!$AV$3:$AV$1002,1) | N19: =IF(K19=0,"—",M19/K19) | O19: =IF(C19=0,"—",M19/C19) | P19: =SUMIFS(Leads!$AY$3:$AY$1002,Leads!$AQ$3:$AQ$1002,$B19,Leads!$B$3:$B$1002,">="&$C$4,Leads!$B$3:$B$1002,"<"&($C$4+7),Leads!$AZ$3:$AZ$1002,"<="&$C$7) | Q19: =IF(AND(C19+R19>=$I$10,AND(C19>0,IFERROR(C19/G19,1E+99)>$I$9),AND(R19>0,IFERROR(R19/S19,1E+99)>$I$9)),"Réduire 30 %",IF(AND(C19>0,G19>0,IFERROR(C19/G19,1E+99)<$I$11,IFERROR(K19/G19,0)>=$I$6),"Augmenter +20 %",IF(C19+R19<$I$10,"Garder (données insuffisantes)","Garder"))) | R19: =SUMIFS('Dépenses'!$C$8:$C$464,'Dépenses'!$A$8:$A$464,">="&($C$4-7),'Dépenses'!$A$8:$A$464,"<"&$C$4) | S19: =COUNTIFS(Leads!$AQ$3:$AQ$1002,$B19,Leads!$B$3:$B$1002,">="&($C$4-7),Leads!$B$3:$B$1002,"<"&$C$4,Leads!$AZ$3:$AZ$1002,"<="&$C$7,Leads!$AU$3:$AU$1002,1)
B20: Meta – Leads | C20: =SUMIFS('Dépenses'!$D$8:$D$464,'Dépenses'!$A$8:$A$464,">="&$C$4,'Dépenses'!$A$8:$A$464,"<"&($C$4+7)) | D20: ='Dépenses'!$D$3*COUNTIFS('Dépenses'!$A$8:$A$464,">="&$C$4,'Dépenses'!$A$8:$A$464,"<"&($C$4+7),'Dépenses'!$D$8:$D$464,"<>") | E20: =C20-D20 | F20: =COUNTIFS(Leads!$AQ$3:$AQ$1002,$B20,Leads!$B$3:$B$1002,">="&$C$4,Leads!$B$3:$B$1002,"<"&($C$4+7),Leads!$AZ$3:$AZ$1002,"<="&$C$7) | G20: =COUNTIFS(Leads!$AQ$3:$AQ$1002,$B20,Leads!$B$3:$B$1002,">="&$C$4,Leads!$B$3:$B$1002,"<"&($C$4+7),Leads!$AZ$3:$AZ$1002,"<="&$C$7,Leads!$AU$3:$AU$1002,1) | H20: =IF(F20=0,"—",G20/F20) | I20: =IF(OR(F20=0,C20=0),"—",C20/F20) | J20: =IF(OR(G20=0,C20=0),"—",C20/G20) | K20: =COUNTIFS(Leads!$AQ$3:$AQ$1002,$B20,Leads!$B$3:$B$1002,">="&$C$4,Leads!$B$3:$B$1002,"<"&($C$4+7),Leads!$AZ$3:$AZ$1002,"<="&$C$7,Leads!$AV$3:$AV$1002,1) | L20: =IF(G20=0,"—",K20/G20) | M20: =SUMIFS(Leads!$V$3:$V$1002,Leads!$AQ$3:$AQ$1002,$B20,Leads!$B$3:$B$1002,">="&$C$4,Leads!$B$3:$B$1002,"<"&($C$4+7),Leads!$AZ$3:$AZ$1002,"<="&$C$7,Leads!$AV$3:$AV$1002,1) | N20: =IF(K20=0,"—",M20/K20) | O20: =IF(C20=0,"—",M20/C20) | P20: =SUMIFS(Leads!$AY$3:$AY$1002,Leads!$AQ$3:$AQ$1002,$B20,Leads!$B$3:$B$1002,">="&$C$4,Leads!$B$3:$B$1002,"<"&($C$4+7),Leads!$AZ$3:$AZ$1002,"<="&$C$7) | Q20: =IF(AND(C20+R20>=$I$10,AND(C20>0,IFERROR(C20/G20,1E+99)>$I$9),AND(R20>0,IFERROR(R20/S20,1E+99)>$I$9)),"Réduire 30 %",IF(AND(C20>0,G20>0,IFERROR(C20/G20,1E+99)<$I$11,IFERROR(K20/G20,0)>=$I$6),"Augmenter +20 %",IF(C20+R20<$I$10,"Garder (données insuffisantes)","Garder"))) | R20: =SUMIFS('Dépenses'!$D$8:$D$464,'Dépenses'!$A$8:$A$464,">="&($C$4-7),'Dépenses'!$A$8:$A$464,"<"&$C$4) | S20: =COUNTIFS(Leads!$AQ$3:$AQ$1002,$B20,Leads!$B$3:$B$1002,">="&($C$4-7),Leads!$B$3:$B$1002,"<"&$C$4,Leads!$AZ$3:$AZ$1002,"<="&$C$7,Leads!$AU$3:$AU$1002,1)
B21: Google Search – Mariage et privé | C21: =SUMIFS('Dépenses'!$E$8:$E$464,'Dépenses'!$A$8:$A$464,">="&$C$4,'Dépenses'!$A$8:$A$464,"<"&($C$4+7)) | D21: ='Dépenses'!$E$3*COUNTIFS('Dépenses'!$A$8:$A$464,">="&$C$4,'Dépenses'!$A$8:$A$464,"<"&($C$4+7),'Dépenses'!$E$8:$E$464,"<>") | E21: =C21-D21 | F21: =COUNTIFS(Leads!$AQ$3:$AQ$1002,$B21,Leads!$B$3:$B$1002,">="&$C$4,Leads!$B$3:$B$1002,"<"&($C$4+7),Leads!$AZ$3:$AZ$1002,"<="&$C$7) | G21: =COUNTIFS(Leads!$AQ$3:$AQ$1002,$B21,Leads!$B$3:$B$1002,">="&$C$4,Leads!$B$3:$B$1002,"<"&($C$4+7),Leads!$AZ$3:$AZ$1002,"<="&$C$7,Leads!$AU$3:$AU$1002,1) | H21: =IF(F21=0,"—",G21/F21) | I21: =IF(OR(F21=0,C21=0),"—",C21/F21) | J21: =IF(OR(G21=0,C21=0),"—",C21/G21) | K21: =COUNTIFS(Leads!$AQ$3:$AQ$1002,$B21,Leads!$B$3:$B$1002,">="&$C$4,Leads!$B$3:$B$1002,"<"&($C$4+7),Leads!$AZ$3:$AZ$1002,"<="&$C$7,Leads!$AV$3:$AV$1002,1) | L21: =IF(G21=0,"—",K21/G21) | M21: =SUMIFS(Leads!$V$3:$V$1002,Leads!$AQ$3:$AQ$1002,$B21,Leads!$B$3:$B$1002,">="&$C$4,Leads!$B$3:$B$1002,"<"&($C$4+7),Leads!$AZ$3:$AZ$1002,"<="&$C$7,Leads!$AV$3:$AV$1002,1) | N21: =IF(K21=0,"—",M21/K21) | O21: =IF(C21=0,"—",M21/C21) | P21: =SUMIFS(Leads!$AY$3:$AY$1002,Leads!$AQ$3:$AQ$1002,$B21,Leads!$B$3:$B$1002,">="&$C$4,Leads!$B$3:$B$1002,"<"&($C$4+7),Leads!$AZ$3:$AZ$1002,"<="&$C$7) | Q21: =IF(AND(C21+R21>=$I$10,AND(C21>0,IFERROR(C21/G21,1E+99)>$I$9),AND(R21>0,IFERROR(R21/S21,1E+99)>$I$9)),"Réduire 30 %",IF(AND(C21>0,G21>0,IFERROR(C21/G21,1E+99)<$I$11,IFERROR(K21/G21,0)>=$I$6),"Augmenter +20 %",IF(C21+R21<$I$10,"Garder (données insuffisantes)","Garder"))) | R21: =SUMIFS('Dépenses'!$E$8:$E$464,'Dépenses'!$A$8:$A$464,">="&($C$4-7),'Dépenses'!$A$8:$A$464,"<"&$C$4) | S21: =COUNTIFS(Leads!$AQ$3:$AQ$1002,$B21,Leads!$B$3:$B$1002,">="&($C$4-7),Leads!$B$3:$B$1002,"<"&$C$4,Leads!$AZ$3:$AZ$1002,"<="&$C$7,Leads!$AU$3:$AU$1002,1)
B22: ChatGPT Ads – Test | C22: =SUMIFS('Dépenses'!$F$8:$F$464,'Dépenses'!$A$8:$A$464,">="&$C$4,'Dépenses'!$A$8:$A$464,"<"&($C$4+7)) | D22: ='Dépenses'!$F$3*COUNTIFS('Dépenses'!$A$8:$A$464,">="&$C$4,'Dépenses'!$A$8:$A$464,"<"&($C$4+7),'Dépenses'!$F$8:$F$464,"<>") | E22: =C22-D22 | F22: =COUNTIFS(Leads!$AQ$3:$AQ$1002,$B22,Leads!$B$3:$B$1002,">="&$C$4,Leads!$B$3:$B$1002,"<"&($C$4+7),Leads!$AZ$3:$AZ$1002,"<="&$C$7) | G22: =COUNTIFS(Leads!$AQ$3:$AQ$1002,$B22,Leads!$B$3:$B$1002,">="&$C$4,Leads!$B$3:$B$1002,"<"&($C$4+7),Leads!$AZ$3:$AZ$1002,"<="&$C$7,Leads!$AU$3:$AU$1002,1) | H22: =IF(F22=0,"—",G22/F22) | I22: =IF(OR(F22=0,C22=0),"—",C22/F22) | J22: =IF(OR(G22=0,C22=0),"—",C22/G22) | K22: =COUNTIFS(Leads!$AQ$3:$AQ$1002,$B22,Leads!$B$3:$B$1002,">="&$C$4,Leads!$B$3:$B$1002,"<"&($C$4+7),Leads!$AZ$3:$AZ$1002,"<="&$C$7,Leads!$AV$3:$AV$1002,1) | L22: =IF(G22=0,"—",K22/G22) | M22: =SUMIFS(Leads!$V$3:$V$1002,Leads!$AQ$3:$AQ$1002,$B22,Leads!$B$3:$B$1002,">="&$C$4,Leads!$B$3:$B$1002,"<"&($C$4+7),Leads!$AZ$3:$AZ$1002,"<="&$C$7,Leads!$AV$3:$AV$1002,1) | N22: =IF(K22=0,"—",M22/K22) | O22: =IF(C22=0,"—",M22/C22) | P22: =SUMIFS(Leads!$AY$3:$AY$1002,Leads!$AQ$3:$AQ$1002,$B22,Leads!$B$3:$B$1002,">="&$C$4,Leads!$B$3:$B$1002,"<"&($C$4+7),Leads!$AZ$3:$AZ$1002,"<="&$C$7) | Q22: =IF(AND(C22+R22>=$I$10,AND(C22>0,IFERROR(C22/G22,1E+99)>$I$9),AND(R22>0,IFERROR(R22/S22,1E+99)>$I$9)),"Réduire 30 %",IF(AND(C22>0,G22>0,IFERROR(C22/G22,1E+99)<$I$11,IFERROR(K22/G22,0)>=$I$6),"Augmenter +20 %",IF(C22+R22<$I$10,"Garder (données insuffisantes)","Garder"))) | R22: =SUMIFS('Dépenses'!$F$8:$F$464,'Dépenses'!$A$8:$A$464,">="&($C$4-7),'Dépenses'!$A$8:$A$464,"<"&$C$4) | S22: =COUNTIFS(Leads!$AQ$3:$AQ$1002,$B22,Leads!$B$3:$B$1002,">="&($C$4-7),Leads!$B$3:$B$1002,"<"&$C$4,Leads!$AZ$3:$AZ$1002,"<="&$C$7,Leads!$AU$3:$AU$1002,1)
B23: Microsoft Ads | C23: =SUMIFS('Dépenses'!$G$8:$G$464,'Dépenses'!$A$8:$A$464,">="&$C$4,'Dépenses'!$A$8:$A$464,"<"&($C$4+7)) | D23: ='Dépenses'!$G$3*COUNTIFS('Dépenses'!$A$8:$A$464,">="&$C$4,'Dépenses'!$A$8:$A$464,"<"&($C$4+7),'Dépenses'!$G$8:$G$464,"<>") | E23: =C23-D23 | F23: =COUNTIFS(Leads!$AQ$3:$AQ$1002,$B23,Leads!$B$3:$B$1002,">="&$C$4,Leads!$B$3:$B$1002,"<"&($C$4+7),Leads!$AZ$3:$AZ$1002,"<="&$C$7) | G23: =COUNTIFS(Leads!$AQ$3:$AQ$1002,$B23,Leads!$B$3:$B$1002,">="&$C$4,Leads!$B$3:$B$1002,"<"&($C$4+7),Leads!$AZ$3:$AZ$1002,"<="&$C$7,Leads!$AU$3:$AU$1002,1) | H23: =IF(F23=0,"—",G23/F23) | I23: =IF(OR(F23=0,C23=0),"—",C23/F23) | J23: =IF(OR(G23=0,C23=0),"—",C23/G23) | K23: =COUNTIFS(Leads!$AQ$3:$AQ$1002,$B23,Leads!$B$3:$B$1002,">="&$C$4,Leads!$B$3:$B$1002,"<"&($C$4+7),Leads!$AZ$3:$AZ$1002,"<="&$C$7,Leads!$AV$3:$AV$1002,1) | L23: =IF(G23=0,"—",K23/G23) | M23: =SUMIFS(Leads!$V$3:$V$1002,Leads!$AQ$3:$AQ$1002,$B23,Leads!$B$3:$B$1002,">="&$C$4,Leads!$B$3:$B$1002,"<"&($C$4+7),Leads!$AZ$3:$AZ$1002,"<="&$C$7,Leads!$AV$3:$AV$1002,1) | N23: =IF(K23=0,"—",M23/K23) | O23: =IF(C23=0,"—",M23/C23) | P23: =SUMIFS(Leads!$AY$3:$AY$1002,Leads!$AQ$3:$AQ$1002,$B23,Leads!$B$3:$B$1002,">="&$C$4,Leads!$B$3:$B$1002,"<"&($C$4+7),Leads!$AZ$3:$AZ$1002,"<="&$C$7) | Q23: =IF(AND(C23+R23>=$I$10,AND(C23>0,IFERROR(C23/G23,1E+99)>$I$9),AND(R23>0,IFERROR(R23/S23,1E+99)>$I$9)),"Réduire 30 %",IF(AND(C23>0,G23>0,IFERROR(C23/G23,1E+99)<$I$11,IFERROR(K23/G23,0)>=$I$6),"Augmenter +20 %",IF(C23+R23<$I$10,"Garder (données insuffisantes)","Garder"))) | R23: =SUMIFS('Dépenses'!$G$8:$G$464,'Dépenses'!$A$8:$A$464,">="&($C$4-7),'Dépenses'!$A$8:$A$464,"<"&$C$4) | S23: =COUNTIFS(Leads!$AQ$3:$AQ$1002,$B23,Leads!$B$3:$B$1002,">="&($C$4-7),Leads!$B$3:$B$1002,"<"&$C$4,Leads!$AZ$3:$AZ$1002,"<="&$C$7,Leads!$AU$3:$AU$1002,1)
B24: Google Search – Marque | C24: =SUMIFS('Dépenses'!$H$8:$H$464,'Dépenses'!$A$8:$A$464,">="&$C$4,'Dépenses'!$A$8:$A$464,"<"&($C$4+7)) | D24: ='Dépenses'!$H$3*COUNTIFS('Dépenses'!$A$8:$A$464,">="&$C$4,'Dépenses'!$A$8:$A$464,"<"&($C$4+7),'Dépenses'!$H$8:$H$464,"<>") | E24: =C24-D24 | F24: =COUNTIFS(Leads!$AQ$3:$AQ$1002,$B24,Leads!$B$3:$B$1002,">="&$C$4,Leads!$B$3:$B$1002,"<"&($C$4+7),Leads!$AZ$3:$AZ$1002,"<="&$C$7) | G24: =COUNTIFS(Leads!$AQ$3:$AQ$1002,$B24,Leads!$B$3:$B$1002,">="&$C$4,Leads!$B$3:$B$1002,"<"&($C$4+7),Leads!$AZ$3:$AZ$1002,"<="&$C$7,Leads!$AU$3:$AU$1002,1) | H24: =IF(F24=0,"—",G24/F24) | I24: =IF(OR(F24=0,C24=0),"—",C24/F24) | J24: =IF(OR(G24=0,C24=0),"—",C24/G24) | K24: =COUNTIFS(Leads!$AQ$3:$AQ$1002,$B24,Leads!$B$3:$B$1002,">="&$C$4,Leads!$B$3:$B$1002,"<"&($C$4+7),Leads!$AZ$3:$AZ$1002,"<="&$C$7,Leads!$AV$3:$AV$1002,1) | L24: =IF(G24=0,"—",K24/G24) | M24: =SUMIFS(Leads!$V$3:$V$1002,Leads!$AQ$3:$AQ$1002,$B24,Leads!$B$3:$B$1002,">="&$C$4,Leads!$B$3:$B$1002,"<"&($C$4+7),Leads!$AZ$3:$AZ$1002,"<="&$C$7,Leads!$AV$3:$AV$1002,1) | N24: =IF(K24=0,"—",M24/K24) | O24: =IF(C24=0,"—",M24/C24) | P24: =SUMIFS(Leads!$AY$3:$AY$1002,Leads!$AQ$3:$AQ$1002,$B24,Leads!$B$3:$B$1002,">="&$C$4,Leads!$B$3:$B$1002,"<"&($C$4+7),Leads!$AZ$3:$AZ$1002,"<="&$C$7) | Q24: =IF(AND(C24+R24>=$I$10,AND(C24>0,IFERROR(C24/G24,1E+99)>$I$9),AND(R24>0,IFERROR(R24/S24,1E+99)>$I$9)),"Réduire 30 %",IF(AND(C24>0,G24>0,IFERROR(C24/G24,1E+99)<$I$11,IFERROR(K24/G24,0)>=$I$6),"Augmenter +20 %",IF(C24+R24<$I$10,"Garder (données insuffisantes)","Garder"))) | R24: =SUMIFS('Dépenses'!$H$8:$H$464,'Dépenses'!$A$8:$A$464,">="&($C$4-7),'Dépenses'!$A$8:$A$464,"<"&$C$4) | S24: =COUNTIFS(Leads!$AQ$3:$AQ$1002,$B24,Leads!$B$3:$B$1002,">="&($C$4-7),Leads!$B$3:$B$1002,"<"&$C$4,Leads!$AZ$3:$AZ$1002,"<="&$C$7,Leads!$AU$3:$AU$1002,1)
B25: Autres sources (non payées) | C25: 0 | D25: 0 | E25: =C25-D25 | F25: =COUNTIFS(Leads!$B$3:$B$1002,">="&$C$4,Leads!$B$3:$B$1002,"<"&($C$4+7),Leads!$AZ$3:$AZ$1002,"<="&$C$7)-SUM(F19:F24) | G25: =COUNTIFS(Leads!$B$3:$B$1002,">="&$C$4,Leads!$B$3:$B$1002,"<"&($C$4+7),Leads!$AZ$3:$AZ$1002,"<="&$C$7,Leads!$AU$3:$AU$1002,1)-SUM(G19:G24) | H25: =IF(F25=0,"—",G25/F25) | I25: =IF(OR(F25=0,C25=0),"—",C25/F25) | J25: =IF(OR(G25=0,C25=0),"—",C25/G25) | K25: =COUNTIFS(Leads!$B$3:$B$1002,">="&$C$4,Leads!$B$3:$B$1002,"<"&($C$4+7),Leads!$AZ$3:$AZ$1002,"<="&$C$7,Leads!$AV$3:$AV$1002,1)-SUM(K19:K24) | L25: =IF(G25=0,"—",K25/G25) | M25: =SUMIFS(Leads!$V$3:$V$1002,Leads!$B$3:$B$1002,">="&$C$4,Leads!$B$3:$B$1002,"<"&($C$4+7),Leads!$AZ$3:$AZ$1002,"<="&$C$7,Leads!$AV$3:$AV$1002,1)-SUM(M19:M24) | N25: =IF(K25=0,"—",M25/K25) | O25: =IF(C25=0,"—",M25/C25) | P25: =SUMIFS(Leads!$AY$3:$AY$1002,Leads!$B$3:$B$1002,">="&$C$4,Leads!$B$3:$B$1002,"<"&($C$4+7),Leads!$AZ$3:$AZ$1002,"<="&$C$7)-SUM(P19:P24) | Q25: — | R25: 0 | S25: =COUNTIFS(Leads!$B$3:$B$1002,">="&($C$4-7),Leads!$B$3:$B$1002,"<"&$C$4,Leads!$AZ$3:$AZ$1002,"<="&$C$7,Leads!$AU$3:$AU$1002,1)-SUM(S19:S24)
B26: Total | C26: =SUM(C19:C25) | D26: =SUM(D19:D25) | E26: =C26-D26 | F26: =SUM(F19:F25) | G26: =SUM(G19:G25) | H26: =IF(F26=0,"—",G26/F26) | I26: =IF(OR(F26=0,C26=0),"—",C26/F26) | J26: =IF(OR(G26=0,C26=0),"—",C26/G26) | K26: =SUM(K19:K25) | L26: =IF(G26=0,"—",K26/G26) | M26: =SUM(M19:M25) | N26: =IF(K26=0,"—",M26/K26) | O26: =IF(C26=0,"—",M26/C26) | P26: =SUM(P19:P25) | Q26: — | R26: =SUM(R19:R25) | S26: =SUM(S19:S25)
B29: Coût par LQ de Google Search (Corporatif + Mariage), pour la règle ChatGPT : | C29: =IFERROR((C32+C34)/(G32+G34),1E+99) | D29: (1E+99 = aucun LQ Google ce mois-ci)
B30: Mois : du 1er jour indiqué en C5 à la fin du mois
B31: Campagne | C31: Dépenses | D31: Budget cible (jours saisis) | E31: Écart vs budget | F31: Leads (tous) | G31: Leads qualifiés (LQ) | H31: % qualifiés | I31: Coût par lead | J31: Coût par LQ | K31: Contrats (dépôts) | L31: Taux de signature | M31: Revenu (montant gagné) | N31: Panier moyen | O31: ROAS | P31: Pipeline pondéré | Q31: Décision
