Workbook
Name Panier_ref: Cibles!$B$11
Name Marge_brute: Cibles!$B$14
Name Plafond_CPL: Cibles!$B$15
Name Plafond_contrat_pct: Cibles!$B$16
Name Plafond_contrat: Cibles!$B$17
Name ROAS_min: Cibles!$B$18
Name ROAS_point_mort: Cibles!$B$19
Name S_MaxConv: Cibles!$B$22
Name S_CPAcible: Cibles!$B$23
Name S_CPAmaj: Cibles!$B$24
Name S_Qualite: Cibles!$B$25
Name S_Valeur: Cibles!$B$26
Name S_CoupeCPLQ: Cibles!$B$27
Name S_CoupeCPC: Cibles!$B$28
Name S_PctQual: Cibles!$B$29
Name S_PerdueClass: Cibles!$B$30
Name S_HausseCPC: Cibles!$B$31
Name S_DG: Cibles!$B$32
Name S_MS: Cibles!$B$33
Name Liste_campagnes: Cibles!$A$36:$A$42
Name Sem_ref: 'Règles'!$B$6
Name Debut4: 'Règles'!$B$7
Name Debut2: 'Règles'!$B$8

Sheet Saisie hebdo
A1: Saisie hebdomadaire — Google Ads × Notion
A2: Chaque lundi : remplir les cellules jaunes de la semaine précédente (lundi au dimanche). Colonnes grises = calcul automatique, ne pas modifier. Le mois est celui du lundi de la semaine.
A3: REPÈRES | E3: SAISIE (cellules jaunes) — Google Ads : Coût → Part perdue · Notion : Leads → Valeur | P3: CALCULS AUTOMATIQUES
A4: Semaine (lundi) | B4: Mois | C4: Campagne | D4: Remarque | E4: Coût | F4: Impressions | G4: Clics | H4: Conversions Google (formulaire + appels) | I4: Part d'impr. perdue (budget) % | J4: Part d'impr. perdue (classement) % | K4: Leads reçus (Notion) | L4: Leads qualifiés A/B/C | M4: Soumissions envoyées | N4: Contrats gagnés | O4: Valeur des contrats $ | P4: CTR | Q4: CPC moyen | R4: Taux de conversion | S4: CPA Google (coût ÷ conv.) | T4: Coût par lead | U4: Coût par lead qualifié | V4: Coût par contrat | W4: % qualifiés | X4: Taux de conclusion (contrats ÷ soumissions) | Y4: ROAS (valeur ÷ coût)
A5: 46307 | B5: =DATE(YEAR(A5),MONTH(A5),1) | C5: S-FR | Marque | D5: EXEMPLE — à effacer | E5: 45.3 | F5: 210 | G5: 38 | H5: 6 | I5: 0 | J5: 0.12 | K5: 5 | L5: 4 | M5: 3 | N5: 1 | O5: 1995 | P5: =IF(N(F5)=0,"",G5/F5) | Q5: =IF(N(G5)=0,"",E5/G5) | R5: =IF(N(G5)=0,"",H5/G5) | S5: =IF(N(H5)=0,"",E5/H5) | T5: =IF(N(K5)=0,"",E5/K5) | U5: =IF(N(L5)=0,"",E5/L5) | V5: =IF(N(N5)=0,"",E5/N5) | W5: =IF(N(K5)=0,"",L5/K5) | X5: =IF(N(M5)=0,"",N5/M5) | Y5: =IF(N(E5)=0,"",O5/E5)
A6: 46307 | B6: =DATE(YEAR(A6),MONTH(A6),1) | C6: S-FR | Corporatif & Fêtes | D6: EXEMPLE — à effacer | E6: 612.4 | F6: 3150 | G6: 168 | H6: 9 | I6: 0.05 | J6: 0.38 | K6: 8 | L6: 5 | M6: 4 | N6: 1 | O6: 2495 | P6: =IF(N(F6)=0,"",G6/F6) | Q6: =IF(N(G6)=0,"",E6/G6) | R6: =IF(N(G6)=0,"",H6/G6) | S6: =IF(N(H6)=0,"",E6/H6) | T6: =IF(N(K6)=0,"",E6/K6) | U6: =IF(N(L6)=0,"",E6/L6) | V6: =IF(N(N6)=0,"",E6/N6) | W6: =IF(N(K6)=0,"",L6/K6) | X6: =IF(N(M6)=0,"",N6/M6) | Y6: =IF(N(E6)=0,"",O6/E6)
A7: 46307 | B7: =DATE(YEAR(A7),MONTH(A7),1) | C7: S-FR | Événements privés | P7: =IF(N(F7)=0,"",G7/F7) | Q7: =IF(N(G7)=0,"",E7/G7) | R7: =IF(N(G7)=0,"",H7/G7) | S7: =IF(N(H7)=0,"",E7/H7) | T7: =IF(N(K7)=0,"",E7/K7) | U7: =IF(N(L7)=0,"",E7/L7) | V7: =IF(N(N7)=0,"",E7/N7) | W7: =IF(N(K7)=0,"",L7/K7) | X7: =IF(N(M7)=0,"",N7/M7) | Y7: =IF(N(E7)=0,"",O7/E7)
A8: 46307 | B8: =DATE(YEAR(A8),MONTH(A8),1) | C8: S-EN | Corporate Montréal | P8: =IF(N(F8)=0,"",G8/F8) | Q8: =IF(N(G8)=0,"",E8/G8) | R8: =IF(N(G8)=0,"",H8/G8) | S8: =IF(N(H8)=0,"",E8/H8) | T8: =IF(N(K8)=0,"",E8/K8) | U8: =IF(N(L8)=0,"",E8/L8) | V8: =IF(N(N8)=0,"",E8/N8) | W8: =IF(N(K8)=0,"",L8/K8) | X8: =IF(N(M8)=0,"",N8/M8) | Y8: =IF(N(E8)=0,"",O8/E8)
A9: 46307 | B9: =DATE(YEAR(A9),MONTH(A9),1) | C9: S-FR | Québec-Lévis (test) | P9: =IF(N(F9)=0,"",G9/F9) | Q9: =IF(N(G9)=0,"",E9/G9) | R9: =IF(N(G9)=0,"",H9/G9) | S9: =IF(N(H9)=0,"",E9/H9) | T9: =IF(N(K9)=0,"",E9/K9) | U9: =IF(N(L9)=0,"",E9/L9) | V9: =IF(N(N9)=0,"",E9/N9) | W9: =IF(N(K9)=0,"",L9/K9) | X9: =IF(N(M9)=0,"",N9/M9) | Y9: =IF(N(E9)=0,"",O9/E9)
A10: 46307 | B10: =DATE(YEAR(A10),MONTH(A10),1) | C10: Demand Gen | P10: =IF(N(F10)=0,"",G10/F10) | Q10: =IF(N(G10)=0,"",E10/G10) | R10: =IF(N(G10)=0,"",H10/G10) | S10: =IF(N(H10)=0,"",E10/H10) | T10: =IF(N(K10)=0,"",E10/K10) | U10: =IF(N(L10)=0,"",E10/L10) | V10: =IF(N(N10)=0,"",E10/N10) | W10: =IF(N(K10)=0,"",L10/K10) | X10: =IF(N(M10)=0,"",N10/M10) | Y10: =IF(N(E10)=0,"",O10/E10)
A11: 46307 | B11: =DATE(YEAR(A11),MONTH(A11),1) | C11: Microsoft Ads | P11: =IF(N(F11)=0,"",G11/F11) | Q11: =IF(N(G11)=0,"",E11/G11) | R11: =IF(N(G11)=0,"",H11/G11) | S11: =IF(N(H11)=0,"",E11/H11) | T11: =IF(N(K11)=0,"",E11/K11) | U11: =IF(N(L11)=0,"",E11/L11) | V11: =IF(N(N11)=0,"",E11/N11) | W11: =IF(N(K11)=0,"",L11/K11) | X11: =IF(N(M11)=0,"",N11/M11) | Y11: =IF(N(E11)=0,"",O11/E11)
A12: 46314 | B12: =DATE(YEAR(A12),MONTH(A12),1) | C12: S-FR | Marque | P12: =IF(N(F12)=0,"",G12/F12) | Q12: =IF(N(G12)=0,"",E12/G12) | R12: =IF(N(G12)=0,"",H12/G12) | S12: =IF(N(H12)=0,"",E12/H12) | T12: =IF(N(K12)=0,"",E12/K12) | U12: =IF(N(L12)=0,"",E12/L12) | V12: =IF(N(N12)=0,"",E12/N12) | W12: =IF(N(K12)=0,"",L12/K12) | X12: =IF(N(M12)=0,"",N12/M12) | Y12: =IF(N(E12)=0,"",O12/E12)
A13: 46314 | B13: =DATE(YEAR(A13),MONTH(A13),1) | C13: S-FR | Corporatif & Fêtes | P13: =IF(N(F13)=0,"",G13/F13) | Q13: =IF(N(G13)=0,"",E13/G13) | R13: =IF(N(G13)=0,"",H13/G13) | S13: =IF(N(H13)=0,"",E13/H13) | T13: =IF(N(K13)=0,"",E13/K13) | U13: =IF(N(L13)=0,"",E13/L13) | V13: =IF(N(N13)=0,"",E13/N13) | W13: =IF(N(K13)=0,"",L13/K13) | X13: =IF(N(M13)=0,"",N13/M13) | Y13: =IF(N(E13)=0,"",O13/E13)
A14: 46314 | B14: =DATE(YEAR(A14),MONTH(A14),1) | C14: S-FR | Événements privés | P14: =IF(N(F14)=0,"",G14/F14) | Q14: =IF(N(G14)=0,"",E14/G14) | R14: =IF(N(G14)=0,"",H14/G14) | S14: =IF(N(H14)=0,"",E14/H14) | T14: =IF(N(K14)=0,"",E14/K14) | U14: =IF(N(L14)=0,"",E14/L14) | V14: =IF(N(N14)=0,"",E14/N14) | W14: =IF(N(K14)=0,"",L14/K14) | X14: =IF(N(M14)=0,"",N14/M14) | Y14: =IF(N(E14)=0,"",O14/E14)
A15: 46314 | B15: =DATE(YEAR(A15),MONTH(A15),1) | C15: S-EN | Corporate Montréal | P15: =IF(N(F15)=0,"",G15/F15) | Q15: =IF(N(G15)=0,"",E15/G15) | R15: =IF(N(G15)=0,"",H15/G15) | S15: =IF(N(H15)=0,"",E15/H15) | T15: =IF(N(K15)=0,"",E15/K15) | U15: =IF(N(L15)=0,"",E15/L15) | V15: =IF(N(N15)=0,"",E15/N15) | W15: =IF(N(K15)=0,"",L15/K15) | X15: =IF(N(M15)=0,"",N15/M15) | Y15: =IF(N(E15)=0,"",O15/E15)
A16: 46314 | B16: =DATE(YEAR(A16),MONTH(A16),1) | C16: S-FR | Québec-Lévis (test) | P16: =IF(N(F16)=0,"",G16/F16) | Q16: =IF(N(G16)=0,"",E16/G16) | R16: =IF(N(G16)=0,"",H16/G16) | S16: =IF(N(H16)=0,"",E16/H16) | T16: =IF(N(K16)=0,"",E16/K16) | U16: =IF(N(L16)=0,"",E16/L16) | V16: =IF(N(N16)=0,"",E16/N16) | W16: =IF(N(K16)=0,"",L16/K16) | X16: =IF(N(M16)=0,"",N16/M16) | Y16: =IF(N(E16)=0,"",O16/E16)
A17: 46314 | B17: =DATE(YEAR(A17),MONTH(A17),1) | C17: Demand Gen | P17: =IF(N(F17)=0,"",G17/F17) | Q17: =IF(N(G17)=0,"",E17/G17) | R17: =IF(N(G17)=0,"",H17/G17) | S17: =IF(N(H17)=0,"",E17/H17) | T17: =IF(N(K17)=0,"",E17/K17) | U17: =IF(N(L17)=0,"",E17/L17) | V17: =IF(N(N17)=0,"",E17/N17) | W17: =IF(N(K17)=0,"",L17/K17) | X17: =IF(N(M17)=0,"",N17/M17) | Y17: =IF(N(E17)=0,"",O17/E17)
A18: 46314 | B18: =DATE(YEAR(A18),MONTH(A18),1) | C18: Microsoft Ads | P18: =IF(N(F18)=0,"",G18/F18) | Q18: =IF(N(G18)=0,"",E18/G18) | R18: =IF(N(G18)=0,"",H18/G18) | S18: =IF(N(H18)=0,"",E18/H18) | T18: =IF(N(K18)=0,"",E18/K18) | U18: =IF(N(L18)=0,"",E18/L18) | V18: =IF(N(N18)=0,"",E18/N18) | W18: =IF(N(K18)=0,"",L18/K18) | X18: =IF(N(M18)=0,"",N18/M18) | Y18: =IF(N(E18)=0,"",O18/E18)
... A361: 46657 | B361: =DATE(YEAR(A361),MONTH(A361),1) | C361: Microsoft Ads | P361: =IF(N(F361)=0,"",G361/F361) | Q361: =IF(N(G361)=0,"",E361/G361) | R361: =IF(N(G361)=0,"",H361/G361) | S361: =IF(N(H361)=0,"",E361/H361) | T361: =IF(N(K361)=0,"",E361/K361) | U361: =IF(N(L361)=0,"",E361/L361) | V361: =IF(N(N361)=0,"",E361/N361) | W361: =IF(N(K361)=0,"",L361/K361) | X361: =IF(N(M361)=0,"",N361/M361) | Y361: =IF(N(E361)=0,"",O361/E361)

Sheet Synthèse mensuelle
A1: Synthèse mensuelle par campagne
A2: Calculée automatiquement à partir de « Saisie hebdo » (une semaine compte dans le mois de son lundi). Parts d'impressions perdues = moyenne simple des semaines saisies. Ne rien saisir ici.
A4: Mois | B4: Campagne | C4: Coût | D4: Impressions | E4: Clics | F4: Conversions Google | G4: Part perdue budget (moy.) | H4: Part perdue classement (moy.) | I4: Leads reçus | J4: Leads qualifiés A/B/C | K4: Soumissions | L4: Contrats gagnés | M4: Valeur des contrats | N4: CTR | O4: CPC moyen | P4: Taux de conversion | Q4: CPA Google (coût ÷ conv.) | R4: Coût par lead | S4: Coût par lead qualifié | T4: Coût par contrat | U4: % qualifiés | V4: Taux de conclusion (contrats ÷ soumissions) | W4: ROAS (valeur ÷ coût)
A5: 46296 | B5: S-FR | Marque | C5: =SUMIFS('Saisie hebdo'!$E$5:$E$2000,'Saisie hebdo'!$B$5:$B$2000,$A5,'Saisie hebdo'!$C$5:$C$2000,$B5) | D5: =SUMIFS('Saisie hebdo'!$F$5:$F$2000,'Saisie hebdo'!$B$5:$B$2000,$A5,'Saisie hebdo'!$C$5:$C$2000,$B5) | E5: =SUMIFS('Saisie hebdo'!$G$5:$G$2000,'Saisie hebdo'!$B$5:$B$2000,$A5,'Saisie hebdo'!$C$5:$C$2000,$B5) | F5: =SUMIFS('Saisie hebdo'!$H$5:$H$2000,'Saisie hebdo'!$B$5:$B$2000,$A5,'Saisie hebdo'!$C$5:$C$2000,$B5) | G5: =IFERROR(AVERAGEIFS('Saisie hebdo'!$I$5:$I$2000,'Saisie hebdo'!$B$5:$B$2000,$A5,'Saisie hebdo'!$C$5:$C$2000,$B5),"") | H5: =IFERROR(AVERAGEIFS('Saisie hebdo'!$J$5:$J$2000,'Saisie hebdo'!$B$5:$B$2000,$A5,'Saisie hebdo'!$C$5:$C$2000,$B5),"") | I5: =SUMIFS('Saisie hebdo'!$K$5:$K$2000,'Saisie hebdo'!$B$5:$B$2000,$A5,'Saisie hebdo'!$C$5:$C$2000,$B5) | J5: =SUMIFS('Saisie hebdo'!$L$5:$L$2000,'Saisie hebdo'!$B$5:$B$2000,$A5,'Saisie hebdo'!$C$5:$C$2000,$B5) | K5: =SUMIFS('Saisie hebdo'!$M$5:$M$2000,'Saisie hebdo'!$B$5:$B$2000,$A5,'Saisie hebdo'!$C$5:$C$2000,$B5) | L5: =SUMIFS('Saisie hebdo'!$N$5:$N$2000,'Saisie hebdo'!$B$5:$B$2000,$A5,'Saisie hebdo'!$C$5:$C$2000,$B5) | M5: =SUMIFS('Saisie hebdo'!$O$5:$O$2000,'Saisie hebdo'!$B$5:$B$2000,$A5,'Saisie hebdo'!$C$5:$C$2000,$B5) | N5: =IF(N(D5)=0,"",E5/D5) | O5: =IF(N(E5)=0,"",C5/E5) | P5: =IF(N(E5)=0,"",F5/E5) | Q5: =IF(N(F5)=0,"",C5/F5) | R5: =IF(N(I5)=0,"",C5/I5) | S5: =IF(N(J5)=0,"",C5/J5) | T5: =IF(N(L5)=0,"",C5/L5) | U5: =IF(N(I5)=0,"",J5/I5) | V5: =IF(N(K5)=0,"",L5/K5) | W5: =IF(N(C5)=0,"",M5/C5)
A6: 46296 | B6: S-FR | Corporatif & Fêtes | C6: =SUMIFS('Saisie hebdo'!$E$5:$E$2000,'Saisie hebdo'!$B$5:$B$2000,$A6,'Saisie hebdo'!$C$5:$C$2000,$B6) | D6: =SUMIFS('Saisie hebdo'!$F$5:$F$2000,'Saisie hebdo'!$B$5:$B$2000,$A6,'Saisie hebdo'!$C$5:$C$2000,$B6) | E6: =SUMIFS('Saisie hebdo'!$G$5:$G$2000,'Saisie hebdo'!$B$5:$B$2000,$A6,'Saisie hebdo'!$C$5:$C$2000,$B6) | F6: =SUMIFS('Saisie hebdo'!$H$5:$H$2000,'Saisie hebdo'!$B$5:$B$2000,$A6,'Saisie hebdo'!$C$5:$C$2000,$B6) | G6: =IFERROR(AVERAGEIFS('Saisie hebdo'!$I$5:$I$2000,'Saisie hebdo'!$B$5:$B$2000,$A6,'Saisie hebdo'!$C$5:$C$2000,$B6),"") | H6: =IFERROR(AVERAGEIFS('Saisie hebdo'!$J$5:$J$2000,'Saisie hebdo'!$B$5:$B$2000,$A6,'Saisie hebdo'!$C$5:$C$2000,$B6),"") | I6: =SUMIFS('Saisie hebdo'!$K$5:$K$2000,'Saisie hebdo'!$B$5:$B$2000,$A6,'Saisie hebdo'!$C$5:$C$2000,$B6) | J6: =SUMIFS('Saisie hebdo'!$L$5:$L$2000,'Saisie hebdo'!$B$5:$B$2000,$A6,'Saisie hebdo'!$C$5:$C$2000,$B6) | K6: =SUMIFS('Saisie hebdo'!$M$5:$M$2000,'Saisie hebdo'!$B$5:$B$2000,$A6,'Saisie hebdo'!$C$5:$C$2000,$B6) | L6: =SUMIFS('Saisie hebdo'!$N$5:$N$2000,'Saisie hebdo'!$B$5:$B$2000,$A6,'Saisie hebdo'!$C$5:$C$2000,$B6) | M6: =SUMIFS('Saisie hebdo'!$O$5:$O$2000,'Saisie hebdo'!$B$5:$B$2000,$A6,'Saisie hebdo'!$C$5:$C$2000,$B6) | N6: =IF(N(D6)=0,"",E6/D6) | O6: =IF(N(E6)=0,"",C6/E6) | P6: =IF(N(E6)=0,"",F6/E6) | Q6: =IF(N(F6)=0,"",C6/F6) | R6: =IF(N(I6)=0,"",C6/I6) | S6: =IF(N(J6)=0,"",C6/J6) | T6: =IF(N(L6)=0,"",C6/L6) | U6: =IF(N(I6)=0,"",J6/I6) | V6: =IF(N(K6)=0,"",L6/K6) | W6: =IF(N(C6)=0,"",M6/C6)
A7: 46296 | B7: S-FR | Événements privés | C7: =SUMIFS('Saisie hebdo'!$E$5:$E$2000,'Saisie hebdo'!$B$5:$B$2000,$A7,'Saisie hebdo'!$C$5:$C$2000,$B7) | D7: =SUMIFS('Saisie hebdo'!$F$5:$F$2000,'Saisie hebdo'!$B$5:$B$2000,$A7,'Saisie hebdo'!$C$5:$C$2000,$B7) | E7: =SUMIFS('Saisie hebdo'!$G$5:$G$2000,'Saisie hebdo'!$B$5:$B$2000,$A7,'Saisie hebdo'!$C$5:$C$2000,$B7) | F7: =SUMIFS('Saisie hebdo'!$H$5:$H$2000,'Saisie hebdo'!$B$5:$B$2000,$A7,'Saisie hebdo'!$C$5:$C$2000,$B7) | G7: =IFERROR(AVERAGEIFS('Saisie hebdo'!$I$5:$I$2000,'Saisie hebdo'!$B$5:$B$2000,$A7,'Saisie hebdo'!$C$5:$C$2000,$B7),"") | H7: =IFERROR(AVERAGEIFS('Saisie hebdo'!$J$5:$J$2000,'Saisie hebdo'!$B$5:$B$2000,$A7,'Saisie hebdo'!$C$5:$C$2000,$B7),"") | I7: =SUMIFS('Saisie hebdo'!$K$5:$K$2000,'Saisie hebdo'!$B$5:$B$2000,$A7,'Saisie hebdo'!$C$5:$C$2000,$B7) | J7: =SUMIFS('Saisie hebdo'!$L$5:$L$2000,'Saisie hebdo'!$B$5:$B$2000,$A7,'Saisie hebdo'!$C$5:$C$2000,$B7) | K7: =SUMIFS('Saisie hebdo'!$M$5:$M$2000,'Saisie hebdo'!$B$5:$B$2000,$A7,'Saisie hebdo'!$C$5:$C$2000,$B7) | L7: =SUMIFS('Saisie hebdo'!$N$5:$N$2000,'Saisie hebdo'!$B$5:$B$2000,$A7,'Saisie hebdo'!$C$5:$C$2000,$B7) | M7: =SUMIFS('Saisie hebdo'!$O$5:$O$2000,'Saisie hebdo'!$B$5:$B$2000,$A7,'Saisie hebdo'!$C$5:$C$2000,$B7) | N7: =IF(N(D7)=0,"",E7/D7) | O7: =IF(N(E7)=0,"",C7/E7) | P7: =IF(N(E7)=0,"",F7/E7) | Q7: =IF(N(F7)=0,"",C7/F7) | R7: =IF(N(I7)=0,"",C7/I7) | S7: =IF(N(J7)=0,"",C7/J7) | T7: =IF(N(L7)=0,"",C7/L7) | U7: =IF(N(I7)=0,"",J7/I7) | V7: =IF(N(K7)=0,"",L7/K7) | W7: =IF(N(C7)=0,"",M7/C7)
A8: 46296 | B8: S-EN | Corporate Montréal | C8: =SUMIFS('Saisie hebdo'!$E$5:$E$2000,'Saisie hebdo'!$B$5:$B$2000,$A8,'Saisie hebdo'!$C$5:$C$2000,$B8) | D8: =SUMIFS('Saisie hebdo'!$F$5:$F$2000,'Saisie hebdo'!$B$5:$B$2000,$A8,'Saisie hebdo'!$C$5:$C$2000,$B8) | E8: =SUMIFS('Saisie hebdo'!$G$5:$G$2000,'Saisie hebdo'!$B$5:$B$2000,$A8,'Saisie hebdo'!$C$5:$C$2000,$B8) | F8: =SUMIFS('Saisie hebdo'!$H$5:$H$2000,'Saisie hebdo'!$B$5:$B$2000,$A8,'Saisie hebdo'!$C$5:$C$2000,$B8) | G8: =IFERROR(AVERAGEIFS('Saisie hebdo'!$I$5:$I$2000,'Saisie hebdo'!$B$5:$B$2000,$A8,'Saisie hebdo'!$C$5:$C$2000,$B8),"") | H8: =IFERROR(AVERAGEIFS('Saisie hebdo'!$J$5:$J$2000,'Saisie hebdo'!$B$5:$B$2000,$A8,'Saisie hebdo'!$C$5:$C$2000,$B8),"") | I8: =SUMIFS('Saisie hebdo'!$K$5:$K$2000,'Saisie hebdo'!$B$5:$B$2000,$A8,'Saisie hebdo'!$C$5:$C$2000,$B8) | J8: =SUMIFS('Saisie hebdo'!$L$5:$L$2000,'Saisie hebdo'!$B$5:$B$2000,$A8,'Saisie hebdo'!$C$5:$C$2000,$B8) | K8: =SUMIFS('Saisie hebdo'!$M$5:$M$2000,'Saisie hebdo'!$B$5:$B$2000,$A8,'Saisie hebdo'!$C$5:$C$2000,$B8) | L8: =SUMIFS('Saisie hebdo'!$N$5:$N$2000,'Saisie hebdo'!$B$5:$B$2000,$A8,'Saisie hebdo'!$C$5:$C$2000,$B8) | M8: =SUMIFS('Saisie hebdo'!$O$5:$O$2000,'Saisie hebdo'!$B$5:$B$2000,$A8,'Saisie hebdo'!$C$5:$C$2000,$B8) | N8: =IF(N(D8)=0,"",E8/D8) | O8: =IF(N(E8)=0,"",C8/E8) | P8: =IF(N(E8)=0,"",F8/E8) | Q8: =IF(N(F8)=0,"",C8/F8) | R8: =IF(N(I8)=0,"",C8/I8) | S8: =IF(N(J8)=0,"",C8/J8) | T8: =IF(N(L8)=0,"",C8/L8) | U8: =IF(N(I8)=0,"",J8/I8) | V8: =IF(N(K8)=0,"",L8/K8) | W8: =IF(N(C8)=0,"",M8/C8)
A9: 46296 | B9: S-FR | Québec-Lévis (test) | C9: =SUMIFS('Saisie hebdo'!$E$5:$E$2000,'Saisie hebdo'!$B$5:$B$2000,$A9,'Saisie hebdo'!$C$5:$C$2000,$B9) | D9: =SUMIFS('Saisie hebdo'!$F$5:$F$2000,'Saisie hebdo'!$B$5:$B$2000,$A9,'Saisie hebdo'!$C$5:$C$2000,$B9) | E9: =SUMIFS('Saisie hebdo'!$G$5:$G$2000,'Saisie hebdo'!$B$5:$B$2000,$A9,'Saisie hebdo'!$C$5:$C$2000,$B9) | F9: =SUMIFS('Saisie hebdo'!$H$5:$H$2000,'Saisie hebdo'!$B$5:$B$2000,$A9,'Saisie hebdo'!$C$5:$C$2000,$B9) | G9: =IFERROR(AVERAGEIFS('Saisie hebdo'!$I$5:$I$2000,'Saisie hebdo'!$B$5:$B$2000,$A9,'Saisie hebdo'!$C$5:$C$2000,$B9),"") | H9: =IFERROR(AVERAGEIFS('Saisie hebdo'!$J$5:$J$2000,'Saisie hebdo'!$B$5:$B$2000,$A9,'Saisie hebdo'!$C$5:$C$2000,$B9),"") | I9: =SUMIFS('Saisie hebdo'!$K$5:$K$2000,'Saisie hebdo'!$B$5:$B$2000,$A9,'Saisie hebdo'!$C$5:$C$2000,$B9) | J9: =SUMIFS('Saisie hebdo'!$L$5:$L$2000,'Saisie hebdo'!$B$5:$B$2000,$A9,'Saisie hebdo'!$C$5:$C$2000,$B9) | K9: =SUMIFS('Saisie hebdo'!$M$5:$M$2000,'Saisie hebdo'!$B$5:$B$2000,$A9,'Saisie hebdo'!$C$5:$C$2000,$B9) | L9: =SUMIFS('Saisie hebdo'!$N$5:$N$2000,'Saisie hebdo'!$B$5:$B$2000,$A9,'Saisie hebdo'!$C$5:$C$2000,$B9) | M9: =SUMIFS('Saisie hebdo'!$O$5:$O$2000,'Saisie hebdo'!$B$5:$B$2000,$A9,'Saisie hebdo'!$C$5:$C$2000,$B9) | N9: =IF(N(D9)=0,"",E9/D9) | O9: =IF(N(E9)=0,"",C9/E9) | P9: =IF(N(E9)=0,"",F9/E9) | Q9: =IF(N(F9)=0,"",C9/F9) | R9: =IF(N(I9)=0,"",C9/I9) | S9: =IF(N(J9)=0,"",C9/J9) | T9: =IF(N(L9)=0,"",C9/L9) | U9: =IF(N(I9)=0,"",J9/I9) | V9: =IF(N(K9)=0,"",L9/K9) | W9: =IF(N(C9)=0,"",M9/C9)
A10: 46296 | B10: Demand Gen | C10: =SUMIFS('Saisie hebdo'!$E$5:$E$2000,'Saisie hebdo'!$B$5:$B$2000,$A10,'Saisie hebdo'!$C$5:$C$2000,$B10) | D10: =SUMIFS('Saisie hebdo'!$F$5:$F$2000,'Saisie hebdo'!$B$5:$B$2000,$A10,'Saisie hebdo'!$C$5:$C$2000,$B10) | E10: =SUMIFS('Saisie hebdo'!$G$5:$G$2000,'Saisie hebdo'!$B$5:$B$2000,$A10,'Saisie hebdo'!$C$5:$C$2000,$B10) | F10: =SUMIFS('Saisie hebdo'!$H$5:$H$2000,'Saisie hebdo'!$B$5:$B$2000,$A10,'Saisie hebdo'!$C$5:$C$2000,$B10) | G10: =IFERROR(AVERAGEIFS('Saisie hebdo'!$I$5:$I$2000,'Saisie hebdo'!$B$5:$B$2000,$A10,'Saisie hebdo'!$C$5:$C$2000,$B10),"") | H10: =IFERROR(AVERAGEIFS('Saisie hebdo'!$J$5:$J$2000,'Saisie hebdo'!$B$5:$B$2000,$A10,'Saisie hebdo'!$C$5:$C$2000,$B10),"") | I10: =SUMIFS('Saisie hebdo'!$K$5:$K$2000,'Saisie hebdo'!$B$5:$B$2000,$A10,'Saisie hebdo'!$C$5:$C$2000,$B10) | J10: =SUMIFS('Saisie hebdo'!$L$5:$L$2000,'Saisie hebdo'!$B$5:$B$2000,$A10,'Saisie hebdo'!$C$5:$C$2000,$B10) | K10: =SUMIFS('Saisie hebdo'!$M$5:$M$2000,'Saisie hebdo'!$B$5:$B$2000,$A10,'Saisie hebdo'!$C$5:$C$2000,$B10) | L10: =SUMIFS('Saisie hebdo'!$N$5:$N$2000,'Saisie hebdo'!$B$5:$B$2000,$A10,'Saisie hebdo'!$C$5:$C$2000,$B10) | M10: =SUMIFS('Saisie hebdo'!$O$5:$O$2000,'Saisie hebdo'!$B$5:$B$2000,$A10,'Saisie hebdo'!$C$5:$C$2000,$B10) | N10: =IF(N(D10)=0,"",E10/D10) | O10: =IF(N(E10)=0,"",C10/E10) | P10: =IF(N(E10)=0,"",F10/E10) | Q10: =IF(N(F10)=0,"",C10/F10) | R10: =IF(N(I10)=0,"",C10/I10) | S10: =IF(N(J10)=0,"",C10/J10) | T10: =IF(N(L10)=0,"",C10/L10) | U10: =IF(N(I10)=0,"",J10/I10) | V10: =IF(N(K10)=0,"",L10/K10) | W10: =IF(N(C10)=0,"",M10/C10)
A11: 46296 | B11: Microsoft Ads | C11: =SUMIFS('Saisie hebdo'!$E$5:$E$2000,'Saisie hebdo'!$B$5:$B$2000,$A11,'Saisie hebdo'!$C$5:$C$2000,$B11) | D11: =SUMIFS('Saisie hebdo'!$F$5:$F$2000,'Saisie hebdo'!$B$5:$B$2000,$A11,'Saisie hebdo'!$C$5:$C$2000,$B11) | E11: =SUMIFS('Saisie hebdo'!$G$5:$G$2000,'Saisie hebdo'!$B$5:$B$2000,$A11,'Saisie hebdo'!$C$5:$C$2000,$B11) | F11: =SUMIFS('Saisie hebdo'!$H$5:$H$2000,'Saisie hebdo'!$B$5:$B$2000,$A11,'Saisie hebdo'!$C$5:$C$2000,$B11) | G11: =IFERROR(AVERAGEIFS('Saisie hebdo'!$I$5:$I$2000,'Saisie hebdo'!$B$5:$B$2000,$A11,'Saisie hebdo'!$C$5:$C$2000,$B11),"") | H11: =IFERROR(AVERAGEIFS('Saisie hebdo'!$J$5:$J$2000,'Saisie hebdo'!$B$5:$B$2000,$A11,'Saisie hebdo'!$C$5:$C$2000,$B11),"") | I11: =SUMIFS('Saisie hebdo'!$K$5:$K$2000,'Saisie hebdo'!$B$5:$B$2000,$A11,'Saisie hebdo'!$C$5:$C$2000,$B11) | J11: =SUMIFS('Saisie hebdo'!$L$5:$L$2000,'Saisie hebdo'!$B$5:$B$2000,$A11,'Saisie hebdo'!$C$5:$C$2000,$B11) | K11: =SUMIFS('Saisie hebdo'!$M$5:$M$2000,'Saisie hebdo'!$B$5:$B$2000,$A11,'Saisie hebdo'!$C$5:$C$2000,$B11) | L11: =SUMIFS('Saisie hebdo'!$N$5:$N$2000,'Saisie hebdo'!$B$5:$B$2000,$A11,'Saisie hebdo'!$C$5:$C$2000,$B11) | M11: =SUMIFS('Saisie hebdo'!$O$5:$O$2000,'Saisie hebdo'!$B$5:$B$2000,$A11,'Saisie hebdo'!$C$5:$C$2000,$B11) | N11: =IF(N(D11)=0,"",E11/D11) | O11: =IF(N(E11)=0,"",C11/E11) | P11: =IF(N(E11)=0,"",F11/E11) | Q11: =IF(N(F11)=0,"",C11/F11) | R11: =IF(N(I11)=0,"",C11/I11) | S11: =IF(N(J11)=0,"",C11/J11) | T11: =IF(N(L11)=0,"",C11/L11) | U11: =IF(N(I11)=0,"",J11/I11) | V11: =IF(N(K11)=0,"",L11/K11) | W11: =IF(N(C11)=0,"",M11/C11)
A12: 46296 | B12: Total du compte | C12: =SUMIFS('Saisie hebdo'!$E$5:$E$2000,'Saisie hebdo'!$B$5:$B$2000,$A12) | D12: =SUMIFS('Saisie hebdo'!$F$5:$F$2000,'Saisie hebdo'!$B$5:$B$2000,$A12) | E12: =SUMIFS('Saisie hebdo'!$G$5:$G$2000,'Saisie hebdo'!$B$5:$B$2000,$A12) | F12: =SUMIFS('Saisie hebdo'!$H$5:$H$2000,'Saisie hebdo'!$B$5:$B$2000,$A12) | G12: =IFERROR(AVERAGEIFS('Saisie hebdo'!$I$5:$I$2000,'Saisie hebdo'!$B$5:$B$2000,$A12),"") | H12: =IFERROR(AVERAGEIFS('Saisie hebdo'!$J$5:$J$2000,'Saisie hebdo'!$B$5:$B$2000,$A12),"") | I12: =SUMIFS('Saisie hebdo'!$K$5:$K$2000,'Saisie hebdo'!$B$5:$B$2000,$A12) | J12: =SUMIFS('Saisie hebdo'!$L$5:$L$2000,'Saisie hebdo'!$B$5:$B$2000,$A12) | K12: =SUMIFS('Saisie hebdo'!$M$5:$M$2000,'Saisie hebdo'!$B$5:$B$2000,$A12) | L12: =SUMIFS('Saisie hebdo'!$N$5:$N$2000,'Saisie hebdo'!$B$5:$B$2000,$A12) | M12: =SUMIFS('Saisie hebdo'!$O$5:$O$2000,'Saisie hebdo'!$B$5:$B$2000,$A12) | N12: =IF(N(D12)=0,"",E12/D12) | O12: =IF(N(E12)=0,"",C12/E12) | P12: =IF(N(E12)=0,"",F12/E12) | Q12: =IF(N(F12)=0,"",C12/F12) | R12: =IF(N(I12)=0,"",C12/I12) | S12: =IF(N(J12)=0,"",C12/J12) | T12: =IF(N(L12)=0,"",C12/L12) | U12: =IF(N(I12)=0,"",J12/I12) | V12: =IF(N(K12)=0,"",L12/K12) | W12: =IF(N(C12)=0,"",M12/C12)
A13: 46327 | B13: S-FR | Marque | C13: =SUMIFS('Saisie hebdo'!$E$5:$E$2000,'Saisie hebdo'!$B$5:$B$2000,$A13,'Saisie hebdo'!$C$5:$C$2000,$B13) | D13: =SUMIFS('Saisie hebdo'!$F$5:$F$2000,'Saisie hebdo'!$B$5:$B$2000,$A13,'Saisie hebdo'!$C$5:$C$2000,$B13) | E13: =SUMIFS('Saisie hebdo'!$G$5:$G$2000,'Saisie hebdo'!$B$5:$B$2000,$A13,'Saisie hebdo'!$C$5:$C$2000,$B13) | F13: =SUMIFS('Saisie hebdo'!$H$5:$H$2000,'Saisie hebdo'!$B$5:$B$2000,$A13,'Saisie hebdo'!$C$5:$C$2000,$B13) | G13: =IFERROR(AVERAGEIFS('Saisie hebdo'!$I$5:$I$2000,'Saisie hebdo'!$B$5:$B$2000,$A13,'Saisie hebdo'!$C$5:$C$2000,$B13),"") | H13: =IFERROR(AVERAGEIFS('Saisie hebdo'!$J$5:$J$2000,'Saisie hebdo'!$B$5:$B$2000,$A13,'Saisie hebdo'!$C$5:$C$2000,$B13),"") | I13: =SUMIFS('Saisie hebdo'!$K$5:$K$2000,'Saisie hebdo'!$B$5:$B$2000,$A13,'Saisie hebdo'!$C$5:$C$2000,$B13) | J13: =SUMIFS('Saisie hebdo'!$L$5:$L$2000,'Saisie hebdo'!$B$5:$B$2000,$A13,'Saisie hebdo'!$C$5:$C$2000,$B13) | K13: =SUMIFS('Saisie hebdo'!$M$5:$M$2000,'Saisie hebdo'!$B$5:$B$2000,$A13,'Saisie hebdo'!$C$5:$C$2000,$B13) | L13: =SUMIFS('Saisie hebdo'!$N$5:$N$2000,'Saisie hebdo'!$B$5:$B$2000,$A13,'Saisie hebdo'!$C$5:$C$2000,$B13) | M13: =SUMIFS('Saisie hebdo'!$O$5:$O$2000,'Saisie hebdo'!$B$5:$B$2000,$A13,'Saisie hebdo'!$C$5:$C$2000,$B13) | N13: =IF(N(D13)=0,"",E13/D13) | O13: =IF(N(E13)=0,"",C13/E13) | P13: =IF(N(E13)=0,"",F13/E13) | Q13: =IF(N(F13)=0,"",C13/F13) | R13: =IF(N(I13)=0,"",C13/I13) | S13: =IF(N(J13)=0,"",C13/J13) | T13: =IF(N(L13)=0,"",C13/L13) | U13: =IF(N(I13)=0,"",J13/I13) | V13: =IF(N(K13)=0,"",L13/K13) | W13: =IF(N(C13)=0,"",M13/C13)
A14: 46327 | B14: S-FR | Corporatif & Fêtes | C14: =SUMIFS('Saisie hebdo'!$E$5:$E$2000,'Saisie hebdo'!$B$5:$B$2000,$A14,'Saisie hebdo'!$C$5:$C$2000,$B14) | D14: =SUMIFS('Saisie hebdo'!$F$5:$F$2000,'Saisie hebdo'!$B$5:$B$2000,$A14,'Saisie hebdo'!$C$5:$C$2000,$B14) | E14: =SUMIFS('Saisie hebdo'!$G$5:$G$2000,'Saisie hebdo'!$B$5:$B$2000,$A14,'Saisie hebdo'!$C$5:$C$2000,$B14) | F14: =SUMIFS('Saisie hebdo'!$H$5:$H$2000,'Saisie hebdo'!$B$5:$B$2000,$A14,'Saisie hebdo'!$C$5:$C$2000,$B14) | G14: =IFERROR(AVERAGEIFS('Saisie hebdo'!$I$5:$I$2000,'Saisie hebdo'!$B$5:$B$2000,$A14,'Saisie hebdo'!$C$5:$C$2000,$B14),"") | H14: =IFERROR(AVERAGEIFS('Saisie hebdo'!$J$5:$J$2000,'Saisie hebdo'!$B$5:$B$2000,$A14,'Saisie hebdo'!$C$5:$C$2000,$B14),"") | I14: =SUMIFS('Saisie hebdo'!$K$5:$K$2000,'Saisie hebdo'!$B$5:$B$2000,$A14,'Saisie hebdo'!$C$5:$C$2000,$B14) | J14: =SUMIFS('Saisie hebdo'!$L$5:$L$2000,'Saisie hebdo'!$B$5:$B$2000,$A14,'Saisie hebdo'!$C$5:$C$2000,$B14) | K14: =SUMIFS('Saisie hebdo'!$M$5:$M$2000,'Saisie hebdo'!$B$5:$B$2000,$A14,'Saisie hebdo'!$C$5:$C$2000,$B14) | L14: =SUMIFS('Saisie hebdo'!$N$5:$N$2000,'Saisie hebdo'!$B$5:$B$2000,$A14,'Saisie hebdo'!$C$5:$C$2000,$B14) | M14: =SUMIFS('Saisie hebdo'!$O$5:$O$2000,'Saisie hebdo'!$B$5:$B$2000,$A14,'Saisie hebdo'!$C$5:$C$2000,$B14) | N14: =IF(N(D14)=0,"",E14/D14) | O14: =IF(N(E14)=0,"",C14/E14) | P14: =IF(N(E14)=0,"",F14/E14) | Q14: =IF(N(F14)=0,"",C14/F14) | R14: =IF(N(I14)=0,"",C14/I14) | S14: =IF(N(J14)=0,"",C14/J14) | T14: =IF(N(L14)=0,"",C14/L14) | U14: =IF(N(I14)=0,"",J14/I14) | V14: =IF(N(K14)=0,"",L14/K14) | W14: =IF(N(C14)=0,"",M14/C14)
A15: 46327 | B15: S-FR | Événements privés | C15: =SUMIFS('Saisie hebdo'!$E$5:$E$2000,'Saisie hebdo'!$B$5:$B$2000,$A15,'Saisie hebdo'!$C$5:$C$2000,$B15) | D15: =SUMIFS('Saisie hebdo'!$F$5:$F$2000,'Saisie hebdo'!$B$5:$B$2000,$A15,'Saisie hebdo'!$C$5:$C$2000,$B15) | E15: =SUMIFS('Saisie hebdo'!$G$5:$G$2000,'Saisie hebdo'!$B$5:$B$2000,$A15,'Saisie hebdo'!$C$5:$C$2000,$B15) | F15: =SUMIFS('Saisie hebdo'!$H$5:$H$2000,'Saisie hebdo'!$B$5:$B$2000,$A15,'Saisie hebdo'!$C$5:$C$2000,$B15) | G15: =IFERROR(AVERAGEIFS('Saisie hebdo'!$I$5:$I$2000,'Saisie hebdo'!$B$5:$B$2000,$A15,'Saisie hebdo'!$C$5:$C$2000,$B15),"") | H15: =IFERROR(AVERAGEIFS('Saisie hebdo'!$J$5:$J$2000,'Saisie hebdo'!$B$5:$B$2000,$A15,'Saisie hebdo'!$C$5:$C$2000,$B15),"") | I15: =SUMIFS('Saisie hebdo'!$K$5:$K$2000,'Saisie hebdo'!$B$5:$B$2000,$A15,'Saisie hebdo'!$C$5:$C$2000,$B15) | J15: =SUMIFS('Saisie hebdo'!$L$5:$L$2000,'Saisie hebdo'!$B$5:$B$2000,$A15,'Saisie hebdo'!$C$5:$C$2000,$B15) | K15: =SUMIFS('Saisie hebdo'!$M$5:$M$2000,'Saisie hebdo'!$B$5:$B$2000,$A15,'Saisie hebdo'!$C$5:$C$2000,$B15) | L15: =SUMIFS('Saisie hebdo'!$N$5:$N$2000,'Saisie hebdo'!$B$5:$B$2000,$A15,'Saisie hebdo'!$C$5:$C$2000,$B15) | M15: =SUMIFS('Saisie hebdo'!$O$5:$O$2000,'Saisie hebdo'!$B$5:$B$2000,$A15,'Saisie hebdo'!$C$5:$C$2000,$B15) | N15: =IF(N(D15)=0,"",E15/D15) | O15: =IF(N(E15)=0,"",C15/E15) | P15: =IF(N(E15)=0,"",F15/E15) | Q15: =IF(N(F15)=0,"",C15/F15) | R15: =IF(N(I15)=0,"",C15/I15) | S15: =IF(N(J15)=0,"",C15/J15) | T15: =IF(N(L15)=0,"",C15/L15) | U15: =IF(N(I15)=0,"",J15/I15) | V15: =IF(N(K15)=0,"",L15/K15) | W15: =IF(N(C15)=0,"",M15/C15)
A16: 46327 | B16: S-EN | Corporate Montréal | C16: =SUMIFS('Saisie hebdo'!$E$5:$E$2000,'Saisie hebdo'!$B$5:$B$2000,$A16,'Saisie hebdo'!$C$5:$C$2000,$B16) | D16: =SUMIFS('Saisie hebdo'!$F$5:$F$2000,'Saisie hebdo'!$B$5:$B$2000,$A16,'Saisie hebdo'!$C$5:$C$2000,$B16) | E16: =SUMIFS('Saisie hebdo'!$G$5:$G$2000,'Saisie hebdo'!$B$5:$B$2000,$A16,'Saisie hebdo'!$C$5:$C$2000,$B16) | F16: =SUMIFS('Saisie hebdo'!$H$5:$H$2000,'Saisie hebdo'!$B$5:$B$2000,$A16,'Saisie hebdo'!$C$5:$C$2000,$B16) | G16: =IFERROR(AVERAGEIFS('Saisie hebdo'!$I$5:$I$2000,'Saisie hebdo'!$B$5:$B$2000,$A16,'Saisie hebdo'!$C$5:$C$2000,$B16),"") | H16: =IFERROR(AVERAGEIFS('Saisie hebdo'!$J$5:$J$2000,'Saisie hebdo'!$B$5:$B$2000,$A16,'Saisie hebdo'!$C$5:$C$2000,$B16),"") | I16: =SUMIFS('Saisie hebdo'!$K$5:$K$2000,'Saisie hebdo'!$B$5:$B$2000,$A16,'Saisie hebdo'!$C$5:$C$2000,$B16) | J16: =SUMIFS('Saisie hebdo'!$L$5:$L$2000,'Saisie hebdo'!$B$5:$B$2000,$A16,'Saisie hebdo'!$C$5:$C$2000,$B16) | K16: =SUMIFS('Saisie hebdo'!$M$5:$M$2000,'Saisie hebdo'!$B$5:$B$2000,$A16,'Saisie hebdo'!$C$5:$C$2000,$B16) | L16: =SUMIFS('Saisie hebdo'!$N$5:$N$2000,'Saisie hebdo'!$B$5:$B$2000,$A16,'Saisie hebdo'!$C$5:$C$2000,$B16) | M16: =SUMIFS('Saisie hebdo'!$O$5:$O$2000,'Saisie hebdo'!$B$5:$B$2000,$A16,'Saisie hebdo'!$C$5:$C$2000,$B16) | N16: =IF(N(D16)=0,"",E16/D16) | O16: =IF(N(E16)=0,"",C16/E16) | P16: =IF(N(E16)=0,"",F16/E16) | Q16: =IF(N(F16)=0,"",C16/F16) | R16: =IF(N(I16)=0,"",C16/I16) | S16: =IF(N(J16)=0,"",C16/J16) | T16: =IF(N(L16)=0,"",C16/L16) | U16: =IF(N(I16)=0,"",J16/I16) | V16: =IF(N(K16)=0,"",L16/K16) | W16: =IF(N(C16)=0,"",M16/C16)
A17: 46327 | B17: S-FR | Québec-Lévis (test) | C17: =SUMIFS('Saisie hebdo'!$E$5:$E$2000,'Saisie hebdo'!$B$5:$B$2000,$A17,'Saisie hebdo'!$C$5:$C$2000,$B17) | D17: =SUMIFS('Saisie hebdo'!$F$5:$F$2000,'Saisie hebdo'!$B$5:$B$2000,$A17,'Saisie hebdo'!$C$5:$C$2000,$B17) | E17: =SUMIFS('Saisie hebdo'!$G$5:$G$2000,'Saisie hebdo'!$B$5:$B$2000,$A17,'Saisie hebdo'!$C$5:$C$2000,$B17) | F17: =SUMIFS('Saisie hebdo'!$H$5:$H$2000,'Saisie hebdo'!$B$5:$B$2000,$A17,'Saisie hebdo'!$C$5:$C$2000,$B17) | G17: =IFERROR(AVERAGEIFS('Saisie hebdo'!$I$5:$I$2000,'Saisie hebdo'!$B$5:$B$2000,$A17,'Saisie hebdo'!$C$5:$C$2000,$B17),"") | H17: =IFERROR(AVERAGEIFS('Saisie hebdo'!$J$5:$J$2000,'Saisie hebdo'!$B$5:$B$2000,$A17,'Saisie hebdo'!$C$5:$C$2000,$B17),"") | I17: =SUMIFS('Saisie hebdo'!$K$5:$K$2000,'Saisie hebdo'!$B$5:$B$2000,$A17,'Saisie hebdo'!$C$5:$C$2000,$B17) | J17: =SUMIFS('Saisie hebdo'!$L$5:$L$2000,'Saisie hebdo'!$B$5:$B$2000,$A17,'Saisie hebdo'!$C$5:$C$2000,$B17) | K17: =SUMIFS('Saisie hebdo'!$M$5:$M$2000,'Saisie hebdo'!$B$5:$B$2000,$A17,'Saisie hebdo'!$C$5:$C$2000,$B17) | L17: =SUMIFS('Saisie hebdo'!$N$5:$N$2000,'Saisie hebdo'!$B$5:$B$2000,$A17,'Saisie hebdo'!$C$5:$C$2000,$B17) | M17: =SUMIFS('Saisie hebdo'!$O$5:$O$2000,'Saisie hebdo'!$B$5:$B$2000,$A17,'Saisie hebdo'!$C$5:$C$2000,$B17) | N17: =IF(N(D17)=0,"",E17/D17) | O17: =IF(N(E17)=0,"",C17/E17) | P17: =IF(N(E17)=0,"",F17/E17) | Q17: =IF(N(F17)=0,"",C17/F17) | R17: =IF(N(I17)=0,"",C17/I17) | S17: =IF(N(J17)=0,"",C17/J17) | T17: =IF(N(L17)=0,"",C17/L17) | U17: =IF(N(I17)=0,"",J17/I17) | V17: =IF(N(K17)=0,"",L17/K17) | W17: =IF(N(C17)=0,"",M17/C17)
A18: 46327 | B18: Demand Gen | C18: =SUMIFS('Saisie hebdo'!$E$5:$E$2000,'Saisie hebdo'!$B$5:$B$2000,$A18,'Saisie hebdo'!$C$5:$C$2000,$B18) | D18: =SUMIFS('Saisie hebdo'!$F$5:$F$2000,'Saisie hebdo'!$B$5:$B$2000,$A18,'Saisie hebdo'!$C$5:$C$2000,$B18) | E18: =SUMIFS('Saisie hebdo'!$G$5:$G$2000,'Saisie hebdo'!$B$5:$B$2000,$A18,'Saisie hebdo'!$C$5:$C$2000,$B18) | F18: =SUMIFS('Saisie hebdo'!$H$5:$H$2000,'Saisie hebdo'!$B$5:$B$2000,$A18,'Saisie hebdo'!$C$5:$C$2000,$B18) | G18: =IFERROR(AVERAGEIFS('Saisie hebdo'!$I$5:$I$2000,'Saisie hebdo'!$B$5:$B$2000,$A18,'Saisie hebdo'!$C$5:$C$2000,$B18),"") | H18: =IFERROR(AVERAGEIFS('Saisie hebdo'!$J$5:$J$2000,'Saisie hebdo'!$B$5:$B$2000,$A18,'Saisie hebdo'!$C$5:$C$2000,$B18),"") | I18: =SUMIFS('Saisie hebdo'!$K$5:$K$2000,'Saisie hebdo'!$B$5:$B$2000,$A18,'Saisie hebdo'!$C$5:$C$2000,$B18) | J18: =SUMIFS('Saisie hebdo'!$L$5:$L$2000,'Saisie hebdo'!$B$5:$B$2000,$A18,'Saisie hebdo'!$C$5:$C$2000,$B18) | K18: =SUMIFS('Saisie hebdo'!$M$5:$M$2000,'Saisie hebdo'!$B$5:$B$2000,$A18,'Saisie hebdo'!$C$5:$C$2000,$B18) | L18: =SUMIFS('Saisie hebdo'!$N$5:$N$2000,'Saisie hebdo'!$B$5:$B$2000,$A18,'Saisie hebdo'!$C$5:$C$2000,$B18) | M18: =SUMIFS('Saisie hebdo'!$O$5:$O$2000,'Saisie hebdo'!$B$5:$B$2000,$A18,'Saisie hebdo'!$C$5:$C$2000,$B18) | N18: =IF(N(D18)=0,"",E18/D18) | O18: =IF(N(E18)=0,"",C18/E18) | P18: =IF(N(E18)=0,"",F18/E18) | Q18: =IF(N(F18)=0,"",C18/F18) | R18: =IF(N(I18)=0,"",C18/I18) | S18: =IF(N(J18)=0,"",C18/J18) | T18: =IF(N(L18)=0,"",C18/L18) | U18: =IF(N(I18)=0,"",J18/I18) | V18: =IF(N(K18)=0,"",L18/K18) | W18: =IF(N(C18)=0,"",M18/C18)
A19: 46327 | B19: Microsoft Ads | C19: =SUMIFS('Saisie hebdo'!$E$5:$E$2000,'Saisie hebdo'!$B$5:$B$2000,$A19,'Saisie hebdo'!$C$5:$C$2000,$B19) | D19: =SUMIFS('Saisie hebdo'!$F$5:$F$2000,'Saisie hebdo'!$B$5:$B$2000,$A19,'Saisie hebdo'!$C$5:$C$2000,$B19) | E19: =SUMIFS('Saisie hebdo'!$G$5:$G$2000,'Saisie hebdo'!$B$5:$B$2000,$A19,'Saisie hebdo'!$C$5:$C$2000,$B19) | F19: =SUMIFS('Saisie hebdo'!$H$5:$H$2000,'Saisie hebdo'!$B$5:$B$2000,$A19,'Saisie hebdo'!$C$5:$C$2000,$B19) | G19: =IFERROR(AVERAGEIFS('Saisie hebdo'!$I$5:$I$2000,'Saisie hebdo'!$B$5:$B$2000,$A19,'Saisie hebdo'!$C$5:$C$2000,$B19),"") | H19: =IFERROR(AVERAGEIFS('Saisie hebdo'!$J$5:$J$2000,'Saisie hebdo'!$B$5:$B$2000,$A19,'Saisie hebdo'!$C$5:$C$2000,$B19),"") | I19: =SUMIFS('Saisie hebdo'!$K$5:$K$2000,'Saisie hebdo'!$B$5:$B$2000,$A19,'Saisie hebdo'!$C$5:$C$2000,$B19) | J19: =SUMIFS('Saisie hebdo'!$L$5:$L$2000,'Saisie hebdo'!$B$5:$B$2000,$A19,'Saisie hebdo'!$C$5:$C$2000,$B19) | K19: =SUMIFS('Saisie hebdo'!$M$5:$M$2000,'Saisie hebdo'!$B$5:$B$2000,$A19,'Saisie hebdo'!$C$5:$C$2000,$B19) | L19: =SUMIFS('Saisie hebdo'!$N$5:$N$2000,'Saisie hebdo'!$B$5:$B$2000,$A19,'Saisie hebdo'!$C$5:$C$2000,$B19) | M19: =SUMIFS('Saisie hebdo'!$O$5:$O$2000,'Saisie hebdo'!$B$5:$B$2000,$A19,'Saisie hebdo'!$C$5:$C$2000,$B19) | N19: =IF(N(D19)=0,"",E19/D19) | O19: =IF(N(E19)=0,"",C19/E19) | P19: =IF(N(E19)=0,"",F19/E19) | Q19: =IF(N(F19)=0,"",C19/F19) | R19: =IF(N(I19)=0,"",C19/I19) | S19: =IF(N(J19)=0,"",C19/J19) | T19: =IF(N(L19)=0,"",C19/L19) | U19: =IF(N(I19)=0,"",J19/I19) | V19: =IF(N(K19)=0,"",L19/K19) | W19: =IF(N(C19)=0,"",M19/C19)
A20: 46327 | B20: Total du compte | C20: =SUMIFS('Saisie hebdo'!$E$5:$E$2000,'Saisie hebdo'!$B$5:$B$2000,$A20) | D20: =SUMIFS('Saisie hebdo'!$F$5:$F$2000,'Saisie hebdo'!$B$5:$B$2000,$A20) | E20: =SUMIFS('Saisie hebdo'!$G$5:$G$2000,'Saisie hebdo'!$B$5:$B$2000,$A20) | F20: =SUMIFS('Saisie hebdo'!$H$5:$H$2000,'Saisie hebdo'!$B$5:$B$2000,$A20) | G20: =IFERROR(AVERAGEIFS('Saisie hebdo'!$I$5:$I$2000,'Saisie hebdo'!$B$5:$B$2000,$A20),"") | H20: =IFERROR(AVERAGEIFS('Saisie hebdo'!$J$5:$J$2000,'Saisie hebdo'!$B$5:$B$2000,$A20),"") | I20: =SUMIFS('Saisie hebdo'!$K$5:$K$2000,'Saisie hebdo'!$B$5:$B$2000,$A20) | J20: =SUMIFS('Saisie hebdo'!$L$5:$L$2000,'Saisie hebdo'!$B$5:$B$2000,$A20) | K20: =SUMIFS('Saisie hebdo'!$M$5:$M$2000,'Saisie hebdo'!$B$5:$B$2000,$A20) | L20: =SUMIFS('Saisie hebdo'!$N$5:$N$2000,'Saisie hebdo'!$B$5:$B$2000,$A20) | M20: =SUMIFS('Saisie hebdo'!$O$5:$O$2000,'Saisie hebdo'!$B$5:$B$2000,$A20) | N20: =IF(N(D20)=0,"",E20/D20) | O20: =IF(N(E20)=0,"",C20/E20) | P20: =IF(N(E20)=0,"",F20/E20) | Q20: =IF(N(F20)=0,"",C20/F20) | R20: =IF(N(I20)=0,"",C20/I20) | S20: =IF(N(J20)=0,"",C20/J20) | T20: =IF(N(L20)=0,"",C20/L20) | U20: =IF(N(I20)=0,"",J20/I20) | V20: =IF(N(K20)=0,"",L20/K20) | W20: =IF(N(C20)=0,"",M20/C20)
A21: 46357 | B21: S-FR | Marque | C21: =SUMIFS('Saisie hebdo'!$E$5:$E$2000,'Saisie hebdo'!$B$5:$B$2000,$A21,'Saisie hebdo'!$C$5:$C$2000,$B21) | D21: =SUMIFS('Saisie hebdo'!$F$5:$F$2000,'Saisie hebdo'!$B$5:$B$2000,$A21,'Saisie hebdo'!$C$5:$C$2000,$B21) | E21: =SUMIFS('Saisie hebdo'!$G$5:$G$2000,'Saisie hebdo'!$B$5:$B$2000,$A21,'Saisie hebdo'!$C$5:$C$2000,$B21) | F21: =SUMIFS('Saisie hebdo'!$H$5:$H$2000,'Saisie hebdo'!$B$5:$B$2000,$A21,'Saisie hebdo'!$C$5:$C$2000,$B21) | G21: =IFERROR(AVERAGEIFS('Saisie hebdo'!$I$5:$I$2000,'Saisie hebdo'!$B$5:$B$2000,$A21,'Saisie hebdo'!$C$5:$C$2000,$B21),"") | H21: =IFERROR(AVERAGEIFS('Saisie hebdo'!$J$5:$J$2000,'Saisie hebdo'!$B$5:$B$2000,$A21,'Saisie hebdo'!$C$5:$C$2000,$B21),"") | I21: =SUMIFS('Saisie hebdo'!$K$5:$K$2000,'Saisie hebdo'!$B$5:$B$2000,$A21,'Saisie hebdo'!$C$5:$C$2000,$B21) | J21: =SUMIFS('Saisie hebdo'!$L$5:$L$2000,'Saisie hebdo'!$B$5:$B$2000,$A21,'Saisie hebdo'!$C$5:$C$2000,$B21) | K21: =SUMIFS('Saisie hebdo'!$M$5:$M$2000,'Saisie hebdo'!$B$5:$B$2000,$A21,'Saisie hebdo'!$C$5:$C$2000,$B21) | L21: =SUMIFS('Saisie hebdo'!$N$5:$N$2000,'Saisie hebdo'!$B$5:$B$2000,$A21,'Saisie hebdo'!$C$5:$C$2000,$B21) | M21: =SUMIFS('Saisie hebdo'!$O$5:$O$2000,'Saisie hebdo'!$B$5:$B$2000,$A21,'Saisie hebdo'!$C$5:$C$2000,$B21) | N21: =IF(N(D21)=0,"",E21/D21) | O21: =IF(N(E21)=0,"",C21/E21) | P21: =IF(N(E21)=0,"",F21/E21) | Q21: =IF(N(F21)=0,"",C21/F21) | R21: =IF(N(I21)=0,"",C21/I21) | S21: =IF(N(J21)=0,"",C21/J21) | T21: =IF(N(L21)=0,"",C21/L21) | U21: =IF(N(I21)=0,"",J21/I21) | V21: =IF(N(K21)=0,"",L21/K21) | W21: =IF(N(C21)=0,"",M21/C21)
A22: 46357 | B22: S-FR | Corporatif & Fêtes | C22: =SUMIFS('Saisie hebdo'!$E$5:$E$2000,'Saisie hebdo'!$B$5:$B$2000,$A22,'Saisie hebdo'!$C$5:$C$2000,$B22) | D22: =SUMIFS('Saisie hebdo'!$F$5:$F$2000,'Saisie hebdo'!$B$5:$B$2000,$A22,'Saisie hebdo'!$C$5:$C$2000,$B22) | E22: =SUMIFS('Saisie hebdo'!$G$5:$G$2000,'Saisie hebdo'!$B$5:$B$2000,$A22,'Saisie hebdo'!$C$5:$C$2000,$B22) | F22: =SUMIFS('Saisie hebdo'!$H$5:$H$2000,'Saisie hebdo'!$B$5:$B$2000,$A22,'Saisie hebdo'!$C$5:$C$2000,$B22) | G22: =IFERROR(AVERAGEIFS('Saisie hebdo'!$I$5:$I$2000,'Saisie hebdo'!$B$5:$B$2000,$A22,'Saisie hebdo'!$C$5:$C$2000,$B22),"") | H22: =IFERROR(AVERAGEIFS('Saisie hebdo'!$J$5:$J$2000,'Saisie hebdo'!$B$5:$B$2000,$A22,'Saisie hebdo'!$C$5:$C$2000,$B22),"") | I22: =SUMIFS('Saisie hebdo'!$K$5:$K$2000,'Saisie hebdo'!$B$5:$B$2000,$A22,'Saisie hebdo'!$C$5:$C$2000,$B22) | J22: =SUMIFS('Saisie hebdo'!$L$5:$L$2000,'Saisie hebdo'!$B$5:$B$2000,$A22,'Saisie hebdo'!$C$5:$C$2000,$B22) | K22: =SUMIFS('Saisie hebdo'!$M$5:$M$2000,'Saisie hebdo'!$B$5:$B$2000,$A22,'Saisie hebdo'!$C$5:$C$2000,$B22) | L22: =SUMIFS('Saisie hebdo'!$N$5:$N$2000,'Saisie hebdo'!$B$5:$B$2000,$A22,'Saisie hebdo'!$C$5:$C$2000,$B22) | M22: =SUMIFS('Saisie hebdo'!$O$5:$O$2000,'Saisie hebdo'!$B$5:$B$2000,$A22,'Saisie hebdo'!$C$5:$C$2000,$B22) | N22: =IF(N(D22)=0,"",E22/D22) | O22: =IF(N(E22)=0,"",C22/E22) | P22: =IF(N(E22)=0,"",F22/E22) | Q22: =IF(N(F22)=0,"",C22/F22) | R22: =IF(N(I22)=0,"",C22/I22) | S22: =IF(N(J22)=0,"",C22/J22) | T22: =IF(N(L22)=0,"",C22/L22) | U22: =IF(N(I22)=0,"",J22/I22) | V22: =IF(N(K22)=0,"",L22/K22) | W22: =IF(N(C22)=0,"",M22/C22)
A23: 46357 | B23: S-FR | Événements privés | C23: =SUMIFS('Saisie hebdo'!$E$5:$E$2000,'Saisie hebdo'!$B$5:$B$2000,$A23,'Saisie hebdo'!$C$5:$C$2000,$B23) | D23: =SUMIFS('Saisie hebdo'!$F$5:$F$2000,'Saisie hebdo'!$B$5:$B$2000,$A23,'Saisie hebdo'!$C$5:$C$2000,$B23) | E23: =SUMIFS('Saisie hebdo'!$G$5:$G$2000,'Saisie hebdo'!$B$5:$B$2000,$A23,'Saisie hebdo'!$C$5:$C$2000,$B23) | F23: =SUMIFS('Saisie hebdo'!$H$5:$H$2000,'Saisie hebdo'!$B$5:$B$2000,$A23,'Saisie hebdo'!$C$5:$C$2000,$B23) | G23: =IFERROR(AVERAGEIFS('Saisie hebdo'!$I$5:$I$2000,'Saisie hebdo'!$B$5:$B$2000,$A23,'Saisie hebdo'!$C$5:$C$2000,$B23),"") | H23: =IFERROR(AVERAGEIFS('Saisie hebdo'!$J$5:$J$2000,'Saisie hebdo'!$B$5:$B$2000,$A23,'Saisie hebdo'!$C$5:$C$2000,$B23),"") | I23: =SUMIFS('Saisie hebdo'!$K$5:$K$2000,'Saisie hebdo'!$B$5:$B$2000,$A23,'Saisie hebdo'!$C$5:$C$2000,$B23) | J23: =SUMIFS('Saisie hebdo'!$L$5:$L$2000,'Saisie hebdo'!$B$5:$B$2000,$A23,'Saisie hebdo'!$C$5:$C$2000,$B23) | K23: =SUMIFS('Saisie hebdo'!$M$5:$M$2000,'Saisie hebdo'!$B$5:$B$2000,$A23,'Saisie hebdo'!$C$5:$C$2000,$B23) | L23: =SUMIFS('Saisie hebdo'!$N$5:$N$2000,'Saisie hebdo'!$B$5:$B$2000,$A23,'Saisie hebdo'!$C$5:$C$2000,$B23) | M23: =SUMIFS('Saisie hebdo'!$O$5:$O$2000,'Saisie hebdo'!$B$5:$B$2000,$A23,'Saisie hebdo'!$C$5:$C$2000,$B23) | N23: =IF(N(D23)=0,"",E23/D23) | O23: =IF(N(E23)=0,"",C23/E23) | P23: =IF(N(E23)=0,"",F23/E23) | Q23: =IF(N(F23)=0,"",C23/F23) | R23: =IF(N(I23)=0,"",C23/I23) | S23: =IF(N(J23)=0,"",C23/J23) | T23: =IF(N(L23)=0,"",C23/L23) | U23: =IF(N(I23)=0,"",J23/I23) | V23: =IF(N(K23)=0,"",L23/K23) | W23: =IF(N(C23)=0,"",M23/C23)
A24: 46357 | B24: S-EN | Corporate Montréal | C24: =SUMIFS('Saisie hebdo'!$E$5:$E$2000,'Saisie hebdo'!$B$5:$B$2000,$A24,'Saisie hebdo'!$C$5:$C$2000,$B24) | D24: =SUMIFS('Saisie hebdo'!$F$5:$F$2000,'Saisie hebdo'!$B$5:$B$2000,$A24,'Saisie hebdo'!$C$5:$C$2000,$B24) | E24: =SUMIFS('Saisie hebdo'!$G$5:$G$2000,'Saisie hebdo'!$B$5:$B$2000,$A24,'Saisie hebdo'!$C$5:$C$2000,$B24) | F24: =SUMIFS('Saisie hebdo'!$H$5:$H$2000,'Saisie hebdo'!$B$5:$B$2000,$A24,'Saisie hebdo'!$C$5:$C$2000,$B24) | G24: =IFERROR(AVERAGEIFS('Saisie hebdo'!$I$5:$I$2000,'Saisie hebdo'!$B$5:$B$2000,$A24,'Saisie hebdo'!$C$5:$C$2000,$B24),"") | H24: =IFERROR(AVERAGEIFS('Saisie hebdo'!$J$5:$J$2000,'Saisie hebdo'!$B$5:$B$2000,$A24,'Saisie hebdo'!$C$5:$C$2000,$B24),"") | I24: =SUMIFS('Saisie hebdo'!$K$5:$K$2000,'Saisie hebdo'!$B$5:$B$2000,$A24,'Saisie hebdo'!$C$5:$C$2000,$B24) | J24: =SUMIFS('Saisie hebdo'!$L$5:$L$2000,'Saisie hebdo'!$B$5:$B$2000,$A24,'Saisie hebdo'!$C$5:$C$2000,$B24) | K24: =SUMIFS('Saisie hebdo'!$M$5:$M$2000,'Saisie hebdo'!$B$5:$B$2000,$A24,'Saisie hebdo'!$C$5:$C$2000,$B24) | L24: =SUMIFS('Saisie hebdo'!$N$5:$N$2000,'Saisie hebdo'!$B$5:$B$2000,$A24,'Saisie hebdo'!$C$5:$C$2000,$B24) | M24: =SUMIFS('Saisie hebdo'!$O$5:$O$2000,'Saisie hebdo'!$B$5:$B$2000,$A24,'Saisie hebdo'!$C$5:$C$2000,$B24) | N24: =IF(N(D24)=0,"",E24/D24) | O24: =IF(N(E24)=0,"",C24/E24) | P24: =IF(N(E24)=0,"",F24/E24) | Q24: =IF(N(F24)=0,"",C24/F24) | R24: =IF(N(I24)=0,"",C24/I24) | S24: =IF(N(J24)=0,"",C24/J24) | T24: =IF(N(L24)=0,"",C24/L24) | U24: =IF(N(I24)=0,"",J24/I24) | V24: =IF(N(K24)=0,"",L24/K24) | W24: =IF(N(C24)=0,"",M24/C24)
A25: 46357 | B25: S-FR | Québec-Lévis (test) | C25: =SUMIFS('Saisie hebdo'!$E$5:$E$2000,'Saisie hebdo'!$B$5:$B$2000,$A25,'Saisie hebdo'!$C$5:$C$2000,$B25) | D25: =SUMIFS('Saisie hebdo'!$F$5:$F$2000,'Saisie hebdo'!$B$5:$B$2000,$A25,'Saisie hebdo'!$C$5:$C$2000,$B25) | E25: =SUMIFS('Saisie hebdo'!$G$5:$G$2000,'Saisie hebdo'!$B$5:$B$2000,$A25,'Saisie hebdo'!$C$5:$C$2000,$B25) | F25: =SUMIFS('Saisie hebdo'!$H$5:$H$2000,'Saisie hebdo'!$B$5:$B$2000,$A25,'Saisie hebdo'!$C$5:$C$2000,$B25) | G25: =IFERROR(AVERAGEIFS('Saisie hebdo'!$I$5:$I$2000,'Saisie hebdo'!$B$5:$B$2000,$A25,'Saisie hebdo'!$C$5:$C$2000,$B25),"") | H25: =IFERROR(AVERAGEIFS('Saisie hebdo'!$J$5:$J$2000,'Saisie hebdo'!$B$5:$B$2000,$A25,'Saisie hebdo'!$C$5:$C$2000,$B25),"") | I25: =SUMIFS('Saisie hebdo'!$K$5:$K$2000,'Saisie hebdo'!$B$5:$B$2000,$A25,'Saisie hebdo'!$C$5:$C$2000,$B25) | J25: =SUMIFS('Saisie hebdo'!$L$5:$L$2000,'Saisie hebdo'!$B$5:$B$2000,$A25,'Saisie hebdo'!$C$5:$C$2000,$B25) | K25: =SUMIFS('Saisie hebdo'!$M$5:$M$2000,'Saisie hebdo'!$B$5:$B$2000,$A25,'Saisie hebdo'!$C$5:$C$2000,$B25) | L25: =SUMIFS('Saisie hebdo'!$N$5:$N$2000,'Saisie hebdo'!$B$5:$B$2000,$A25,'Saisie hebdo'!$C$5:$C$2000,$B25) | M25: =SUMIFS('Saisie hebdo'!$O$5:$O$2000,'Saisie hebdo'!$B$5:$B$2000,$A25,'Saisie hebdo'!$C$5:$C$2000,$B25) | N25: =IF(N(D25)=0,"",E25/D25) | O25: =IF(N(E25)=0,"",C25/E25) | P25: =IF(N(E25)=0,"",F25/E25) | Q25: =IF(N(F25)=0,"",C25/F25) | R25: =IF(N(I25)=0,"",C25/I25) | S25: =IF(N(J25)=0,"",C25/J25) | T25: =IF(N(L25)=0,"",C25/L25) | U25: =IF(N(I25)=0,"",J25/I25) | V25: =IF(N(K25)=0,"",L25/K25) | W25: =IF(N(C25)=0,"",M25/C25)
A26: 46357 | B26: Demand Gen | C26: =SUMIFS('Saisie hebdo'!$E$5:$E$2000,'Saisie hebdo'!$B$5:$B$2000,$A26,'Saisie hebdo'!$C$5:$C$2000,$B26) | D26: =SUMIFS('Saisie hebdo'!$F$5:$F$2000,'Saisie hebdo'!$B$5:$B$2000,$A26,'Saisie hebdo'!$C$5:$C$2000,$B26) | E26: =SUMIFS('Saisie hebdo'!$G$5:$G$2000,'Saisie hebdo'!$B$5:$B$2000,$A26,'Saisie hebdo'!$C$5:$C$2000,$B26) | F26: =SUMIFS('Saisie hebdo'!$H$5:$H$2000,'Saisie hebdo'!$B$5:$B$2000,$A26,'Saisie hebdo'!$C$5:$C$2000,$B26) | G26: =IFERROR(AVERAGEIFS('Saisie hebdo'!$I$5:$I$2000,'Saisie hebdo'!$B$5:$B$2000,$A26,'Saisie hebdo'!$C$5:$C$2000,$B26),"") | H26: =IFERROR(AVERAGEIFS('Saisie hebdo'!$J$5:$J$2000,'Saisie hebdo'!$B$5:$B$2000,$A26,'Saisie hebdo'!$C$5:$C$2000,$B26),"") | I26: =SUMIFS('Saisie hebdo'!$K$5:$K$2000,'Saisie hebdo'!$B$5:$B$2000,$A26,'Saisie hebdo'!$C$5:$C$2000,$B26) | J26: =SUMIFS('Saisie hebdo'!$L$5:$L$2000,'Saisie hebdo'!$B$5:$B$2000,$A26,'Saisie hebdo'!$C$5:$C$2000,$B26) | K26: =SUMIFS('Saisie hebdo'!$M$5:$M$2000,'Saisie hebdo'!$B$5:$B$2000,$A26,'Saisie hebdo'!$C$5:$C$2000,$B26) | L26: =SUMIFS('Saisie hebdo'!$N$5:$N$2000,'Saisie hebdo'!$B$5:$B$2000,$A26,'Saisie hebdo'!$C$5:$C$2000,$B26) | M26: =SUMIFS('Saisie hebdo'!$O$5:$O$2000,'Saisie hebdo'!$B$5:$B$2000,$A26,'Saisie hebdo'!$C$5:$C$2000,$B26) | N26: =IF(N(D26)=0,"",E26/D26) | O26: =IF(N(E26)=0,"",C26/E26) | P26: =IF(N(E26)=0,"",F26/E26) | Q26: =IF(N(F26)=0,"",C26/F26) | R26: =IF(N(I26)=0,"",C26/I26) | S26: =IF(N(J26)=0,"",C26/J26) | T26: =IF(N(L26)=0,"",C26/L26) | U26: =IF(N(I26)=0,"",J26/I26) | V26: =IF(N(K26)=0,"",L26/K26) | W26: =IF(N(C26)=0,"",M26/C26)
A27: 46357 | B27: Microsoft Ads | C27: =SUMIFS('Saisie hebdo'!$E$5:$E$2000,'Saisie hebdo'!$B$5:$B$2000,$A27,'Saisie hebdo'!$C$5:$C$2000,$B27) | D27: =SUMIFS('Saisie hebdo'!$F$5:$F$2000,'Saisie hebdo'!$B$5:$B$2000,$A27,'Saisie hebdo'!$C$5:$C$2000,$B27) | E27: =SUMIFS('Saisie hebdo'!$G$5:$G$2000,'Saisie hebdo'!$B$5:$B$2000,$A27,'Saisie hebdo'!$C$5:$C$2000,$B27) | F27: =SUMIFS('Saisie hebdo'!$H$5:$H$2000,'Saisie hebdo'!$B$5:$B$2000,$A27,'Saisie hebdo'!$C$5:$C$2000,$B27) | G27: =IFERROR(AVERAGEIFS('Saisie hebdo'!$I$5:$I$2000,'Saisie hebdo'!$B$5:$B$2000,$A27,'Saisie hebdo'!$C$5:$C$2000,$B27),"") | H27: =IFERROR(AVERAGEIFS('Saisie hebdo'!$J$5:$J$2000,'Saisie hebdo'!$B$5:$B$2000,$A27,'Saisie hebdo'!$C$5:$C$2000,$B27),"") | I27: =SUMIFS('Saisie hebdo'!$K$5:$K$2000,'Saisie hebdo'!$B$5:$B$2000,$A27,'Saisie hebdo'!$C$5:$C$2000,$B27) | J27: =SUMIFS('Saisie hebdo'!$L$5:$L$2000,'Saisie hebdo'!$B$5:$B$2000,$A27,'Saisie hebdo'!$C$5:$C$2000,$B27) | K27: =SUMIFS('Saisie hebdo'!$M$5:$M$2000,'Saisie hebdo'!$B$5:$B$2000,$A27,'Saisie hebdo'!$C$5:$C$2000,$B27) | L27: =SUMIFS('Saisie hebdo'!$N$5:$N$2000,'Saisie hebdo'!$B$5:$B$2000,$A27,'Saisie hebdo'!$C$5:$C$2000,$B27) | M27: =SUMIFS('Saisie hebdo'!$O$5:$O$2000,'Saisie hebdo'!$B$5:$B$2000,$A27,'Saisie hebdo'!$C$5:$C$2000,$B27) | N27: =IF(N(D27)=0,"",E27/D27) | O27: =IF(N(E27)=0,"",C27/E27) | P27: =IF(N(E27)=0,"",F27/E27) | Q27: =IF(N(F27)=0,"",C27/F27) | R27: =IF(N(I27)=0,"",C27/I27) | S27: =IF(N(J27)=0,"",C27/J27) | T27: =IF(N(L27)=0,"",C27/L27) | U27: =IF(N(I27)=0,"",J27/I27) | V27: =IF(N(K27)=0,"",L27/K27) | W27: =IF(N(C27)=0,"",M27/C27)
A28: 46357 | B28: Total du compte | C28: =SUMIFS('Saisie hebdo'!$E$5:$E$2000,'Saisie hebdo'!$B$5:$B$2000,$A28) | D28: =SUMIFS('Saisie hebdo'!$F$5:$F$2000,'Saisie hebdo'!$B$5:$B$2000,$A28) | E28: =SUMIFS('Saisie hebdo'!$G$5:$G$2000,'Saisie hebdo'!$B$5:$B$2000,$A28) | F28: =SUMIFS('Saisie hebdo'!$H$5:$H$2000,'Saisie hebdo'!$B$5:$B$2000,$A28) | G28: =IFERROR(AVERAGEIFS('Saisie hebdo'!$I$5:$I$2000,'Saisie hebdo'!$B$5:$B$2000,$A28),"") | H28: =IFERROR(AVERAGEIFS('Saisie hebdo'!$J$5:$J$2000,'Saisie hebdo'!$B$5:$B$2000,$A28),"") | I28: =SUMIFS('Saisie hebdo'!$K$5:$K$2000,'Saisie hebdo'!$B$5:$B$2000,$A28) | J28: =SUMIFS('Saisie hebdo'!$L$5:$L$2000,'Saisie hebdo'!$B$5:$B$2000,$A28) | K28: =SUMIFS('Saisie hebdo'!$M$5:$M$2000,'Saisie hebdo'!$B$5:$B$2000,$A28) | L28: =SUMIFS('Saisie hebdo'!$N$5:$N$2000,'Saisie hebdo'!$B$5:$B$2000,$A28) | M28: =SUMIFS('Saisie hebdo'!$O$5:$O$2000,'Saisie hebdo'!$B$5:$B$2000,$A28) | N28: =IF(N(D28)=0,"",E28/D28) | O28: =IF(N(E28)=0,"",C28/E28) | P28: =IF(N(E28)=0,"",F28/E28) | Q28: =IF(N(F28)=0,"",C28/F28) | R28: =IF(N(I28)=0,"",C28/I28) | S28: =IF(N(J28)=0,"",C28/J28) | T28: =IF(N(L28)=0,"",C28/L28) | U28: =IF(N(I28)=0,"",J28/I28) | V28: =IF(N(K28)=0,"",L28/K28) | W28: =IF(N(C28)=0,"",M28/C28)
A29: 46388 | B29: S-FR | Marque | C29: =SUMIFS('Saisie hebdo'!$E$5:$E$2000,'Saisie hebdo'!$B$5:$B$2000,$A29,'Saisie hebdo'!$C$5:$C$2000,$B29) | D29: =SUMIFS('Saisie hebdo'!$F$5:$F$2000,'Saisie hebdo'!$B$5:$B$2000,$A29,'Saisie hebdo'!$C$5:$C$2000,$B29) | E29: =SUMIFS('Saisie hebdo'!$G$5:$G$2000,'Saisie hebdo'!$B$5:$B$2000,$A29,'Saisie hebdo'!$C$5:$C$2000,$B29) | F29: =SUMIFS('Saisie hebdo'!$H$5:$H$2000,'Saisie hebdo'!$B$5:$B$2000,$A29,'Saisie hebdo'!$C$5:$C$2000,$B29) | G29: =IFERROR(AVERAGEIFS('Saisie hebdo'!$I$5:$I$2000,'Saisie hebdo'!$B$5:$B$2000,$A29,'Saisie hebdo'!$C$5:$C$2000,$B29),"") | H29: =IFERROR(AVERAGEIFS('Saisie hebdo'!$J$5:$J$2000,'Saisie hebdo'!$B$5:$B$2000,$A29,'Saisie hebdo'!$C$5:$C$2000,$B29),"") | I29: =SUMIFS('Saisie hebdo'!$K$5:$K$2000,'Saisie hebdo'!$B$5:$B$2000,$A29,'Saisie hebdo'!$C$5:$C$2000,$B29) | J29: =SUMIFS('Saisie hebdo'!$L$5:$L$2000,'Saisie hebdo'!$B$5:$B$2000,$A29,'Saisie hebdo'!$C$5:$C$2000,$B29) | K29: =SUMIFS('Saisie hebdo'!$M$5:$M$2000,'Saisie hebdo'!$B$5:$B$2000,$A29,'Saisie hebdo'!$C$5:$C$2000,$B29) | L29: =SUMIFS('Saisie hebdo'!$N$5:$N$2000,'Saisie hebdo'!$B$5:$B$2000,$A29,'Saisie hebdo'!$C$5:$C$2000,$B29) | M29: =SUMIFS('Saisie hebdo'!$O$5:$O$2000,'Saisie hebdo'!$B$5:$B$2000,$A29,'Saisie hebdo'!$C$5:$C$2000,$B29) | N29: =IF(N(D29)=0,"",E29/D29) | O29: =IF(N(E29)=0,"",C29/E29) | P29: =IF(N(E29)=0,"",F29/E29) | Q29: =IF(N(F29)=0,"",C29/F29) | R29: =IF(N(I29)=0,"",C29/I29) | S29: =IF(N(J29)=0,"",C29/J29) | T29: =IF(N(L29)=0,"",C29/L29) | U29: =IF(N(I29)=0,"",J29/I29) | V29: =IF(N(K29)=0,"",L29/K29) | W29: =IF(N(C29)=0,"",M29/C29)
A30: 46388 | B30: S-FR | Corporatif & Fêtes | C30: =SUMIFS('Saisie hebdo'!$E$5:$E$2000,'Saisie hebdo'!$B$5:$B$2000,$A30,'Saisie hebdo'!$C$5:$C$2000,$B30) | D30: =SUMIFS('Saisie hebdo'!$F$5:$F$2000,'Saisie hebdo'!$B$5:$B$2000,$A30,'Saisie hebdo'!$C$5:$C$2000,$B30) | E30: =SUMIFS('Saisie hebdo'!$G$5:$G$2000,'Saisie hebdo'!$B$5:$B$2000,$A30,'Saisie hebdo'!$C$5:$C$2000,$B30) | F30: =SUMIFS('Saisie hebdo'!$H$5:$H$2000,'Saisie hebdo'!$B$5:$B$2000,$A30,'Saisie hebdo'!$C$5:$C$2000,$B30) | G30: =IFERROR(AVERAGEIFS('Saisie hebdo'!$I$5:$I$2000,'Saisie hebdo'!$B$5:$B$2000,$A30,'Saisie hebdo'!$C$5:$C$2000,$B30),"") | H30: =IFERROR(AVERAGEIFS('Saisie hebdo'!$J$5:$J$2000,'Saisie hebdo'!$B$5:$B$2000,$A30,'Saisie hebdo'!$C$5:$C$2000,$B30),"") | I30: =SUMIFS('Saisie hebdo'!$K$5:$K$2000,'Saisie hebdo'!$B$5:$B$2000,$A30,'Saisie hebdo'!$C$5:$C$2000,$B30) | J30: =SUMIFS('Saisie hebdo'!$L$5:$L$2000,'Saisie hebdo'!$B$5:$B$2000,$A30,'Saisie hebdo'!$C$5:$C$2000,$B30) | K30: =SUMIFS('Saisie hebdo'!$M$5:$M$2000,'Saisie hebdo'!$B$5:$B$2000,$A30,'Saisie hebdo'!$C$5:$C$2000,$B30) | L30: =SUMIFS('Saisie hebdo'!$N$5:$N$2000,'Saisie hebdo'!$B$5:$B$2000,$A30,'Saisie hebdo'!$C$5:$C$2000,$B30) | M30: =SUMIFS('Saisie hebdo'!$O$5:$O$2000,'Saisie hebdo'!$B$5:$B$2000,$A30,'Saisie hebdo'!$C$5:$C$2000,$B30) | N30: =IF(N(D30)=0,"",E30/D30) | O30: =IF(N(E30)=0,"",C30/E30) | P30: =IF(N(E30)=0,"",F30/E30) | Q30: =IF(N(F30)=0,"",C30/F30) | R30: =IF(N(I30)=0,"",C30/I30) | S30: =IF(N(J30)=0,"",C30/J30) | T30: =IF(N(L30)=0,"",C30/L30) | U30: =IF(N(I30)=0,"",J30/I30) | V30: =IF(N(K30)=0,"",L30/K30) | W30: =IF(N(C30)=0,"",M30/C30)
A31: 46388 | B31: S-FR | Événements privés | C31: =SUMIFS('Saisie hebdo'!$E$5:$E$2000,'Saisie hebdo'!$B$5:$B$2000,$A31,'Saisie hebdo'!$C$5:$C$2000,$B31) | D31: =SUMIFS('Saisie hebdo'!$F$5:$F$2000,'Saisie hebdo'!$B$5:$B$2000,$A31,'Saisie hebdo'!$C$5:$C$2000,$B31) | E31: =SUMIFS('Saisie hebdo'!$G$5:$G$2000,'Saisie hebdo'!$B$5:$B$2000,$A31,'Saisie hebdo'!$C$5:$C$2000,$B31) | F31: =SUMIFS('Saisie hebdo'!$H$5:$H$2000,'Saisie hebdo'!$B$5:$B$2000,$A31,'Saisie hebdo'!$C$5:$C$2000,$B31) | G31: =IFERROR(AVERAGEIFS('Saisie hebdo'!$I$5:$I$2000,'Saisie hebdo'!$B$5:$B$2000,$A31,'Saisie hebdo'!$C$5:$C$2000,$B31),"") | H31: =IFERROR(AVERAGEIFS('Saisie hebdo'!$J$5:$J$2000,'Saisie hebdo'!$B$5:$B$2000,$A31,'Saisie hebdo'!$C$5:$C$2000,$B31),"") | I31: =SUMIFS('Saisie hebdo'!$K$5:$K$2000,'Saisie hebdo'!$B$5:$B$2000,$A31,'Saisie hebdo'!$C$5:$C$2000,$B31) | J31: =SUMIFS('Saisie hebdo'!$L$5:$L$2000,'Saisie hebdo'!$B$5:$B$2000,$A31,'Saisie hebdo'!$C$5:$C$2000,$B31) | K31: =SUMIFS('Saisie hebdo'!$M$5:$M$2000,'Saisie hebdo'!$B$5:$B$2000,$A31,'Saisie hebdo'!$C$5:$C$2000,$B31) | L31: =SUMIFS('Saisie hebdo'!$N$5:$N$2000,'Saisie hebdo'!$B$5:$B$2000,$A31,'Saisie hebdo'!$C$5:$C$2000,$B31) | M31: =SUMIFS('Saisie hebdo'!$O$5:$O$2000,'Saisie hebdo'!$B$5:$B$2000,$A31,'Saisie hebdo'!$C$5:$C$2000,$B31) | N31: =IF(N(D31)=0,"",E31/D31) | O31: =IF(N(E31)=0,"",C31/E31) | P31: =IF(N(E31)=0,"",F31/E31) | Q31: =IF(N(F31)=0,"",C31/F31) | R31: =IF(N(I31)=0,"",C31/I31) | S31: =IF(N(J31)=0,"",C31/J31) | T31: =IF(N(L31)=0,"",C31/L31) | U31: =IF(N(I31)=0,"",J31/I31) | V31: =IF(N(K31)=0,"",L31/K31) | W31: =IF(N(C31)=0,"",M31/C31)
A32: 46388 | B32: S-EN | Corporate Montréal | C32: =SUMIFS('Saisie hebdo'!$E$5:$E$2000,'Saisie hebdo'!$B$5:$B$2000,$A32,'Saisie hebdo'!$C$5:$C$2000,$B32) | D32: =SUMIFS('Saisie hebdo'!$F$5:$F$2000,'Saisie hebdo'!$B$5:$B$2000,$A32,'Saisie hebdo'!$C$5:$C$2000,$B32) | E32: =SUMIFS('Saisie hebdo'!$G$5:$G$2000,'Saisie hebdo'!$B$5:$B$2000,$A32,'Saisie hebdo'!$C$5:$C$2000,$B32) | F32: =SUMIFS('Saisie hebdo'!$H$5:$H$2000,'Saisie hebdo'!$B$5:$B$2000,$A32,'Saisie hebdo'!$C$5:$C$2000,$B32) | G32: =IFERROR(AVERAGEIFS('Saisie hebdo'!$I$5:$I$2000,'Saisie hebdo'!$B$5:$B$2000,$A32,'Saisie hebdo'!$C$5:$C$2000,$B32),"") | H32: =IFERROR(AVERAGEIFS('Saisie hebdo'!$J$5:$J$2000,'Saisie hebdo'!$B$5:$B$2000,$A32,'Saisie hebdo'!$C$5:$C$2000,$B32),"") | I32: =SUMIFS('Saisie hebdo'!$K$5:$K$2000,'Saisie hebdo'!$B$5:$B$2000,$A32,'Saisie hebdo'!$C$5:$C$2000,$B32) | J32: =SUMIFS('Saisie hebdo'!$L$5:$L$2000,'Saisie hebdo'!$B$5:$B$2000,$A32,'Saisie hebdo'!$C$5:$C$2000,$B32) | K32: =SUMIFS('Saisie hebdo'!$M$5:$M$2000,'Saisie hebdo'!$B$5:$B$2000,$A32,'Saisie hebdo'!$C$5:$C$2000,$B32) | L32: =SUMIFS('Saisie hebdo'!$N$5:$N$2000,'Saisie hebdo'!$B$5:$B$2000,$A32,'Saisie hebdo'!$C$5:$C$2000,$B32) | M32: =SUMIFS('Saisie hebdo'!$O$5:$O$2000,'Saisie hebdo'!$B$5:$B$2000,$A32,'Saisie hebdo'!$C$5:$C$2000,$B32) | N32: =IF(N(D32)=0,"",E32/D32) | O32: =IF(N(E32)=0,"",C32/E32) | P32: =IF(N(E32)=0,"",F32/E32) | Q32: =IF(N(F32)=0,"",C32/F32) | R32: =IF(N(I32)=0,"",C32/I32) | S32: =IF(N(J32)=0,"",C32/J32) | T32: =IF(N(L32)=0,"",C32/L32) | U32: =IF(N(I32)=0,"",J32/I32) | V32: =IF(N(K32)=0,"",L32/K32) | W32: =IF(N(C32)=0,"",M32/C32)
A33: 46388 | B33: S-FR | Québec-Lévis (test) | C33: =SUMIFS('Saisie hebdo'!$E$5:$E$2000,'Saisie hebdo'!$B$5:$B$2000,$A33,'Saisie hebdo'!$C$5:$C$2000,$B33) | D33: =SUMIFS('Saisie hebdo'!$F$5:$F$2000,'Saisie hebdo'!$B$5:$B$2000,$A33,'Saisie hebdo'!$C$5:$C$2000,$B33) | E33: =SUMIFS('Saisie hebdo'!$G$5:$G$2000,'Saisie hebdo'!$B$5:$B$2000,$A33,'Saisie hebdo'!$C$5:$C$2000,$B33) | F33: =SUMIFS('Saisie hebdo'!$H$5:$H$2000,'Saisie hebdo'!$B$5:$B$2000,$A33,'Saisie hebdo'!$C$5:$C$2000,$B33) | G33: =IFERROR(AVERAGEIFS('Saisie hebdo'!$I$5:$I$2000,'Saisie hebdo'!$B$5:$B$2000,$A33,'Saisie hebdo'!$C$5:$C$2000,$B33),"") | H33: =IFERROR(AVERAGEIFS('Saisie hebdo'!$J$5:$J$2000,'Saisie hebdo'!$B$5:$B$2000,$A33,'Saisie hebdo'!$C$5:$C$2000,$B33),"") | I33: =SUMIFS('Saisie hebdo'!$K$5:$K$2000,'Saisie hebdo'!$B$5:$B$2000,$A33,'Saisie hebdo'!$C$5:$C$2000,$B33) | J33: =SUMIFS('Saisie hebdo'!$L$5:$L$2000,'Saisie hebdo'!$B$5:$B$2000,$A33,'Saisie hebdo'!$C$5:$C$2000,$B33) | K33: =SUMIFS('Saisie hebdo'!$M$5:$M$2000,'Saisie hebdo'!$B$5:$B$2000,$A33,'Saisie hebdo'!$C$5:$C$2000,$B33) | L33: =SUMIFS('Saisie hebdo'!$N$5:$N$2000,'Saisie hebdo'!$B$5:$B$2000,$A33,'Saisie hebdo'!$C$5:$C$2000,$B33) | M33: =SUMIFS('Saisie hebdo'!$O$5:$O$2000,'Saisie hebdo'!$B$5:$B$2000,$A33,'Saisie hebdo'!$C$5:$C$2000,$B33) | N33: =IF(N(D33)=0,"",E33/D33) | O33: =IF(N(E33)=0,"",C33/E33) | P33: =IF(N(E33)=0,"",F33/E33) | Q33: =IF(N(F33)=0,"",C33/F33) | R33: =IF(N(I33)=0,"",C33/I33) | S33: =IF(N(J33)=0,"",C33/J33) | T33: =IF(N(L33)=0,"",C33/L33) | U33: =IF(N(I33)=0,"",J33/I33) | V33: =IF(N(K33)=0,"",L33/K33) | W33: =IF(N(C33)=0,"",M33/C33)
A34: 46388 | B34: Demand Gen | C34: =SUMIFS('Saisie hebdo'!$E$5:$E$2000,'Saisie hebdo'!$B$5:$B$2000,$A34,'Saisie hebdo'!$C$5:$C$2000,$B34) | D34: =SUMIFS('Saisie hebdo'!$F$5:$F$2000,'Saisie hebdo'!$B$5:$B$2000,$A34,'Saisie hebdo'!$C$5:$C$2000,$B34) | E34: =SUMIFS('Saisie hebdo'!$G$5:$G$2000,'Saisie hebdo'!$B$5:$B$2000,$A34,'Saisie hebdo'!$C$5:$C$2000,$B34) | F34: =SUMIFS('Saisie hebdo'!$H$5:$H$2000,'Saisie hebdo'!$B$5:$B$2000,$A34,'Saisie hebdo'!$C$5:$C$2000,$B34) | G34: =IFERROR(AVERAGEIFS('Saisie hebdo'!$I$5:$I$2000,'Saisie hebdo'!$B$5:$B$2000,$A34,'Saisie hebdo'!$C$5:$C$2000,$B34),"") | H34: =IFERROR(AVERAGEIFS('Saisie hebdo'!$J$5:$J$2000,'Saisie hebdo'!$B$5:$B$2000,$A34,'Saisie hebdo'!$C$5:$C$2000,$B34),"") | I34: =SUMIFS('Saisie hebdo'!$K$5:$K$2000,'Saisie hebdo'!$B$5:$B$2000,$A34,'Saisie hebdo'!$C$5:$C$2000,$B34) | J34: =SUMIFS('Saisie hebdo'!$L$5:$L$2000,'Saisie hebdo'!$B$5:$B$2000,$A34,'Saisie hebdo'!$C$5:$C$2000,$B34) | K34: =SUMIFS('Saisie hebdo'!$M$5:$M$2000,'Saisie hebdo'!$B$5:$B$2000,$A34,'Saisie hebdo'!$C$5:$C$2000,$B34) | L34: =SUMIFS('Saisie hebdo'!$N$5:$N$2000,'Saisie hebdo'!$B$5:$B$2000,$A34,'Saisie hebdo'!$C$5:$C$2000,$B34) | M34: =SUMIFS('Saisie hebdo'!$O$5:$O$2000,'Saisie hebdo'!$B$5:$B$2000,$A34,'Saisie hebdo'!$C$5:$C$2000,$B34) | N34: =IF(N(D34)=0,"",E34/D34) | O34: =IF(N(E34)=0,"",C34/E34) | P34: =IF(N(E34)=0,"",F34/E34) | Q34: =IF(N(F34)=0,"",C34/F34) | R34: =IF(N(I34)=0,"",C34/I34) | S34: =IF(N(J34)=0,"",C34/J34) | T34: =IF(N(L34)=0,"",C34/L34) | U34: =IF(N(I34)=0,"",J34/I34) | V34: =IF(N(K34)=0,"",L34/K34) | W34: =IF(N(C34)=0,"",M34/C34)
A35: 46388 | B35: Microsoft Ads | C35: =SUMIFS('Saisie hebdo'!$E$5:$E$2000,'Saisie hebdo'!$B$5:$B$2000,$A35,'Saisie hebdo'!$C$5:$C$2000,$B35) | D35: =SUMIFS('Saisie hebdo'!$F$5:$F$2000,'Saisie hebdo'!$B$5:$B$2000,$A35,'Saisie hebdo'!$C$5:$C$2000,$B35) | E35: =SUMIFS('Saisie hebdo'!$G$5:$G$2000,'Saisie hebdo'!$B$5:$B$2000,$A35,'Saisie hebdo'!$C$5:$C$2000,$B35) | F35: =SUMIFS('Saisie hebdo'!$H$5:$H$2000,'Saisie hebdo'!$B$5:$B$2000,$A35,'Saisie hebdo'!$C$5:$C$2000,$B35) | G35: =IFERROR(AVERAGEIFS('Saisie hebdo'!$I$5:$I$2000,'Saisie hebdo'!$B$5:$B$2000,$A35,'Saisie hebdo'!$C$5:$C$2000,$B35),"") | H35: =IFERROR(AVERAGEIFS('Saisie hebdo'!$J$5:$J$2000,'Saisie hebdo'!$B$5:$B$2000,$A35,'Saisie hebdo'!$C$5:$C$2000,$B35),"") | I35: =SUMIFS('Saisie hebdo'!$K$5:$K$2000,'Saisie hebdo'!$B$5:$B$2000,$A35,'Saisie hebdo'!$C$5:$C$2000,$B35) | J35: =SUMIFS('Saisie hebdo'!$L$5:$L$2000,'Saisie hebdo'!$B$5:$B$2000,$A35,'Saisie hebdo'!$C$5:$C$2000,$B35) | K35: =SUMIFS('Saisie hebdo'!$M$5:$M$2000,'Saisie hebdo'!$B$5:$B$2000,$A35,'Saisie hebdo'!$C$5:$C$2000,$B35) | L35: =SUMIFS('Saisie hebdo'!$N$5:$N$2000,'Saisie hebdo'!$B$5:$B$2000,$A35,'Saisie hebdo'!$C$5:$C$2000,$B35) | M35: =SUMIFS('Saisie hebdo'!$O$5:$O$2000,'Saisie hebdo'!$B$5:$B$2000,$A35,'Saisie hebdo'!$C$5:$C$2000,$B35) | N35: =IF(N(D35)=0,"",E35/D35) | O35: =IF(N(E35)=0,"",C35/E35) | P35: =IF(N(E35)=0,"",F35/E35) | Q35: =IF(N(F35)=0,"",C35/F35) | R35: =IF(N(I35)=0,"",C35/I35) | S35: =IF(N(J35)=0,"",C35/J35) | T35: =IF(N(L35)=0,"",C35/L35) | U35: =IF(N(I35)=0,"",J35/I35) | V35: =IF(N(K35)=0,"",L35/K35) | W35: =IF(N(C35)=0,"",M35/C35)
A36: 46388 | B36: Total du compte | C36: =SUMIFS('Saisie hebdo'!$E$5:$E$2000,'Saisie hebdo'!$B$5:$B$2000,$A36) | D36: =SUMIFS('Saisie hebdo'!$F$5:$F$2000,'Saisie hebdo'!$B$5:$B$2000,$A36) | E36: =SUMIFS('Saisie hebdo'!$G$5:$G$2000,'Saisie hebdo'!$B$5:$B$2000,$A36) | F36: =SUMIFS('Saisie hebdo'!$H$5:$H$2000,'Saisie hebdo'!$B$5:$B$2000,$A36) | G36: =IFERROR(AVERAGEIFS('Saisie hebdo'!$I$5:$I$2000,'Saisie hebdo'!$B$5:$B$2000,$A36),"") | H36: =IFERROR(AVERAGEIFS('Saisie hebdo'!$J$5:$J$2000,'Saisie hebdo'!$B$5:$B$2000,$A36),"") | I36: =SUMIFS('Saisie hebdo'!$K$5:$K$2000,'Saisie hebdo'!$B$5:$B$2000,$A36) | J36: =SUMIFS('Saisie hebdo'!$L$5:$L$2000,'Saisie hebdo'!$B$5:$B$2000,$A36) | K36: =SUMIFS('Saisie hebdo'!$M$5:$M$2000,'Saisie hebdo'!$B$5:$B$2000,$A36) | L36: =SUMIFS('Saisie hebdo'!$N$5:$N$2000,'Saisie hebdo'!$B$5:$B$2000,$A36) | M36: =SUMIFS('Saisie hebdo'!$O$5:$O$2000,'Saisie hebdo'!$B$5:$B$2000,$A36) | N36: =IF(N(D36)=0,"",E36/D36) | O36: =IF(N(E36)=0,"",C36/E36) | P36: =IF(N(E36)=0,"",F36/E36) | Q36: =IF(N(F36)=0,"",C36/F36) | R36: =IF(N(I36)=0,"",C36/I36) | S36: =IF(N(J36)=0,"",C36/J36) | T36: =IF(N(L36)=0,"",C36/L36) | U36: =IF(N(I36)=0,"",J36/I36) | V36: =IF(N(K36)=0,"",L36/K36) | W36: =IF(N(C36)=0,"",M36/C36)
A37: 46419 | B37: S-FR | Marque | C37: =SUMIFS('Saisie hebdo'!$E$5:$E$2000,'Saisie hebdo'!$B$5:$B$2000,$A37,'Saisie hebdo'!$C$5:$C$2000,$B37) | D37: =SUMIFS('Saisie hebdo'!$F$5:$F$2000,'Saisie hebdo'!$B$5:$B$2000,$A37,'Saisie hebdo'!$C$5:$C$2000,$B37) | E37: =SUMIFS('Saisie hebdo'!$G$5:$G$2000,'Saisie hebdo'!$B$5:$B$2000,$A37,'Saisie hebdo'!$C$5:$C$2000,$B37) | F37: =SUMIFS('Saisie hebdo'!$H$5:$H$2000,'Saisie hebdo'!$B$5:$B$2000,$A37,'Saisie hebdo'!$C$5:$C$2000,$B37) | G37: =IFERROR(AVERAGEIFS('Saisie hebdo'!$I$5:$I$2000,'Saisie hebdo'!$B$5:$B$2000,$A37,'Saisie hebdo'!$C$5:$C$2000,$B37),"") | H37: =IFERROR(AVERAGEIFS('Saisie hebdo'!$J$5:$J$2000,'Saisie hebdo'!$B$5:$B$2000,$A37,'Saisie hebdo'!$C$5:$C$2000,$B37),"") | I37: =SUMIFS('Saisie hebdo'!$K$5:$K$2000,'Saisie hebdo'!$B$5:$B$2000,$A37,'Saisie hebdo'!$C$5:$C$2000,$B37) | J37: =SUMIFS('Saisie hebdo'!$L$5:$L$2000,'Saisie hebdo'!$B$5:$B$2000,$A37,'Saisie hebdo'!$C$5:$C$2000,$B37) | K37: =SUMIFS('Saisie hebdo'!$M$5:$M$2000,'Saisie hebdo'!$B$5:$B$2000,$A37,'Saisie hebdo'!$C$5:$C$2000,$B37) | L37: =SUMIFS('Saisie hebdo'!$N$5:$N$2000,'Saisie hebdo'!$B$5:$B$2000,$A37,'Saisie hebdo'!$C$5:$C$2000,$B37) | M37: =SUMIFS('Saisie hebdo'!$O$5:$O$2000,'Saisie hebdo'!$B$5:$B$2000,$A37,'Saisie hebdo'!$C$5:$C$2000,$B37) | N37: =IF(N(D37)=0,"",E37/D37) | O37: =IF(N(E37)=0,"",C37/E37) | P37: =IF(N(E37)=0,"",F37/E37) | Q37: =IF(N(F37)=0,"",C37/F37) | R37: =IF(N(I37)=0,"",C37/I37) | S37: =IF(N(J37)=0,"",C37/J37) | T37: =IF(N(L37)=0,"",C37/L37) | U37: =IF(N(I37)=0,"",J37/I37) | V37: =IF(N(K37)=0,"",L37/K37) | W37: =IF(N(C37)=0,"",M37/C37)
